Workbook
Name APUb: #REF!
Name BDcodCU: ApuB!$A$5:$A$50005
Name BDcodINS: InsB!$A$16:$A$3015
Name BDcuA: ApuB!$A$5:$DJ$50005
Name BDcuB: ApuB!$B$5:$DJ$50005
Name BDins: InsB!$A$16:$M$3015
Name cellbimuser0EB30BF1602D56040B4019F3: 1714952548072
Name cellbimuser33120D4C9001780EE8508FEB: 1715181719314
Name CODc: #REF!&"C"
Name CODp: #REF!
Name CODr: #REF!&"P"
Name DcCU: Datos!$J$13
Name Dins: Datos!$J$15
Name DLS: Datos!$AJ$12:$AJ$18
Name DpCU: Datos!$J$12
Name DpP: Datos!$J$9
Name EQ: #REF!
Name Frto: Datos!$J$19
Name JL: Datos!$H$19
Name MA: #REF!
Name MO: #REF!
Name NO: Datos!$AJ$12:$AJ$18

Sheet Datos
AQ1: NO | AT1: Feriados
B2: PROYECTO | AQ2: SI | AT2: Comienzo | AU2: Fin | AV2: Descripcion
B3: UBICACIÓN | AQ3: SI
B4: CLIENTE | AQ4: SI
B5: FECHA | AI5: Soles | AJ5: S/ | AQ5: SI
F6: MONEDA | AI6: Dólares | AJ6: $
B7: LOGO | C7: RW7o | D7: =IF(J7=AI5,AJ5,AJ6) -> S/ | G7: Procesar el presupuesto utilizando la moneda en | J7: Soles
F8: NÚMERO DE DECIMALES PARA REDONDEO
B9: MODALIDAD DE E. | C9: CONTRATA | G9: Parciales de las partidas en la hoja de presupuesto | J9: 2 | AI9: CONTRATA | AQ9: NO
B10: IMPUESTO (IGV) | C10: 0.18 | G10: Total de los metrados en cada partida | J10: 2 | AI10: ADMINISTRACION DIRECTA | AO10: CALENDARIO | AR10: PIE DEL PRESUPUESTO
D11: =Pto!G142 -> 352697.08 | AH11: 0 | AI11: 0 | AK11: 0 | AO11: Lunes | AP11: Laborable | AR11: VALOR FIJO
B12: COLOR DE TEXTOS: | G12: Parcial de los insumos en los APUs | J12: 2 | AI12: 1 | AJ12: 6 | AK12: 1 | AO12: Martes | AP12: Laborable | AR12: % COSTO DIRECTO
B13: Subpresupuesto | G13: Cantidad de MO y EQ en los APUs | J13: 4 | AI13: 2 | AJ13: 5 | AK13: 2 | AO13: Miercoles | AP13: Laborable | AR13: SUBTOTAL 1
B14: Título | D14: =VLOOKUP(C14,AL$10:AM$23,2,FALSE) -> #N/A | AI14: 3 | AK14: 3 | AO14: Jueves | AP14: Laborable | AR14: % SUBTOTAL 1
B15: Sub título de orden 1 | D15: =VLOOKUP(C15,AL$10:AM$23,2,FALSE) -> #N/A | G15: Precio de los insumos | J15: 2 | AI15: 4 | AK15: 4 | AO15: Viernes | AP15: Laborable | AR15: SUBTOTAL 2
B16: Sub título de orden 2 | D16: =VLOOKUP(C16,AL$10:AM$23,2,FALSE) -> #N/A | AI16: 5 | AK16: 5 | AO16: Sábado | AP16: Laborable | AR16: % SUBTOTAL 2
B17: Sub título de orden 3 | D17: =VLOOKUP(C17,AL$10:AM$23,2,FALSE) -> #N/A | F17: OTRAS OPCIONES | AI17: SI | AJ17: Parcial | AK17: 6 | AO17: Domingo | AP17: No laborable | AR17: SUBTOTAL 3
B18: Sub título de orden 4 | D18: =VLOOKUP(C18,AL$10:AM$23,2,FALSE) -> #N/A | I18: Factor costo mano de obra | J18: 1 | AI18: NO | AJ18: Cantidad | AK18: 7 | AR18: % SUBTOTAL 3
B19: Sub título de orden 5 | D19: =VLOOKUP(C19,AL$10:AM$23,2,FALSE) -> #N/A | G19: Jornada laboral | H19: 8 | I19: Factor para rendimiento | J19: 1 | AK19: 8 | AO19: TEXTO EN PANEL DE APUS | AR19: SUBTOTAL 4
B20: Sub título de orden 6 | D20: =VLOOKUP(C20,AL$10:AM$23,2,FALSE) -> #N/A | AI20: MO1 y EQ1 | AK20: 9 | AO20: Tamaño ET | AP20: 10 | AR20: % SUBTOTAL 4
B21: Sub título de orden 7 | D21: =VLOOKUP(C21,AL$10:AM$23,2,FALSE) -> #N/A | G21: Igualar el monto total de relación de insumos al CD | J21: SI | AI21: TODOS | AJ21: 1 | AO21: Fuente ET | AP21: Arial | AR21: % FILA ANTERIOR
B22: Sub título de orden 8 | D22: =VLOOKUP(C22,AL$10:AM$23,2,FALSE) -> #N/A | AO22: Tamaño DG | AP22: 9
B23: Sub título de orden 9 | D23: =VLOOKUP(C23,AL$10:AM$23,2,FALSE) -> #N/A | G23: Generar el gráfico de utilización de recursos para | J23: MO1 y EQ1 | AO23: Fuente DG | AP23: Arial
B25: Pie de presupuesto | G25: Al generar E.T. en Word usar IDEM en partidas repetidas | J25: SI
A26: CONTROL CONCURRENTE
A27: GESTION DEL PROYECTO | G27: Al generar E. T. en Word procesar UNIDAD | J27: SI
A28: GASTOS GENERALES
A29: UTILIDAD | G29: Al generar E.T. en Word procesar FORMA DE PAGO | J29: SI
A30: SUBTOTAL
A31: IMPUESTO (IGV) | G31: Calend. Adq. insumos de MO1 en DH y EQ1 en DM | J31: NO
A32: VALOR REFERENCIAL
A33: SUPERVISIÓN | G33: Al consolidar los insumos de las partidas calcular en base a | J33: Parcial
A34: EXPEDIENTE TÉCNICO
A35: LIQUIDACIÓN
A36: PIE DE PRESUPUESTO
A37: DESCRIPCIÓN | B37: SIM. | C37: VALOR | E37: TIPO
A38: GASTOS GENERALES | B38: GG | C38: 15 | E38: % COSTO DIRECTO
A39: UTILIDAD | B39: UT | C39: 10 | E39: % COSTO DIRECTO
A40: SUBTOTAL | B40: ST | E40: SUBTOTAL 1
A41: IMPUESTO (IGV) | B41: IM | C41: 18 | E41: % SUBTOTAL 1
...

Sheet InsB
A2: DATOS NECESARIOS PARA EL CALCULO DE FLETES
A3: INSUMOS | D3: FLETE CON VEHICULO | G3: FLETE CON ACEMILA Y PEON
D4: ORIGEN - DESTINO | F4: Prec. U. | G4: ORIGEN - DESTINO | K4: Prec. U. | L4: p.u.Cemento
A5: MATERIALES | D5: HUARAZ- HUARI | F5: 0.15 | G5: HUARI - OBRA(YUPAN) | K5: 0.06 | L5: 2.5
A6: AGREGADOS | F6: 0 | G6: HUARI - OBRA(YUPAN) | K6: 1.2 | L6: L | M6: A | N6: H
A7: TUBERIAS | F7: 0 | K7: 0 | L7: 6 | M7: 2.2 | N7: 1.5
A8: {=MAX(IF(BDcodINS<90001,BDcodINS,80000))} -> 80012 | B8: {=MAX(IF(BDcodINS<57001,BDcodINS,53500))} -> 53500 | C8: {=MAX(IF(BDcodINS<22501,BDcodINS,20000))} -> 20000
A9: {=MAX(IF(BDcodINS<80001,BDcodINS,77500))} -> 77500 | B9: {=MAX(IF(BDcodINS<53501,BDcodINS,50000))} -> 50000 | C9: {=MAX(IF(BDcodINS<77501,BDcodINS,75000))} -> 75000
A10: {=MAX(IF(BDcodINS<70001,BDcodINS,60000))} -> 60019 | B10: {=MAX(IF(BDcodINS<30001,BDcodINS,27500))} -> 27500 | C10: {=MAX(IF(BDcodINS<75001,BDcodINS,72500))} -> 72500
A11: {=MAX(IF(BDcodINS<50001,BDcodINS,30000))} -> 30141 | B11: {=MAX(IF(BDcodINS<27501,BDcodINS,25000))} -> 25000 | C11: {=MAX(IF(BDcodINS<72501,BDcodINS,70000))} -> 70001
A12: {=MAX(IF(BDcodINS<20001,BDcodINS,10000))} -> 10005 | B12: {=MAX(IF(BDcodINS<25001,BDcodINS,22500))} -> 22500 | C12: {=MAX(IF(BDcodINS<60001,BDcodINS,57000))} -> 57000 | N12: MONEDAS
A13: 60002 | B13: =MATCH($A$13,BDcodINS,0)+15 -> 25 | C13: {=MAX(IF(BDcodINS<95001,BDcodINS,90000))} -> 90004 | N13: =Datos!AI5 -> Soles | P13: =Datos!AI6 -> Dólares
A14: =COUNT(BDcodINS)+16 -> 198 | C14: {=MAX(IF(BDcodINS<100000,BDcodINS,95000))} -> 90004 | H14: SOLO TUBERIA | N14: Factor | O14: =1+Datos!$C$10 -> 1.18 | P14: 3.75 | Q14: =O14 -> 1.18
A15: Cod. | B15: IU | C15: Tipo | D15: Insumo | E15: Und | F15: =Datos!J7 -> Soles | G15: Peso unitario (kg) | H15: Long. (m) | I15: Ø ext. (mm) | J15: espesor (mm) | K15: Específica de Gastos | L15: Codigo de APU de SP | M15: Codigo insumo referido | N15: Adm. Directa | O15: Contrata | P15: Adm. Directa | Q15: Contrata
A16: 10001 | B16: 47 | C16: MO1 | D16: PEON | E16: HH | F16: =IF(AND($F$15=Datos!$AI$5,Datos!$C$9=Datos!$AI$10),IF(A16>30000,N16,ROUND(N16*Datos!$J$18,Dins)),IF(AND($F$15=Datos!$AI$5,Datos!$C$9=Datos!$AI$9),IF(A16>30000,O16,ROUND(O16*Datos!$J$18,Dins)),IF(AND($F$15=Datos!$AI$6,Datos!$C$9=Datos!$AI$10),IF(A16>30000,P16,ROUND(P16*Datos!$J$18,Dins)),IF(AND($F$15=Datos!$AI$6,Datos!$C$9=Datos!$AI$9),IF(A16>30000,Q16,ROUND(Q16*Datos!$J$18,Dins)))))) -> 12.64 | N16: 12.64 | O16: =IF(A16>30000,ROUND(N16/$O$14,Dins),ROUND(N16,Dins)) -> 12.64 | P16: =ROUND(N16/$P$14,Dins) -> 3.37 | Q16: =IF(A16>30000,ROUND(P16/$Q$14,Dins),ROUND(P16,Dins)) -> 3.37
A17: 10002 | B17: 47 | C17: MO1 | D17: OPERARIO TOPOGRAFO | E17: HH | F17: =IF(AND($F$15=Datos!$AI$5,Datos!$C$9=Datos!$AI$10),IF(A17>30000,N17,ROUND(N17*Datos!$J$18,Dins)),IF(AND($F$15=Datos!$AI$5,Datos!$C$9=Datos!$AI$9),IF(A17>30000,O17,ROUND(O17*Datos!$J$18,Dins)),IF(AND($F$15=Datos!$AI$6,Datos!$C$9=Datos!$AI$10),IF(A17>30000,P17,ROUND(P17*Datos!$J$18,Dins)),IF(AND($F$15=Datos!$AI$6,Datos!$C$9=Datos!$AI$9),IF(A17>30000,Q17,ROUND(Q17*Datos!$J$18,Dins)))))) -> 17.59 | N17: 17.59 | O17: =IF(A17>30000,ROUND(N17/$O$14,Dins),ROUND(N17,Dins)) -> 17.59 | P17: =ROUND(N17/$P$14,Dins) -> 4.69 | Q17: =IF(A17>30000,ROUND(P17/$Q$14,Dins),ROUND(P17,Dins)) -> 4.69
A18: 30001 | B18: 21 | C18: MA | D18: CEMENTO PORTLAND TIPO I (42.5 kg) | E18: bol | F18: =IF(AND($F$15=Datos!$AI$5,Datos!$C$9=Datos!$AI$10),IF(A18>30000,N18,ROUND(N18*Datos!$J$18,Dins)),IF(AND($F$15=Datos!$AI$5,Datos!$C$9=Datos!$AI$9),IF(A18>30000,O18,ROUND(O18*Datos!$J$18,Dins)),IF(AND($F$15=Datos!$AI$6,Datos!$C$9=Datos!$AI$10),IF(A18>30000,P18,ROUND(P18*Datos!$J$18,Dins)),IF(AND($F$15=Datos!$AI$6,Datos!$C$9=Datos!$AI$9),IF(A18>30000,Q18,ROUND(Q18*Datos!$J$18,Dins)))))) -> 27 | N18: 31.86 | O18: =IF(A18>30000,ROUND(N18/$O$14,Dins),ROUND(N18,Dins)) -> 27 | P18: =ROUND(N18/$P$14,Dins) -> 8.5 | Q18: =IF(A18>30000,ROUND(P18/$Q$14,Dins),ROUND(P18,Dins)) -> 7.2
A19: 30002 | B19: 38 | C19: MA | D19: HORMIGON | E19: m3 | F19: =IF(AND($F$15=Datos!$AI$5,Datos!$C$9=Datos!$AI$10),IF(A19>30000,N19,ROUND(N19*Datos!$J$18,Dins)),IF(AND($F$15=Datos!$AI$5,Datos!$C$9=Datos!$AI$9),IF(A19>30000,O19,ROUND(O19*Datos!$J$18,Dins)),IF(AND($F$15=Datos!$AI$6,Datos!$C$9=Datos!$AI$10),IF(A19>30000,P19,ROUND(P19*Datos!$J$18,Dins)),IF(AND($F$15=Datos!$AI$6,Datos!$C$9=Datos!$AI$9),IF(A19>30000,Q19,ROUND(Q19*Datos!$J$18,Dins)))))) -> 41.3 | N19: 48.73 | O19: =IF(A19>30000,ROUND(N19/$O$14,Dins),ROUND(N19,Dins)) -> 41.3 | P19: =ROUND(N19/$P$14,Dins) -> 12.99 | Q19: =IF(A19>30000,ROUND(P19/$Q$14,Dins),ROUND(P19,Dins)) -> 11.01
A20: 30003 | B20: 39 | C20: MA | D20: TIZA BOLSA DE 40 kg | E20: und | F20: =IF(AND($F$15=Datos!$AI$5,Datos!$C$9=Datos!$AI$10),IF(A20>30000,N20,ROUND(N20*Datos!$J$18,Dins)),IF(AND($F$15=Datos!$AI$5,Datos!$C$9=Datos!$AI$9),IF(A20>30000,O20,ROUND(O20*Datos!$J$18,Dins)),IF(AND($F$15=Datos!$AI$6,Datos!$C$9=Datos!$AI$10),IF(A20>30000,P20,ROUND(P20*Datos!$J$18,Dins)),IF(AND($F$15=Datos!$AI$6,Datos!$C$9=Datos!$AI$9),IF(A20>30000,Q20,ROUND(Q20*Datos!$J$18,Dins)))))) -> 20 | N20: 23.6 | O20: =IF(A20>30000,ROUND(N20/$O$14,Dins),ROUND(N20,Dins)) -> 20 | P20: =ROUND(N20/$P$14,Dins) -> 6.29 | Q20: =IF(A20>30000,ROUND(P20/$Q$14,Dins),ROUND(P20,Dins)) -> 5.33
A21: 30004 | B21: 30 | C21: MA | D21: OCRE ROJO | E21: kg | F21: =IF(AND($F$15=Datos!$AI$5,Datos!$C$9=Datos!$AI$10),IF(A21>30000,N21,ROUND(N21*Datos!$J$18,Dins)),IF(AND($F$15=Datos!$AI$5,Datos!$C$9=Datos!$AI$9),IF(A21>30000,O21,ROUND(O21*Datos!$J$18,Dins)),IF(AND($F$15=Datos!$AI$6,Datos!$C$9=Datos!$AI$10),IF(A21>30000,P21,ROUND(P21*Datos!$J$18,Dins)),IF(AND($F$15=Datos!$AI$6,Datos!$C$9=Datos!$AI$9),IF(A21>30000,Q21,ROUND(Q21*Datos!$J$18,Dins)))))) -> 8 | N21: 9.44 | O21: =IF(A21>30000,ROUND(N21/$O$14,Dins),ROUND(N21,Dins)) -> 8 | P21: =ROUND(N21/$P$14,Dins) -> 2.52 | Q21: =IF(A21>30000,ROUND(P21/$Q$14,Dins),ROUND(P21,Dins)) -> 2.14
A22: 30005 | B22: 54 | C22: MA | D22: PINTURA ESMALTE | E22: gal | F22: =IF(AND($F$15=Datos!$AI$5,Datos!$C$9=Datos!$AI$10),IF(A22>30000,N22,ROUND(N22*Datos!$J$18,Dins)),IF(AND($F$15=Datos!$AI$5,Datos!$C$9=Datos!$AI$9),IF(A22>30000,O22,ROUND(O22*Datos!$J$18,Dins)),IF(AND($F$15=Datos!$AI$6,Datos!$C$9=Datos!$AI$10),IF(A22>30000,P22,ROUND(P22*Datos!$J$18,Dins)),IF(AND($F$15=Datos!$AI$6,Datos!$C$9=Datos!$AI$9),IF(A22>30000,Q22,ROUND(Q22*Datos!$J$18,Dins)))))) -> 28 | N22: 33.04 | O22: =IF(A22>30000,ROUND(N22/$O$14,Dins),ROUND(N22,Dins)) -> 28 | P22: =ROUND(N22/$P$14,Dins) -> 8.81 | Q22: =IF(A22>30000,ROUND(P22/$Q$14,Dins),ROUND(P22,Dins)) -> 7.47
A23: 30006 | B23: 39 | C23: MA | D23: CORDEL | E23: rll | F23: =IF(AND($F$15=Datos!$AI$5,Datos!$C$9=Datos!$AI$10),IF(A23>30000,N23,ROUND(N23*Datos!$J$18,Dins)),IF(AND($F$15=Datos!$AI$5,Datos!$C$9=Datos!$AI$9),IF(A23>30000,O23,ROUND(O23*Datos!$J$18,Dins)),IF(AND($F$15=Datos!$AI$6,Datos!$C$9=Datos!$AI$10),IF(A23>30000,P23,ROUND(P23*Datos!$J$18,Dins)),IF(AND($F$15=Datos!$AI$6,Datos!$C$9=Datos!$AI$9),IF(A23>30000,Q23,ROUND(Q23*Datos!$J$18,Dins)))))) -> 23.8 | N23: 28.08 | O23: =IF(A23>30000,ROUND(N23/$O$14,Dins),ROUND(N23,Dins)) -> 23.8 | P23: =ROUND(N23/$P$14,Dins) -> 7.49 | Q23: =IF(A23>30000,ROUND(P23/$Q$14,Dins),ROUND(P23,Dins)) -> 6.35
A24: 60001 | B24: 49 | C24: EQ1 | D24: NIVEL TOPOGRAFICO | E24: HM | F24: =IF(AND($F$15=Datos!$AI$5,Datos!$C$9=Datos!$AI$10),IF(A24>30000,N24,ROUND(N24*Datos!$J$18,Dins)),IF(AND($F$15=Datos!$AI$5,Datos!$C$9=Datos!$AI$9),IF(A24>30000,O24,ROUND(O24*Datos!$J$18,Dins)),IF(AND($F$15=Datos!$AI$6,Datos!$C$9=Datos!$AI$10),IF(A24>30000,P24,ROUND(P24*Datos!$J$18,Dins)),IF(AND($F$15=Datos!$AI$6,Datos!$C$9=Datos!$AI$9),IF(A24>30000,Q24,ROUND(Q24*Datos!$J$18,Dins)))))) -> 3.75 | N24: 4.42 | O24: =IF(A24>30000,ROUND(N24/$O$14,Dins),ROUND(N24,Dins)) -> 3.75 | P24: =ROUND(N24/$P$14,Dins) -> 1.18 | Q24: =IF(A24>30000,ROUND(P24/$Q$14,Dins),ROUND(P24,Dins)) -> 1
A25: 60002 | B25: 49 | C25: EQ1 | D25: TEODOLITO | E25: HM | F25: =IF(AND($F$15=Datos!$AI$5,Datos!$C$9=Datos!$AI$10),IF(A25>30000,N25,ROUND(N25*Datos!$J$18,Dins)),IF(AND($F$15=Datos!$AI$5,Datos!$C$9=Datos!$AI$9),IF(A25>30000,O25,ROUND(O25*Datos!$J$18,Dins)),IF(AND($F$15=Datos!$AI$6,Datos!$C$9=Datos!$AI$10),IF(A25>30000,P25,ROUND(P25*Datos!$J$18,Dins)),IF(AND($F$15=Datos!$AI$6,Datos!$C$9=Datos!$AI$9),IF(A25>30000,Q25,ROUND(Q25*Datos!$J$18,Dins)))))) -> 6.25 | N25: 7.38 | O25: =IF(A25>30000,ROUND(N25/$O$14,Dins),ROUND(N25,Dins)) -> 6.25 | P25: =ROUND(N25/$P$14,Dins) -> 1.97 | Q25: =IF(A25>30000,ROUND(P25/$Q$14,Dins),ROUND(P25,Dins)) -> 1.67
A26: 30007 | B26: 49 | C26: MA | D26: NIVEL TOPOGRAFICO | E26: día | F26: =IF(AND($F$15=Datos!$AI$5,Datos!$C$9=Datos!$AI$10),IF(A26>30000,N26,ROUND(N26*Datos!$J$18,Dins)),IF(AND($F$15=Datos!$AI$5,Datos!$C$9=Datos!$AI$9),IF(A26>30000,O26,ROUND(O26*Datos!$J$18,Dins)),IF(AND($F$15=Datos!$AI$6,Datos!$C$9=Datos!$AI$10),IF(A26>30000,P26,ROUND(P26*Datos!$J$18,Dins)),IF(AND($F$15=Datos!$AI$6,Datos!$C$9=Datos!$AI$9),IF(A26>30000,Q26,ROUND(Q26*Datos!$J$18,Dins)))))) -> 30 | N26: 35.4 | O26: =IF(A26>30000,ROUND(N26/$O$14,Dins),ROUND(N26,Dins)) -> 30 | P26: =ROUND(N26/$P$14,Dins) -> 9.44 | Q26: =IF(A26>30000,ROUND(P26/$Q$14,Dins),ROUND(P26,Dins)) -> 8
A27: 30008 | B27: 30 | C27: MA | D27: TEODOLITO | E27: día | F27: =IF(AND($F$15=Datos!$AI$5,Datos!$C$9=Datos!$AI$10),IF(A27>30000,N27,ROUND(N27*Datos!$J$18,Dins)),IF(AND($F$15=Datos!$AI$5,Datos!$C$9=Datos!$AI$9),IF(A27>30000,O27,ROUND(O27*Datos!$J$18,Dins)),IF(AND($F$15=Datos!$AI$6,Datos!$C$9=Datos!$AI$10),IF(A27>30000,P27,ROUND(P27*Datos!$J$18,Dins)),IF(AND($F$15=Datos!$AI$6,Datos!$C$9=Datos!$AI$9),IF(A27>30000,Q27,ROUND(Q27*Datos!$J$18,Dins)))))) -> 50 | N27: 59 | O27: =IF(A27>30000,ROUND(N27/$O$14,Dins),ROUND(N27,Dins)) -> 50 | P27: =ROUND(N27/$P$14,Dins) -> 15.73 | Q27: =IF(A27>30000,ROUND(P27/$Q$14,Dins),ROUND(P27,Dins)) -> 13.33
... A82: 30043 | B82: 37 | C82: MA | D82: REGLA DE ALUMINIO 1" X 4" X 8" | E82: und | F82: =IF(AND($F$15=Datos!$AI$5,Datos!$C$9=Datos!$AI$10),IF(A82>30000,N82,ROUND(N82*Datos!$J$18,Dins)),IF(AND($F$15=Datos!$AI$5,Datos!$C$9=Datos!$AI$9),IF(A82>30000,O82,ROUND(O82*Datos!$J$18,Dins)),IF(AND($F$15=Datos!$AI$6,Datos!$C$9=Datos!$AI$10),IF(A82>30000,P82,ROUND(P82*Datos!$J$18,Dins)),IF(AND($F$15=Datos!$AI$6,Datos!$C$9=Datos!$AI$9),IF(A82>30000,Q82,ROUND(Q82*Datos!$J$18,Dins)))))) -> 60 | N82: 70.8 | O82: =IF(A82>30000,ROUND(N82/$O$14,Dins),ROUND(N82,Dins)) -> 60 | P82: =ROUND(N82/$P$14,Dins) -> 18.88 | Q82: =IF(A82>30000,ROUND(P82/$Q$14,Dins),ROUND(P82,Dins)) -> 16
A83: 90001 | C83: SP | D83: =ApuB!B$225 -> MORTERO 1:4 (cemento - arena) | E83: =ApuB!D$225 -> m3 | F83: =ApuB!E$225 -> 290.2 | L83: =ApuB!A$225 -> 10045 | O83: =IF(A83>30000,ROUND(N83/$O$14,Dins),ROUND(N83,Dins)) -> 0 | P83: =ROUND(N83/$P$14,Dins) -> 0 | Q83: =IF(A83>30000,ROUND(P83/$Q$14,Dins),ROUND(P83,Dins)) -> 0
A84: 30044 | B84: 2 | C84: MA | D84: CLAVOS PARA MADERA CON CABEZA DE 1" | E84: kg | F84: =IF(AND($F$15=Datos!$AI$5,Datos!$C$9=Datos!$AI$10),IF(A84>30000,N84,ROUND(N84*Datos!$J$18,Dins)),IF(AND($F$15=Datos!$AI$5,Datos!$C$9=Datos!$AI$9),IF(A84>30000,O84,ROUND(O84*Datos!$J$18,Dins)),IF(AND($F$15=Datos!$AI$6,Datos!$C$9=Datos!$AI$10),IF(A84>30000,P84,ROUND(P84*Datos!$J$18,Dins)),IF(AND($F$15=Datos!$AI$6,Datos!$C$9=Datos!$AI$9),IF(A84>30000,Q84,ROUND(Q84*Datos!$J$18,Dins)))))) -> 4.5 | N84: 5.31 | O84: =IF(A84>30000,ROUND(N84/$O$14,Dins),ROUND(N84,Dins)) -> 4.5 | P84: =ROUND(N84/$P$14,Dins) -> 1.42 | Q84: =IF(A84>30000,ROUND(P84/$Q$14,Dins),ROUND(P84,Dins)) -> 1.2
A85: 30045 | B85: 39 | C85: MA | D85: AGUARRAS MINERAL | E85: gal | F85: =IF(AND($F$15=Datos!$AI$5,Datos!$C$9=Datos!$AI$10),IF(A85>30000,N85,ROUND(N85*Datos!$J$18,Dins)),IF(AND($F$15=Datos!$AI$5,Datos!$C$9=Datos!$AI$9),IF(A85>30000,O85,ROUND(O85*Datos!$J$18,Dins)),IF(AND($F$15=Datos!$AI$6,Datos!$C$9=Datos!$AI$10),IF(A85>30000,P85,ROUND(P85*Datos!$J$18,Dins)),IF(AND($F$15=Datos!$AI$6,Datos!$C$9=Datos!$AI$9),IF(A85>30000,Q85,ROUND(Q85*Datos!$J$18,Dins)))))) -> 28 | N85: 33.04 | O85: =IF(A85>30000,ROUND(N85/$O$14,Dins),ROUND(N85,Dins)) -> 28 | P85: =ROUND(N85/$P$14,Dins) -> 8.81 | Q85: =IF(A85>30000,ROUND(P85/$Q$14,Dins),ROUND(P85,Dins)) -> 7.47
A86: 30046 | B86: 54 | C86: MA | D86: BARNIZ MARINO | E86: gal | F86: =IF(AND($F$15=Datos!$AI$5,Datos!$C$9=Datos!$AI$10),IF(A86>30000,N86,ROUND(N86*Datos!$J$18,Dins)),IF(AND($F$15=Datos!$AI$5,Datos!$C$9=Datos!$AI$9),IF(A86>30000,O86,ROUND(O86*Datos!$J$18,Dins)),IF(AND($F$15=Datos!$AI$6,Datos!$C$9=Datos!$AI$10),IF(A86>30000,P86,ROUND(P86*Datos!$J$18,Dins)),IF(AND($F$15=Datos!$AI$6,Datos!$C$9=Datos!$AI$9),IF(A86>30000,Q86,ROUND(Q86*Datos!$J$18,Dins)))))) -> 60 | N86: 70.8 | O86: =IF(A86>30000,ROUND(N86/$O$14,Dins),ROUND(N86,Dins)) -> 60 | P86: =ROUND(N86/$P$14,Dins) -> 18.88 | Q86: =IF(A86>30000,ROUND(P86/$Q$14,Dins),ROUND(P86,Dins)) -> 16
A87: 30047 | B87: 37 | C87: MA | D87: REGLA DE ALUMINIO 1½" X 4" X 10" | E87: und | F87: =IF(AND($F$15=Datos!$AI$5,Datos!$C$9=Datos!$AI$10),IF(A87>30000,N87,ROUND(N87*Datos!$J$18,Dins)),IF(AND($F$15=Datos!$AI$5,Datos!$C$9=Datos!$AI$9),IF(A87>30000,O87,ROUND(O87*Datos!$J$18,Dins)),IF(AND($F$15=Datos!$AI$6,Datos!$C$9=Datos!$AI$10),IF(A87>30000,P87,ROUND(P87*Datos!$J$18,Dins)),IF(AND($F$15=Datos!$AI$6,Datos!$C$9=Datos!$AI$9),IF(A87>30000,Q87,ROUND(Q87*Datos!$J$18,Dins)))))) -> 72 | N87: 84.96 | O87: =IF(A87>30000,ROUND(N87/$O$14,Dins),ROUND(N87,Dins)) -> 72 | P87: =ROUND(N87/$P$14,Dins) -> 22.66 | Q87: =IF(A87>30000,ROUND(P87/$Q$14,Dins),ROUND(P87,Dins)) -> 19.2
A88: 30048 | B88: 30 | C88: MA | D88: PORCELANATO VULCANO DE ZANNON 30 X 30 cm | E88: m2 | F88: =IF(AND($F$15=Datos!$AI$5,Datos!$C$9=Datos!$AI$10),IF(A88>30000,N88,ROUND(N88*Datos!$J$18,Dins)),IF(AND($F$15=Datos!$AI$5,Datos!$C$9=Datos!$AI$9),IF(A88>30000,O88,ROUND(O88*Datos!$J$18,Dins)),IF(AND($F$15=Datos!$AI$6,Datos!$C$9=Datos!$AI$10),IF(A88>30000,P88,ROUND(P88*Datos!$J$18,Dins)),IF(AND($F$15=Datos!$AI$6,Datos!$C$9=Datos!$AI$9),IF(A88>30000,Q88,ROUND(Q88*Datos!$J$18,Dins)))))) -> 16.5 | N88: 19.47 | O88: =IF(A88>30000,ROUND(N88/$O$14,Dins),ROUND(N88,Dins)) -> 16.5 | P88: =ROUND(N88/$P$14,Dins) -> 5.19 | Q88: =IF(A88>30000,ROUND(P88/$Q$14,Dins),ROUND(P88,Dins)) -> 4.4
A89: 30049 | B89: 39 | C89: MA | D89: FRAGUA NOVACEL COLOR GRIS | E89: kg | F89: =IF(AND($F$15=Datos!$AI$5,Datos!$C$9=Datos!$AI$10),IF(A89>30000,N89,ROUND(N89*Datos!$J$18,Dins)),IF(AND($F$15=Datos!$AI$5,Datos!$C$9=Datos!$AI$9),IF(A89>30000,O89,ROUND(O89*Datos!$J$18,Dins)),IF(AND($F$15=Datos!$AI$6,Datos!$C$9=Datos!$AI$10),IF(A89>30000,P89,ROUND(P89*Datos!$J$18,Dins)),IF(AND($F$15=Datos!$AI$6,Datos!$C$9=Datos!$AI$9),IF(A89>30000,Q89,ROUND(Q89*Datos!$J$18,Dins)))))) -> 6 | N89: 7.08 | O89: =IF(A89>30000,ROUND(N89/$O$14,Dins),ROUND(N89,Dins)) -> 6 | P89: =ROUND(N89/$P$14,Dins) -> 1.89 | Q89: =IF(A89>30000,ROUND(P89/$Q$14,Dins),ROUND(P89,Dins)) -> 1.6
A90: 90002 | C90: SP | D90: =ApuB!B$255 -> FRAGUA CON POLVO NOVACEL | E90: =ApuB!D$255 -> m2 | F90: =ApuB!E$255 -> 9.85 | L90: =ApuB!A$255 -> 10051 | O90: =IF(A90>30000,ROUND(N90/$O$14,Dins),ROUND(N90,Dins)) -> 0 | P90: =ROUND(N90/$P$14,Dins) -> 0 | Q90: =IF(A90>30000,ROUND(P90/$Q$14,Dins),ROUND(P90,Dins)) -> 0
A91: 30050 | B91: 30 | C91: MA | D91: PEGAMENTO EN POLVO NOVACEL | E91: kg | F91: =IF(AND($F$15=Datos!$AI$5,Datos!$C$9=Datos!$AI$10),IF(A91>30000,N91,ROUND(N91*Datos!$J$18,Dins)),IF(AND($F$15=Datos!$AI$5,Datos!$C$9=Datos!$AI$9),IF(A91>30000,O91,ROUND(O91*Datos!$J$18,Dins)),IF(AND($F$15=Datos!$AI$6,Datos!$C$9=Datos!$AI$10),IF(A91>30000,P91,ROUND(P91*Datos!$J$18,Dins)),IF(AND($F$15=Datos!$AI$6,Datos!$C$9=Datos!$AI$9),IF(A91>30000,Q91,ROUND(Q91*Datos!$J$18,Dins)))))) -> 0.6 | N91: 0.71 | O91: =IF(A91>30000,ROUND(N91/$O$14,Dins),ROUND(N91,Dins)) -> 0.6 | P91: =ROUND(N91/$P$14,Dins) -> 0.19 | Q91: =IF(A91>30000,ROUND(P91/$Q$14,Dins),ROUND(P91,Dins)) -> 0.16
A92: 30051 | B92: 24 | C92: MA | D92: CERAMICA CELIMA SERIE ANTIDESLIZANTE MOSAICO PISO/PARED 0.30X0.30 | E92: m2 | F92: =IF(AND($F$15=Datos!$AI$5,Datos!$C$9=Datos!$AI$10),IF(A92>30000,N92,ROUND(N92*Datos!$J$18,Dins)),IF(AND($F$15=Datos!$AI$5,Datos!$C$9=Datos!$AI$9),IF(A92>30000,O92,ROUND(O92*Datos!$J$18,Dins)),IF(AND($F$15=Datos!$AI$6,Datos!$C$9=Datos!$AI$10),IF(A92>30000,P92,ROUND(P92*Datos!$J$18,Dins)),IF(AND($F$15=Datos!$AI$6,Datos!$C$9=Datos!$AI$9),IF(A92>30000,Q92,ROUND(Q92*Datos!$J$18,Dins)))))) -> 45 | N92: 53.1 | O92: =IF(A92>30000,ROUND(N92/$O$14,Dins),ROUND(N92,Dins)) -> 45 | P92: =ROUND(N92/$P$14,Dins) -> 14.16 | Q92: =IF(A92>30000,ROUND(P92/$Q$14,Dins),ROUND(P92,Dins)) -> 12
A93: 30052 | B93: 39 | C93: MA | D93: ESCOBAS DE PAJA | E93: und | F93: =IF(AND($F$15=Datos!$AI$5,Datos!$C$9=Datos!$AI$10),IF(A93>30000,N93,ROUND(N93*Datos!$J$18,Dins)),IF(AND($F$15=Datos!$AI$5,Datos!$C$9=Datos!$AI$9),IF(A93>30000,O93,ROUND(O93*Datos!$J$18,Dins)),IF(AND($F$15=Datos!$AI$6,Datos!$C$9=Datos!$AI$10),IF(A93>30000,P93,ROUND(P93*Datos!$J$18,Dins)),IF(AND($F$15=Datos!$AI$6,Datos!$C$9=Datos!$AI$9),IF(A93>30000,Q93,ROUND(Q93*Datos!$J$18,Dins)))))) -> 12 | N93: 14.16 | O93: =IF(A93>30000,ROUND(N93/$O$14,Dins),ROUND(N93,Dins)) -> 12 | P93: =ROUND(N93/$P$14,Dins) -> 3.78 | Q93: =IF(A93>30000,ROUND(P93/$Q$14,Dins),ROUND(P93,Dins)) -> 3.2
A94: 90003 | C94: SP | D94: =ApuB!B$270 -> BASE GRANULAR E=0.10 m.COMPACTADA CON EQUIPO LIVIANO | E94: =ApuB!D$270 -> m2 | F94: =ApuB!E$270 -> 13.64 | L94: =ApuB!A$270 -> 10054 | O94: =IF(A94>30000,ROUND(N94/$O$14,Dins),ROUND(N94,Dins)) -> 0 | P94: =ROUND(N94/$P$14,Dins) -> 0 | Q94: =IF(A94>30000,ROUND(P94/$Q$14,Dins),ROUND(P94,Dins)) -> 0
A95: 30053 | B95: 30 | C95: MA | D95: PORCELANA NOVACEL COLOR | E95: kg | F95: =IF(AND($F$15=Datos!$AI$5,Datos!$C$9=Datos!$AI$10),IF(A95>30000,N95,ROUND(N95*Datos!$J$18,Dins)),IF(AND($F$15=Datos!$AI$5,Datos!$C$9=Datos!$AI$9),IF(A95>30000,O95,ROUND(O95*Datos!$J$18,Dins)),IF(AND($F$15=Datos!$AI$6,Datos!$C$9=Datos!$AI$10),IF(A95>30000,P95,ROUND(P95*Datos!$J$18,Dins)),IF(AND($F$15=Datos!$AI$6,Datos!$C$9=Datos!$AI$9),IF(A95>30000,Q95,ROUND(Q95*Datos!$J$18,Dins)))))) -> 6 | N95: 7.08 | O95: =IF(A95>30000,ROUND(N95/$O$14,Dins),ROUND(N95,Dins)) -> 6 | P95: =ROUND(N95/$P$14,Dins) -> 1.89 | Q95: =IF(A95>30000,ROUND(P95/$Q$14,Dins),ROUND(P95,Dins)) -> 1.6
...

Sheet ApuB
A1: 0 | B1: =MATCH($A$1,$A$5:$A$50004,0)+4 -> #N/A | C1: =#REF! -> #REF!
A2: =COUNT(BDcodCU)*5+5 -> 490 | C2: =COUNT(BDcodCU) -> 97
A3: =MAX($A$5:$A$50004)+1 -> 10098 | B3: Cifra de redondeo decimal del parcial | C3: =Datos!J12 -> 2
A4: Cod | B4: Denominación | C4: RTOf | D4: UND | E4: PU | F4: MO | G4: MA | H4: EQ | I4: nINS | J4: RTOi | K4: P.EST. | M4: SP | N4: ET | O4: 1 | P4: 2 | Q4: 3 | R4: 4 | S4: 5 | T4: 6 | U4: 7 | V4: 8 | W4: 9 | X4: 10 | Y4: 11 | Z4: 12 | AA4: 13 | AB4: 14 | AC4: 15 | AD4: 16 | AE4: 17 | AF4: 18 | AG4: 19 | AH4: 20 | AI4: 21 | AJ4: 22 | AK4: 23 | AL4: 24 | AM4: 25 | AN4: 26 | AO4: 27 | AP4: 28 | AQ4: 29 | AR4: 30 | AS4: 31 | AT4: 32 | AU4: 33 | AV4: 34 | AW4: 35 | AX4: 36 | AY4: 37 | AZ4: 38 | BA4: 39 | BB4: 40 | BC4: 41 | BD4: 42 | BE4: 43 | BF4: 44 | BG4: 45 | BH4: 46 | BI4: 47 | BJ4: 48 | BK4: 49 | BL4: 50 | BM4: 51 | BN4: 52 | BO4: 53 | BP4: 54 | BQ4: 55 | BR4: 56 | BS4: 57 | BT4: 58 | BU4: 59 | BV4: 60 | BW4: 61 | BX4: 62 | BY4: 63 | BZ4: 64 | CA4: 65 | CB4: 66 | CC4: 67 | CD4: 68 | CE4: 69 | CF4: 70 | CG4: 71 | CH4: 72 | CI4: 73 | CJ4: 74 | CK4: 75 | CL4: 76 | CM4: 77 | CN4: 78 | CO4: 79 | CP4: 80 | CQ4: 81 | CR4: 82 | CS4: 83 | CT4: 84 | CU4: 85 | CV4: 86 | CW4: 87 | CX4: 88 | CY4: 89 | CZ4: 90 | DA4: 91 | DB4: 92 | DC4: 93 | DD4: 94 | DE4: 95 | DF4: 96 | DG4: 97 | DH4: 98 | DI4: 99 | DJ4: 100
A5: 10001 | B5: TRAZO Y REPLANTEO INICIAL | C5: =ROUND(J5*JL*Frto/8,4) -> 200 | D5: m2 | E5: =SUM($O8:$X8) -> 3.02 | F5: =SUMIF($O5:$X5,"<22501",$O8:$X8) -> 1.21 | G5: =SUMIFS($O8:$X8,$O5:$X5,">30000",$O5:$X5,"<50001") -> 1.41 | H5: =SUMIFS($O8:$X8,$O5:$X5,">60000",$O5:$X5,"<70001") -> 0.4 | I5: 10 | J5: 200 | O5: 10001 | P5: 10002 | Q5: 30001 | R5: 30002 | S5: 30003 | T5: 30004 | U5: 30005 | V5: 30006 | W5: 60001 | X5: 60002
B6: =A5&"C" -> 10001C | O6: 1 | P6: 1 | Q6: 0.018 | R6: 0.0062 | S6: 0.02 | T6: 0.01 | U6: 0.005 | V6: 0.0015 | W6: 1 | X6: 1
O7: =IF(O9>10000,HLOOKUP(O9,N5:$O8,4,FALSE),IF(OR(AND(22500<O5,O5<25001),AND(50000<O5,O5<53501),AND(70000<O5,O5<72501)),$F5,IF(OR(AND(25001<O5,O5<27501),AND(53500<O5,O5<57001),AND(72500<O5,O5<75001)),$G5,IF(OR(AND(27500<O5,O5<30001),AND(57000<O5,O5<60001),AND(75000<O5,O5<77500)),$H5,VLOOKUP(O5,BDins,6,FALSE))))) -> 12.64 | P7: =IF(P9>10000,HLOOKUP(P9,O5:$O8,4,FALSE),IF(OR(AND(22500<P5,P5<25001),AND(50000<P5,P5<53501),AND(70000<P5,P5<72501)),$F5,IF(OR(AND(25001<P5,P5<27501),AND(53500<P5,P5<57001),AND(72500<P5,P5<75001)),$G5,IF(OR(AND(27500<P5,P5<30001),AND(57000<P5,P5<60001),AND(75000<P5,P5<77500)),$H5,VLOOKUP(P5,BDins,6,FALSE))))) -> 17.59 | Q7: =IF(Q9>10000,HLOOKUP(Q9,$O5:P8,4,FALSE),IF(OR(AND(22500<Q5,Q5<25001),AND(50000<Q5,Q5<53501),AND(70000<Q5,Q5<72501)),$F5,IF(OR(AND(25001<Q5,Q5<27501),AND(53500<Q5,Q5<57001),AND(72500<Q5,Q5<75001)),$G5,IF(OR(AND(27500<Q5,Q5<30001),AND(57000<Q5,Q5<60001),AND(75000<Q5,Q5<77500)),$H5,VLOOKUP(Q5,BDins,6,FALSE))))) -> 27 | R7: =IF(R9>10000,HLOOKUP(R9,$O5:Q8,4,FALSE),IF(OR(AND(22500<R5,R5<25001),AND(50000<R5,R5<53501),AND(70000<R5,R5<72501)),$F5,IF(OR(AND(25001<R5,R5<27501),AND(53500<R5,R5<57001),AND(72500<R5,R5<75001)),$G5,IF(OR(AND(27500<R5,R5<30001),AND(57000<R5,R5<60001),AND(75000<R5,R5<77500)),$H5,VLOOKUP(R5,BDins,6,FALSE))))) -> 41.3 | S7: =IF(S9>10000,HLOOKUP(S9,$O5:R8,4,FALSE),IF(OR(AND(22500<S5,S5<25001),AND(50000<S5,S5<53501),AND(70000<S5,S5<72501)),$F5,IF(OR(AND(25001<S5,S5<27501),AND(53500<S5,S5<57001),AND(72500<S5,S5<75001)),$G5,IF(OR(AND(27500<S5,S5<30001),AND(57000<S5,S5<60001),AND(75000<S5,S5<77500)),$H5,VLOOKUP(S5,BDins,6,FALSE))))) -> 20 | T7: =IF(T9>10000,HLOOKUP(T9,$O5:S8,4,FALSE),IF(OR(AND(22500<T5,T5<25001),AND(50000<T5,T5<53501),AND(70000<T5,T5<72501)),$F5,IF(OR(AND(25001<T5,T5<27501),AND(53500<T5,T5<57001),AND(72500<T5,T5<75001)),$G5,IF(OR(AND(27500<T5,T5<30001),AND(57000<T5,T5<60001),AND(75000<T5,T5<77500)),$H5,VLOOKUP(T5,BDins,6,FALSE))))) -> 8 | U7: =IF(U9>10000,HLOOKUP(U9,$O5:T8,4,FALSE),IF(OR(AND(22500<U5,U5<25001),AND(50000<U5,U5<53501),AND(70000<U5,U5<72501)),$F5,IF(OR(AND(25001<U5,U5<27501),AND(53500<U5,U5<57001),AND(72500<U5,U5<75001)),$G5,IF(OR(AND(27500<U5,U5<30001),AND(57000<U5,U5<60001),AND(75000<U5,U5<77500)),$H5,VLOOKUP(U5,BDins,6,FALSE))))) -> 28 | V7: =IF(V9>10000,HLOOKUP(V9,$O5:U8,4,FALSE),IF(OR(AND(22500<V5,V5<25001),AND(50000<V5,V5<53501),AND(70000<V5,V5<72501)),$F5,IF(OR(AND(25001<V5,V5<27501),AND(53500<V5,V5<57001),AND(72500<V5,V5<75001)),$G5,IF(OR(AND(27500<V5,V5<30001),AND(57000<V5,V5<60001),AND(75000<V5,V5<77500)),$H5,VLOOKUP(V5,BDins,6,FALSE))))) -> 23.8 | W7: =IF(W9>10000,HLOOKUP(W9,$O5:V8,4,FALSE),IF(OR(AND(22500<W5,W5<25001),AND(50000<W5,W5<53501),AND(70000<W5,W5<72501)),$F5,IF(OR(AND(25001<W5,W5<27501),AND(53500<W5,W5<57001),AND(72500<W5,W5<75001)),$G5,IF(OR(AND(27500<W5,W5<30001),AND(57000<W5,W5<60001),AND(75000<W5,W5<77500)),$H5,VLOOKUP(W5,BDins,6,FALSE))))) -> 3.75 | X7: =IF(X9>10000,HLOOKUP(X9,$O5:W8,4,FALSE),IF(OR(AND(22500<X5,X5<25001),AND(50000<X5,X5<53501),AND(70000<X5,X5<72501)),$F5,IF(OR(AND(25001<X5,X5<27501),AND(53500<X5,X5<57001),AND(72500<X5,X5<75001)),$G5,IF(OR(AND(27500<X5,X5<30001),AND(57000<X5,X5<60001),AND(75000<X5,X5<77500)),$H5,VLOOKUP(X5,BDins,6,FALSE))))) -> 6.25
O8: =IF($K5>0,ROUND(O6*$E5/100,DpCU),IF(O9>10000,ROUND(HLOOKUP(O9,$O5:$X8,4,FALSE)/100*O6,DpCU),IF(OR(O5<20001,O5>95000,AND(60000<O5,O5<70001)),ROUND(ROUND(O6*JL/$C5,DcCU)*O7,DpCU),IF(OR(AND(20000<O5,O5<22501),AND(30000<O5,O5<50001),77500<O5),ROUND(O7*O6,DpCU),IF(OR(AND(22500<O5,O5<25001),AND(50000<O5,O5<53501),AND(70000<O5,O5<72501)),ROUND($F5/100*O6,DpCU),IF(OR(AND(25000<O5,O5<27501),AND(53500<O5,O5<57001),AND(72500<O5,O5<75001)),ROUND($G5/100*O6,DpCU),ROUND($H5/100*O6,DpCU))))))) -> 0.51 | P8: =IF($K5>0,ROUND(P6*$E5/100,DpCU),IF(P9>10000,ROUND(HLOOKUP(P9,$O5:$X8,4,FALSE)/100*P6,DpCU),IF(OR(P5<20001,P5>95000,AND(60000<P5,P5<70001)),ROUND(ROUND(P6*JL/$C5,DcCU)*P7,DpCU),IF(OR(AND(20000<P5,P5<22501),AND(30000<P5,P5<50001),77500<P5),ROUND(P7*P6,DpCU),IF(OR(AND(22500<P5,P5<25001),AND(50000<P5,P5<53501),AND(70000<P5,P5<72501)),ROUND($F5/100*P6,DpCU),IF(OR(AND(25000<P5,P5<27501),AND(53500<P5,P5<57001),AND(72500<P5,P5<75001)),ROUND($G5/100*P6,DpCU),ROUND($H5/100*P6,DpCU))))))) -> 0.7 | Q8: =IF($K5>0,ROUND(Q6*$E5/100,DpCU),IF(Q9>10000,ROUND(HLOOKUP(Q9,$O5:$X8,4,FALSE)/100*Q6,DpCU),IF(OR(Q5<20001,Q5>95000,AND(60000<Q5,Q5<70001)),ROUND(ROUND(Q6*JL/$C5,DcCU)*Q7,DpCU),IF(OR(AND(20000<Q5,Q5<22501),AND(30000<Q5,Q5<50001),77500<Q5),ROUND(Q7*Q6,DpCU),IF(OR(AND(22500<Q5,Q5<25001),AND(50000<Q5,Q5<53501),AND(70000<Q5,Q5<72501)),ROUND($F5/100*Q6,DpCU),IF(OR(AND(25000<Q5,Q5<27501),AND(53500<Q5,Q5<57001),AND(72500<Q5,Q5<75001)),ROUND($G5/100*Q6,DpCU),ROUND($H5/100*Q6,DpCU))))))) -> 0.49 | R8: =IF($K5>0,ROUND(R6*$E5/100,DpCU),IF(R9>10000,ROUND(HLOOKUP(R9,$O5:$X8,4,FALSE)/100*R6,DpCU),IF(OR(R5<20001,R5>95000,AND(60000<R5,R5<70001)),ROUND(ROUND(R6*JL/$C5,DcCU)*R7,DpCU),IF(OR(AND(20000<R5,R5<22501),AND(30000<R5,R5<50001),77500<R5),ROUND(R7*R6,DpCU),IF(OR(AND(22500<R5,R5<25001),AND(50000<R5,R5<53501),AND(70000<R5,R5<72501)),ROUND($F5/100*R6,DpCU),IF(OR(AND(25000<R5,R5<27501),AND(53500<R5,R5<57001),AND(72500<R5,R5<75001)),ROUND($G5/100*R6,DpCU),ROUND($H5/100*R6,DpCU))))))) -> 0.26 | S8: =IF($K5>0,ROUND(S6*$E5/100,DpCU),IF(S9>10000,ROUND(HLOOKUP(S9,$O5:$X8,4,FALSE)/100*S6,DpCU),IF(OR(S5<20001,S5>95000,AND(60000<S5,S5<70001)),ROUND(ROUND(S6*JL/$C5,DcCU)*S7,DpCU),IF(OR(AND(20000<S5,S5<22501),AND(30000<S5,S5<50001),77500<S5),ROUND(S7*S6,DpCU),IF(OR(AND(22500<S5,S5<25001),AND(50000<S5,S5<53501),AND(70000<S5,S5<72501)),ROUND($F5/100*S6,DpCU),IF(OR(AND(25000<S5,S5<27501),AND(53500<S5,S5<57001),AND(72500<S5,S5<75001)),ROUND($G5/100*S6,DpCU),ROUND($H5/100*S6,DpCU))))))) -> 0.4 | T8: =IF($K5>0,ROUND(T6*$E5/100,DpCU),IF(T9>10000,ROUND(HLOOKUP(T9,$O5:$X8,4,FALSE)/100*T6,DpCU),IF(OR(T5<20001,T5>95000,AND(60000<T5,T5<70001)),ROUND(ROUND(T6*JL/$C5,DcCU)*T7,DpCU),IF(OR(AND(20000<T5,T5<22501),AND(30000<T5,T5<50001),77500<T5),ROUND(T7*T6,DpCU),IF(OR(AND(22500<T5,T5<25001),AND(50000<T5,T5<53501),AND(70000<T5,T5<72501)),ROUND($F5/100*T6,DpCU),IF(OR(AND(25000<T5,T5<27501),AND(53500<T5,T5<57001),AND(72500<T5,T5<75001)),ROUND($G5/100*T6,DpCU),ROUND($H5/100*T6,DpCU))))))) -> 0.08 | U8: =IF($K5>0,ROUND(U6*$E5/100,DpCU),IF(U9>10000,ROUND(HLOOKUP(U9,$O5:$X8,4,FALSE)/100*U6,DpCU),IF(OR(U5<20001,U5>95000,AND(60000<U5,U5<70001)),ROUND(ROUND(U6*JL/$C5,DcCU)*U7,DpCU),IF(OR(AND(20000<U5,U5<22501),AND(30000<U5,U5<50001),77500<U5),ROUND(U7*U6,DpCU),IF(OR(AND(22500<U5,U5<25001),AND(50000<U5,U5<53501),AND(70000<U5,U5<72501)),ROUND($F5/100*U6,DpCU),IF(OR(AND(25000<U5,U5<27501),AND(53500<U5,U5<57001),AND(72500<U5,U5<75001)),ROUND($G5/100*U6,DpCU),ROUND($H5/100*U6,DpCU))))))) -> 0.14 | V8: =IF($K5>0,ROUND(V6*$E5/100,DpCU),IF(V9>10000,ROUND(HLOOKUP(V9,$O5:$X8,4,FALSE)/100*V6,DpCU),IF(OR(V5<20001,V5>95000,AND(60000<V5,V5<70001)),ROUND(ROUND(V6*JL/$C5,DcCU)*V7,DpCU),IF(OR(AND(20000<V5,V5<22501),AND(30000<V5,V5<50001),77500<V5),ROUND(V7*V6,DpCU),IF(OR(AND(22500<V5,V5<25001),AND(50000<V5,V5<53501),AND(70000<V5,V5<72501)),ROUND($F5/100*V6,DpCU),IF(OR(AND(25000<V5,V5<27501),AND(53500<V5,V5<57001),AND(72500<V5,V5<75001)),ROUND($G5/100*V6,DpCU),ROUND($H5/100*V6,DpCU))))))) -> 0.04 | ... X8: =IF($K5>0,ROUND(X6*$E5/100,DpCU),IF(X9>10000,ROUND(HLOOKUP(X9,$O5:$X8,4,FALSE)/100*X6,DpCU),IF(OR(X5<20001,X5>95000,AND(60000<X5,X5<70001)),ROUND(ROUND(X6*JL/$C5,DcCU)*X7,DpCU),IF(OR(AND(20000<X5,X5<22501),AND(30000<X5,X5<50001),77500<X5),ROUND(X7*X6,DpCU),IF(OR(AND(22500<X5,X5<25001),AND(50000<X5,X5<53501),AND(70000<X5,X5<72501)),ROUND($F5/100*X6,DpCU),IF(OR(AND(25000<X5,X5<27501),AND(53500<X5,X5<57001),AND(72500<X5,X5<75001)),ROUND($G5/100*X6,DpCU),ROUND($H5/100*X6,DpCU))))))) -> 0.25
B9: =A5&"r" -> 10001r
A10: 10002 | B10: TRAZO DURANTE LA EJECUCION DE LA OBRA (casco) | C10: =ROUND(J10*JL*Frto/8,4) -> 1 | D10: mes | E10: =SUM($O13:$T13) -> 5296.05 | F10: =SUMIF($O10:$T10,"<22501",$O13:$T13) -> 4081.05 | G10: =SUMIFS($O13:$T13,$O10:$T10,">30000",$O10:$T10,"<50001") -> 1215 | H10: =SUMIFS($O13:$T13,$O10:$T10,">60000",$O10:$T10,"<70001") -> 0 | I10: 6 | J10: 1 | O10: 10001 | P10: 10002 | Q10: 30004 | R10: 30005 | S10: 30007 | T10: 30008
B11: =A10&"C" -> 10002C | O11: 16.875 | P11: 16.875 | Q11: 1 | R11: 0.25 | S11: 15 | T11: 15
O12: =IF(O14>10000,HLOOKUP(O14,N10:$O13,4,FALSE),IF(OR(AND(22500<O10,O10<25001),AND(50000<O10,O10<53501),AND(70000<O10,O10<72501)),$F10,IF(OR(AND(25001<O10,O10<27501),AND(53500<O10,O10<57001),AND(72500<O10,O10<75001)),$G10,IF(OR(AND(27500<O10,O10<30001),AND(57000<O10,O10<60001),AND(75000<O10,O10<77500)),$H10,VLOOKUP(O10,BDins,6,FALSE))))) -> 12.64 | P12: =IF(P14>10000,HLOOKUP(P14,O10:$O13,4,FALSE),IF(OR(AND(22500<P10,P10<25001),AND(50000<P10,P10<53501),AND(70000<P10,P10<72501)),$F10,IF(OR(AND(25001<P10,P10<27501),AND(53500<P10,P10<57001),AND(72500<P10,P10<75001)),$G10,IF(OR(AND(27500<P10,P10<30001),AND(57000<P10,P10<60001),AND(75000<P10,P10<77500)),$H10,VLOOKUP(P10,BDins,6,FALSE))))) -> 17.59 | Q12: =IF(Q14>10000,HLOOKUP(Q14,$O10:P13,4,FALSE),IF(OR(AND(22500<Q10,Q10<25001),AND(50000<Q10,Q10<53501),AND(70000<Q10,Q10<72501)),$F10,IF(OR(AND(25001<Q10,Q10<27501),AND(53500<Q10,Q10<57001),AND(72500<Q10,Q10<75001)),$G10,IF(OR(AND(27500<Q10,Q10<30001),AND(57000<Q10,Q10<60001),AND(75000<Q10,Q10<77500)),$H10,VLOOKUP(Q10,BDins,6,FALSE))))) -> 8 | R12: =IF(R14>10000,HLOOKUP(R14,$O10:Q13,4,FALSE),IF(OR(AND(22500<R10,R10<25001),AND(50000<R10,R10<53501),AND(70000<R10,R10<72501)),$F10,IF(OR(AND(25001<R10,R10<27501),AND(53500<R10,R10<57001),AND(72500<R10,R10<75001)),$G10,IF(OR(AND(27500<R10,R10<30001),AND(57000<R10,R10<60001),AND(75000<R10,R10<77500)),$H10,VLOOKUP(R10,BDins,6,FALSE))))) -> 28 | S12: =IF(S14>10000,HLOOKUP(S14,$O10:R13,4,FALSE),IF(OR(AND(22500<S10,S10<25001),AND(50000<S10,S10<53501),AND(70000<S10,S10<72501)),$F10,IF(OR(AND(25001<S10,S10<27501),AND(53500<S10,S10<57001),AND(72500<S10,S10<75001)),$G10,IF(OR(AND(27500<S10,S10<30001),AND(57000<S10,S10<60001),AND(75000<S10,S10<77500)),$H10,VLOOKUP(S10,BDins,6,FALSE))))) -> 30 | T12: =IF(T14>10000,HLOOKUP(T14,$O10:S13,4,FALSE),IF(OR(AND(22500<T10,T10<25001),AND(50000<T10,T10<53501),AND(70000<T10,T10<72501)),$F10,IF(OR(AND(25001<T10,T10<27501),AND(53500<T10,T10<57001),AND(72500<T10,T10<75001)),$G10,IF(OR(AND(27500<T10,T10<30001),AND(57000<T10,T10<60001),AND(75000<T10,T10<77500)),$H10,VLOOKUP(T10,BDins,6,FALSE))))) -> 50
O13: =IF($K10>0,ROUND(O11*$E10/100,DpCU),IF(O14>10000,ROUND(HLOOKUP(O14,$O10:$T13,4,FALSE)/100*O11,DpCU),IF(OR(O10<20001,O10>95000,AND(60000<O10,O10<70001)),ROUND(ROUND(O11*JL/$C10,DcCU)*O12,DpCU),IF(OR(AND(20000<O10,O10<22501),AND(30000<O10,O10<50001),77500<O10),ROUND(O12*O11,DpCU),IF(OR(AND(22500<O10,O10<25001),AND(50000<O10,O10<53501),AND(70000<O10,O10<72501)),ROUND($F10/100*O11,DpCU),IF(OR(AND(25000<O10,O10<27501),AND(53500<O10,O10<57001),AND(72500<O10,O10<75001)),ROUND($G10/100*O11,DpCU),ROUND($H10/100*O11,DpCU))))))) -> 1706.4 | P13: =IF($K10>0,ROUND(P11*$E10/100,DpCU),IF(P14>10000,ROUND(HLOOKUP(P14,$O10:$T13,4,FALSE)/100*P11,DpCU),IF(OR(P10<20001,P10>95000,AND(60000<P10,P10<70001)),ROUND(ROUND(P11*JL/$C10,DcCU)*P12,DpCU),IF(OR(AND(20000<P10,P10<22501),AND(30000<P10,P10<50001),77500<P10),ROUND(P12*P11,DpCU),IF(OR(AND(22500<P10,P10<25001),AND(50000<P10,P10<53501),AND(70000<P10,P10<72501)),ROUND($F10/100*P11,DpCU),IF(OR(AND(25000<P10,P10<27501),AND(53500<P10,P10<57001),AND(72500<P10,P10<75001)),ROUND($G10/100*P11,DpCU),ROUND($H10/100*P11,DpCU))))))) -> 2374.65 | Q13: =IF($K10>0,ROUND(Q11*$E10/100,DpCU),IF(Q14>10000,ROUND(HLOOKUP(Q14,$O10:$T13,4,FALSE)/100*Q11,DpCU),IF(OR(Q10<20001,Q10>95000,AND(60000<Q10,Q10<70001)),ROUND(ROUND(Q11*JL/$C10,DcCU)*Q12,DpCU),IF(OR(AND(20000<Q10,Q10<22501),AND(30000<Q10,Q10<50001),77500<Q10),ROUND(Q12*Q11,DpCU),IF(OR(AND(22500<Q10,Q10<25001),AND(50000<Q10,Q10<53501),AND(70000<Q10,Q10<72501)),ROUND($F10/100*Q11,DpCU),IF(OR(AND(25000<Q10,Q10<27501),AND(53500<Q10,Q10<57001),AND(72500<Q10,Q10<75001)),ROUND($G10/100*Q11,DpCU),ROUND($H10/100*Q11,DpCU))))))) -> 8 | R13: =IF($K10>0,ROUND(R11*$E10/100,DpCU),IF(R14>10000,ROUND(HLOOKUP(R14,$O10:$T13,4,FALSE)/100*R11,DpCU),IF(OR(R10<20001,R10>95000,AND(60000<R10,R10<70001)),ROUND(ROUND(R11*JL/$C10,DcCU)*R12,DpCU),IF(OR(AND(20000<R10,R10<22501),AND(30000<R10,R10<50001),77500<R10),ROUND(R12*R11,DpCU),IF(OR(AND(22500<R10,R10<25001),AND(50000<R10,R10<53501),AND(70000<R10,R10<72501)),ROUND($F10/100*R11,DpCU),IF(OR(AND(25000<R10,R10<27501),AND(53500<R10,R10<57001),AND(72500<R10,R10<75001)),ROUND($G10/100*R11,DpCU),ROUND($H10/100*R11,DpCU))))))) -> 7 | S13: =IF($K10>0,ROUND(S11*$E10/100,DpCU),IF(S14>10000,ROUND(HLOOKUP(S14,$O10:$T13,4,FALSE)/100*S11,DpCU),IF(OR(S10<20001,S10>95000,AND(60000<S10,S10<70001)),ROUND(ROUND(S11*JL/$C10,DcCU)*S12,DpCU),IF(OR(AND(20000<S10,S10<22501),AND(30000<S10,S10<50001),77500<S10),ROUND(S12*S11,DpCU),IF(OR(AND(22500<S10,S10<25001),AND(50000<S10,S10<53501),AND(70000<S10,S10<72501)),ROUND($F10/100*S11,DpCU),IF(OR(AND(25000<S10,S10<27501),AND(53500<S10,S10<57001),AND(72500<S10,S10<75001)),ROUND($G10/100*S11,DpCU),ROUND($H10/100*S11,DpCU))))))) -> 450 | T13: =IF($K10>0,ROUND(T11*$E10/100,DpCU),IF(T14>10000,ROUND(HLOOKUP(T14,$O10:$T13,4,FALSE)/100*T11,DpCU),IF(OR(T10<20001,T10>95000,AND(60000<T10,T10<70001)),ROUND(ROUND(T11*JL/$C10,DcCU)*T12,DpCU),IF(OR(AND(20000<T10,T10<22501),AND(30000<T10,T10<50001),77500<T10),ROUND(T12*T11,DpCU),IF(OR(AND(22500<T10,T10<25001),AND(50000<T10,T10<53501),AND(70000<T10,T10<72501)),ROUND($F10/100*T11,DpCU),IF(OR(AND(25000<T10,T10<27501),AND(53500<T10,T10<57001),AND(72500<T10,T10<75001)),ROUND($G10/100*T11,DpCU),ROUND($H10/100*T11,DpCU))))))) -> 750
B14: =A10&"r" -> 10002r
A15: 10003 | B15: CARTEL DE OBRA | C15: =ROUND(J15*JL*Frto/8,4) -> 1 | D15: und | E15: =SUM($O18:$O18) -> 500 | F15: =SUMIF($O15:$O15,"<22501",$O18:$O18) -> 0 | G15: =SUMIFS($O18:$O18,$O15:$O15,">30000",$O15:$O15,"<50001") -> 0 | H15: =SUMIFS($O18:$O18,$O15:$O15,">60000",$O15:$O15,"<70001") -> 0 | I15: 1 | J15: 1 | O15: 80001
B16: =A15&"C" -> 10003C | O16: 1
O17: =IF(O19>10000,HLOOKUP(O19,N15:$O18,4,FALSE),IF(OR(AND(22500<O15,O15<25001),AND(50000<O15,O15<53501),AND(70000<O15,O15<72501)),$F15,IF(OR(AND(25001<O15,O15<27501),AND(53500<O15,O15<57001),AND(72500<O15,O15<75001)),$G15,IF(OR(AND(27500<O15,O15<30001),AND(57000<O15,O15<60001),AND(75000<O15,O15<77500)),$H15,VLOOKUP(O15,BDins,6,FALSE))))) -> 500
O18: =IF($K15>0,ROUND(O16*$E15/100,DpCU),IF(O19>10000,ROUND(HLOOKUP(O19,$O15:$O18,4,FALSE)/100*O16,DpCU),IF(OR(O15<20001,O15>95000,AND(60000<O15,O15<70001)),ROUND(ROUND(O16*JL/$C15,DcCU)*O17,DpCU),IF(OR(AND(20000<O15,O15<22501),AND(30000<O15,O15<50001),77500<O15),ROUND(O17*O16,DpCU),IF(OR(AND(22500<O15,O15<25001),AND(50000<O15,O15<53501),AND(70000<O15,O15<72501)),ROUND($F15/100*O16,DpCU),IF(OR(AND(25000<O15,O15<27501),AND(53500<O15,O15<57001),AND(72500<O15,O15<75001)),ROUND($G15/100*O16,DpCU),ROUND($H15/100*O16,DpCU))))))) -> 500
B19: =A15&"r" -> 10003r
A20: 10004 | B20: INSTALACIONES DE OFICINA Y ALMACEN PROVISIONALES | C20: =ROUND(J20*JL*Frto/8,4) -> 0.5 | D20: glb | E20: =SUM($O23:$U23) -> 2519.27 | F20: =SUMIF($O20:$U20,"<22501",$O23:$U23) -> 991.04 | G20: =SUMIFS($O23:$U23,$O20:$U20,">30000",$O20:$U20,"<50001") -> 1498.5 | H20: =SUMIFS($O23:$U23,$O20:$U20,">60000",$O20:$U20,"<70001") -> 0 | I20: 7 | J20: 0.5 | O20: 10001 | P20: 10003 | Q20: 10004 | R20: 30009 | S20: 30010 | T20: 30011 | U20: 70001
B21: =A20&"C" -> 10004C | O21: 1 | P21: 1 | Q21: 2 | R21: 1 | S21: 180 | T21: 8 | U21: 3
O22: =IF(O24>10000,HLOOKUP(O24,N20:$O23,4,FALSE),IF(OR(AND(22500<O20,O20<25001),AND(50000<O20,O20<53501),AND(70000<O20,O20<72501)),$F20,IF(OR(AND(25001<O20,O20<27501),AND(53500<O20,O20<57001),AND(72500<O20,O20<75001)),$G20,IF(OR(AND(27500<O20,O20<30001),AND(57000<O20,O20<60001),AND(75000<O20,O20<77500)),$H20,VLOOKUP(O20,BDins,6,FALSE))))) -> 12.64 | P22: =IF(P24>10000,HLOOKUP(P24,O20:$O23,4,FALSE),IF(OR(AND(22500<P20,P20<25001),AND(50000<P20,P20<53501),AND(70000<P20,P20<72501)),$F20,IF(OR(AND(25001<P20,P20<27501),AND(53500<P20,P20<57001),AND(72500<P20,P20<75001)),$G20,IF(OR(AND(27500<P20,P20<30001),AND(57000<P20,P20<60001),AND(75000<P20,P20<77500)),$H20,VLOOKUP(P20,BDins,6,FALSE))))) -> 14.12 | Q22: =IF(Q24>10000,HLOOKUP(Q24,$O20:P23,4,FALSE),IF(OR(AND(22500<Q20,Q20<25001),AND(50000<Q20,Q20<53501),AND(70000<Q20,Q20<72501)),$F20,IF(OR(AND(25001<Q20,Q20<27501),AND(53500<Q20,Q20<57001),AND(72500<Q20,Q20<75001)),$G20,IF(OR(AND(27500<Q20,Q20<30001),AND(57000<Q20,Q20<60001),AND(75000<Q20,Q20<77500)),$H20,VLOOKUP(Q20,BDins,6,FALSE))))) -> 17.59 | R22: =IF(R24>10000,HLOOKUP(R24,$O20:Q23,4,FALSE),IF(OR(AND(22500<R20,R20<25001),AND(50000<R20,R20<53501),AND(70000<R20,R20<72501)),$F20,IF(OR(AND(25001<R20,R20<27501),AND(53500<R20,R20<57001),AND(72500<R20,R20<75001)),$G20,IF(OR(AND(27500<R20,R20<30001),AND(57000<R20,R20<60001),AND(75000<R20,R20<77500)),$H20,VLOOKUP(R20,BDins,6,FALSE))))) -> 4.5 | S22: =IF(S24>10000,HLOOKUP(S24,$O20:R23,4,FALSE),IF(OR(AND(22500<S20,S20<25001),AND(50000<S20,S20<53501),AND(70000<S20,S20<72501)),$F20,IF(OR(AND(25001<S20,S20<27501),AND(53500<S20,S20<57001),AND(72500<S20,S20<75001)),$G20,IF(OR(AND(27500<S20,S20<30001),AND(57000<S20,S20<60001),AND(75000<S20,S20<77500)),$H20,VLOOKUP(S20,BDins,6,FALSE))))) -> 7.5 | T22: =IF(T24>10000,HLOOKUP(T24,$O20:S23,4,FALSE),IF(OR(AND(22500<T20,T20<25001),AND(50000<T20,T20<53501),AND(70000<T20,T20<72501)),$F20,IF(OR(AND(25001<T20,T20<27501),AND(53500<T20,T20<57001),AND(72500<T20,T20<75001)),$G20,IF(OR(AND(27500<T20,T20<30001),AND(57000<T20,T20<60001),AND(75000<T20,T20<77500)),$H20,VLOOKUP(T20,BDins,6,FALSE))))) -> 18 | U22: =IF(U24>10000,HLOOKUP(U24,$O20:T23,4,FALSE),IF(OR(AND(22500<U20,U20<25001),AND(50000<U20,U20<53501),AND(70000<U20,U20<72501)),$F20,IF(OR(AND(25001<U20,U20<27501),AND(53500<U20,U20<57001),AND(72500<U20,U20<75001)),$G20,IF(OR(AND(27500<U20,U20<30001),AND(57000<U20,U20<60001),AND(75000<U20,U20<77500)),$H20,VLOOKUP(U20,BDins,6,FALSE))))) -> 991.04
O23: =IF($K20>0,ROUND(O21*$E20/100,DpCU),IF(O24>10000,ROUND(HLOOKUP(O24,$O20:$U23,4,FALSE)/100*O21,DpCU),IF(OR(O20<20001,O20>95000,AND(60000<O20,O20<70001)),ROUND(ROUND(O21*JL/$C20,DcCU)*O22,DpCU),IF(OR(AND(20000<O20,O20<22501),AND(30000<O20,O20<50001),77500<O20),ROUND(O22*O21,DpCU),IF(OR(AND(22500<O20,O20<25001),AND(50000<O20,O20<53501),AND(70000<O20,O20<72501)),ROUND($F20/100*O21,DpCU),IF(OR(AND(25000<O20,O20<27501),AND(53500<O20,O20<57001),AND(72500<O20,O20<75001)),ROUND($G20/100*O21,DpCU),ROUND($H20/100*O21,DpCU))))))) -> 202.24 | P23: =IF($K20>0,ROUND(P21*$E20/100,DpCU),IF(P24>10000,ROUND(HLOOKUP(P24,$O20:$U23,4,FALSE)/100*P21,DpCU),IF(OR(P20<20001,P20>95000,AND(60000<P20,P20<70001)),ROUND(ROUND(P21*JL/$C20,DcCU)*P22,DpCU),IF(OR(AND(20000<P20,P20<22501),AND(30000<P20,P20<50001),77500<P20),ROUND(P22*P21,DpCU),IF(OR(AND(22500<P20,P20<25001),AND(50000<P20,P20<53501),AND(70000<P20,P20<72501)),ROUND($F20/100*P21,DpCU),IF(OR(AND(25000<P20,P20<27501),AND(53500<P20,P20<57001),AND(72500<P20,P20<75001)),ROUND($G20/100*P21,DpCU),ROUND($H20/100*P21,DpCU))))))) -> 225.92 | Q23: =IF($K20>0,ROUND(Q21*$E20/100,DpCU),IF(Q24>10000,ROUND(HLOOKUP(Q24,$O20:$U23,4,FALSE)/100*Q21,DpCU),IF(OR(Q20<20001,Q20>95000,AND(60000<Q20,Q20<70001)),ROUND(ROUND(Q21*JL/$C20,DcCU)*Q22,DpCU),IF(OR(AND(20000<Q20,Q20<22501),AND(30000<Q20,Q20<50001),77500<Q20),ROUND(Q22*Q21,DpCU),IF(OR(AND(22500<Q20,Q20<25001),AND(50000<Q20,Q20<53501),AND(70000<Q20,Q20<72501)),ROUND($F20/100*Q21,DpCU),IF(OR(AND(25000<Q20,Q20<27501),AND(53500<Q20,Q20<57001),AND(72500<Q20,Q20<75001)),ROUND($G20/100*Q21,DpCU),ROUND($H20/100*Q21,DpCU))))))) -> 562.88 | R23: =IF($K20>0,ROUND(R21*$E20/100,DpCU),IF(R24>10000,ROUND(HLOOKUP(R24,$O20:$U23,4,FALSE)/100*R21,DpCU),IF(OR(R20<20001,R20>95000,AND(60000<R20,R20<70001)),ROUND(ROUND(R21*JL/$C20,DcCU)*R22,DpCU),IF(OR(AND(20000<R20,R20<22501),AND(30000<R20,R20<50001),77500<R20),ROUND(R22*R21,DpCU),IF(OR(AND(22500<R20,R20<25001),AND(50000<R20,R20<53501),AND(70000<R20,R20<72501)),ROUND($F20/100*R21,DpCU),IF(OR(AND(25000<R20,R20<27501),AND(53500<R20,R20<57001),AND(72500<R20,R20<75001)),ROUND($G20/100*R21,DpCU),ROUND($H20/100*R21,DpCU))))))) -> 4.5 | S23: =IF($K20>0,ROUND(S21*$E20/100,DpCU),IF(S24>10000,ROUND(HLOOKUP(S24,$O20:$U23,4,FALSE)/100*S21,DpCU),IF(OR(S20<20001,S20>95000,AND(60000<S20,S20<70001)),ROUND(ROUND(S21*JL/$C20,DcCU)*S22,DpCU),IF(OR(AND(20000<S20,S20<22501),AND(30000<S20,S20<50001),77500<S20),ROUND(S22*S21,DpCU),IF(OR(AND(22500<S20,S20<25001),AND(50000<S20,S20<53501),AND(70000<S20,S20<72501)),ROUND($F20/100*S21,DpCU),IF(OR(AND(25000<S20,S20<27501),AND(53500<S20,S20<57001),AND(72500<S20,S20<75001)),ROUND($G20/100*S21,DpCU),ROUND($H20/100*S21,DpCU))))))) -> 1350 | T23: =IF($K20>0,ROUND(T21*$E20/100,DpCU),IF(T24>10000,ROUND(HLOOKUP(T24,$O20:$U23,4,FALSE)/100*T21,DpCU),IF(OR(T20<20001,T20>95000,AND(60000<T20,T20<70001)),ROUND(ROUND(T21*JL/$C20,DcCU)*T22,DpCU),IF(OR(AND(20000<T20,T20<22501),AND(30000<T20,T20<50001),77500<T20),ROUND(T22*T21,DpCU),IF(OR(AND(22500<T20,T20<25001),AND(50000<T20,T20<53501),AND(70000<T20,T20<72501)),ROUND($F20/100*T21,DpCU),IF(OR(AND(25000<T20,T20<27501),AND(53500<T20,T20<57001),AND(72500<T20,T20<75001)),ROUND($G20/100*T21,DpCU),ROUND($H20/100*T21,DpCU))))))) -> 144 | U23: =IF($K20>0,ROUND(U21*$E20/100,DpCU),IF(U24>10000,ROUND(HLOOKUP(U24,$O20:$U23,4,FALSE)/100*U21,DpCU),IF(OR(U20<20001,U20>95000,AND(60000<U20,U20<70001)),ROUND(ROUND(U21*JL/$C20,DcCU)*U22,DpCU),IF(OR(AND(20000<U20,U20<22501),AND(30000<U20,U20<50001),77500<U20),ROUND(U22*U21,DpCU),IF(OR(AND(22500<U20,U20<25001),AND(50000<U20,U20<53501),AND(70000<U20,U20<72501)),ROUND($F20/100*U21,DpCU),IF(OR(AND(25000<U20,U20<27501),AND(53500<U20,U20<57001),AND(72500<U20,U20<75001)),ROUND($G20/100*U21,DpCU),ROUND($H20/100*U21,DpCU))))))) -> 29.73
B24: =A20&"r" -> 10004r
A25: 10005 | B25: EQUIPOS DE PROTECCION PERSONAL (EPP'S) | C25: =ROUND(J25*JL*Frto/8,4) -> 1 | D25: glb | E25: =SUM($O28:$T28) -> 4635.75 | F25: =SUMIF($O25:$T25,"<22501",$O28:$T28) -> 0 | G25: =SUMIFS($O28:$T28,$O25:$T25,">30000",$O25:$T25,"<50001") -> 4635.75 | H25: =SUMIFS($O28:$T28,$O25:$T25,">60000",$O25:$T25,"<70001") -> 0 | I25: 6 | J25: 1 | O25: 30012 | P25: 30013 | Q25: 30014 | R25: 30015 | S25: 30016 | T25: 30017
B26: =A25&"C" -> 10005C | O26: 35 | P26: 35 | Q26: 35 | R26: 35 | S26: 35 | T26: 35
O27: =IF(O29>10000,HLOOKUP(O29,N25:$O28,4,FALSE),IF(OR(AND(22500<O25,O25<25001),AND(50000<O25,O25<53501),AND(70000<O25,O25<72501)),$F25,IF(OR(AND(25001<O25,O25<27501),AND(53500<O25,O25<57001),AND(72500<O25,O25<75001)),$G25,IF(OR(AND(27500<O25,O25<30001),AND(57000<O25,O25<60001),AND(75000<O25,O25<77500)),$H25,VLOOKUP(O25,BDins,6,FALSE))))) -> 18.5 | P27: =IF(P29>10000,HLOOKUP(P29,O25:$O28,4,FALSE),IF(OR(AND(22500<P25,P25<25001),AND(50000<P25,P25<53501),AND(70000<P25,P25<72501)),$F25,IF(OR(AND(25001<P25,P25<27501),AND(53500<P25,P25<57001),AND(72500<P25,P25<75001)),$G25,IF(OR(AND(27500<P25,P25<30001),AND(57000<P25,P25<60001),AND(75000<P25,P25<77500)),$H25,VLOOKUP(P25,BDins,6,FALSE))))) -> 48.5 | Q27: =IF(Q29>10000,HLOOKUP(Q29,$O25:P28,4,FALSE),IF(OR(AND(22500<Q25,Q25<25001),AND(50000<Q25,Q25<53501),AND(70000<Q25,Q25<72501)),$F25,IF(OR(AND(25001<Q25,Q25<27501),AND(53500<Q25,Q25<57001),AND(72500<Q25,Q25<75001)),$G25,IF(OR(AND(27500<Q25,Q25<30001),AND(57000<Q25,Q25<60001),AND(75000<Q25,Q25<77500)),$H25,VLOOKUP(Q25,BDins,6,FALSE))))) -> 12 | R27: =IF(R29>10000,HLOOKUP(R29,$O25:Q28,4,FALSE),IF(OR(AND(22500<R25,R25<25001),AND(50000<R25,R25<53501),AND(70000<R25,R25<72501)),$F25,IF(OR(AND(25001<R25,R25<27501),AND(53500<R25,R25<57001),AND(72500<R25,R25<75001)),$G25,IF(OR(AND(27500<R25,R25<30001),AND(57000<R25,R25<60001),AND(75000<R25,R25<77500)),$H25,VLOOKUP(R25,BDins,6,FALSE))))) -> 12.5 | S27: =IF(S29>10000,HLOOKUP(S29,$O25:R28,4,FALSE),IF(OR(AND(22500<S25,S25<25001),AND(50000<S25,S25<53501),AND(70000<S25,S25<72501)),$F25,IF(OR(AND(25001<S25,S25<27501),AND(53500<S25,S25<57001),AND(72500<S25,S25<75001)),$G25,IF(OR(AND(27500<S25,S25<30001),AND(57000<S25,S25<60001),AND(75000<S25,S25<77500)),$H25,VLOOKUP(S25,BDins,6,FALSE))))) -> 11.45 | T27: =IF(T29>10000,HLOOKUP(T29,$O25:S28,4,FALSE),IF(OR(AND(22500<T25,T25<25001),AND(50000<T25,T25<53501),AND(70000<T25,T25<72501)),$F25,IF(OR(AND(25001<T25,T25<27501),AND(53500<T25,T25<57001),AND(72500<T25,T25<75001)),$G25,IF(OR(AND(27500<T25,T25<30001),AND(57000<T25,T25<60001),AND(75000<T25,T25<77500)),$H25,VLOOKUP(T25,BDins,6,FALSE))))) -> 29.5
O28: =IF($K25>0,ROUND(O26*$E25/100,DpCU),IF(O29>10000,ROUND(HLOOKUP(O29,$O25:$T28,4,FALSE)/100*O26,DpCU),IF(OR(O25<20001,O25>95000,AND(60000<O25,O25<70001)),ROUND(ROUND(O26*JL/$C25,DcCU)*O27,DpCU),IF(OR(AND(20000<O25,O25<22501),AND(30000<O25,O25<50001),77500<O25),ROUND(O27*O26,DpCU),IF(OR(AND(22500<O25,O25<25001),AND(50000<O25,O25<53501),AND(70000<O25,O25<72501)),ROUND($F25/100*O26,DpCU),IF(OR(AND(25000<O25,O25<27501),AND(53500<O25,O25<57001),AND(72500<O25,O25<75001)),ROUND($G25/100*O26,DpCU),ROUND($H25/100*O26,DpCU))))))) -> 647.5 | P28: =IF($K25>0,ROUND(P26*$E25/100,DpCU),IF(P29>10000,ROUND(HLOOKUP(P29,$O25:$T28,4,FALSE)/100*P26,DpCU),IF(OR(P25<20001,P25>95000,AND(60000<P25,P25<70001)),ROUND(ROUND(P26*JL/$C25,DcCU)*P27,DpCU),IF(OR(AND(20000<P25,P25<22501),AND(30000<P25,P25<50001),77500<P25),ROUND(P27*P26,DpCU),IF(OR(AND(22500<P25,P25<25001),AND(50000<P25,P25<53501),AND(70000<P25,P25<72501)),ROUND($F25/100*P26,DpCU),IF(OR(AND(25000<P25,P25<27501),AND(53500<P25,P25<57001),AND(72500<P25,P25<75001)),ROUND($G25/100*P26,DpCU),ROUND($H25/100*P26,DpCU))))))) -> 1697.5 | Q28: =IF($K25>0,ROUND(Q26*$E25/100,DpCU),IF(Q29>10000,ROUND(HLOOKUP(Q29,$O25:$T28,4,FALSE)/100*Q26,DpCU),IF(OR(Q25<20001,Q25>95000,AND(60000<Q25,Q25<70001)),ROUND(ROUND(Q26*JL/$C25,DcCU)*Q27,DpCU),IF(OR(AND(20000<Q25,Q25<22501),AND(30000<Q25,Q25<50001),77500<Q25),ROUND(Q27*Q26,DpCU),IF(OR(AND(22500<Q25,Q25<25001),AND(50000<Q25,Q25<53501),AND(70000<Q25,Q25<72501)),ROUND($F25/100*Q26,DpCU),IF(OR(AND(25000<Q25,Q25<27501),AND(53500<Q25,Q25<57001),AND(72500<Q25,Q25<75001)),ROUND($G25/100*Q26,DpCU),ROUND($H25/100*Q26,DpCU))))))) -> 420 | R28: =IF($K25>0,ROUND(R26*$E25/100,DpCU),IF(R29>10000,ROUND(HLOOKUP(R29,$O25:$T28,4,FALSE)/100*R26,DpCU),IF(OR(R25<20001,R25>95000,AND(60000<R25,R25<70001)),ROUND(ROUND(R26*JL/$C25,DcCU)*R27,DpCU),IF(OR(AND(20000<R25,R25<22501),AND(30000<R25,R25<50001),77500<R25),ROUND(R27*R26,DpCU),IF(OR(AND(22500<R25,R25<25001),AND(50000<R25,R25<53501),AND(70000<R25,R25<72501)),ROUND($F25/100*R26,DpCU),IF(OR(AND(25000<R25,R25<27501),AND(53500<R25,R25<57001),AND(72500<R25,R25<75001)),ROUND($G25/100*R26,DpCU),ROUND($H25/100*R26,DpCU))))))) -> 437.5 | S28: =IF($K25>0,ROUND(S26*$E25/100,DpCU),IF(S29>10000,ROUND(HLOOKUP(S29,$O25:$T28,4,FALSE)/100*S26,DpCU),IF(OR(S25<20001,S25>95000,AND(60000<S25,S25<70001)),ROUND(ROUND(S26*JL/$C25,DcCU)*S27,DpCU),IF(OR(AND(20000<S25,S25<22501),AND(30000<S25,S25<50001),77500<S25),ROUND(S27*S26,DpCU),IF(OR(AND(22500<S25,S25<25001),AND(50000<S25,S25<53501),AND(70000<S25,S25<72501)),ROUND($F25/100*S26,DpCU),IF(OR(AND(25000<S25,S25<27501),AND(53500<S25,S25<57001),AND(72500<S25,S25<75001)),ROUND($G25/100*S26,DpCU),ROUND($H25/100*S26,DpCU))))))) -> 400.75 | T28: =IF($K25>0,ROUND(T26*$E25/100,DpCU),IF(T29>10000,ROUND(HLOOKUP(T29,$O25:$T28,4,FALSE)/100*T26,DpCU),IF(OR(T25<20001,T25>95000,AND(60000<T25,T25<70001)),ROUND(ROUND(T26*JL/$C25,DcCU)*T27,DpCU),IF(OR(AND(20000<T25,T25<22501),AND(30000<T25,T25<50001),77500<T25),ROUND(T27*T26,DpCU),IF(OR(AND(22500<T25,T25<25001),AND(50000<T25,T25<53501),AND(70000<T25,T25<72501)),ROUND($F25/100*T26,DpCU),IF(OR(AND(25000<T25,T25<27501),AND(53500<T25,T25<57001),AND(72500<T25,T25<75001)),ROUND($G25/100*T26,DpCU),ROUND($H25/100*T26,DpCU))))))) -> 1032.5
B29: =A25&"r" -> 10005r
A30: 10006 | B30: SEÑALIZACION | C30: =ROUND(J30*JL*Frto/8,4) -> 5 | D30: und | E30: =SUM($O33:$V33) -> 108.11 | F30: =SUMIF($O30:$V30,"<22501",$O33:$V33) -> 70.95 | G30: =SUMIFS($O33:$V33,$O30:$V30,">30000",$O30:$V30,"<50001") -> 35.03 | H30: =SUMIFS($O33:$V33,$O30:$V30,">60000",$O30:$V30,"<70001") -> 0 | I30: 8 | J30: 5 | O30: 10001 | P30: 10003 | Q30: 10004 | R30: 30005 | S30: 30018 | T30: 30019 | U30: 30020 | V30: 70001
B31: =A30&"C" -> 10006C | O31: 1 | P31: 1 | Q31: 1 | R31: 0.11 | S31: 1 | T31: 2 | U31: 1 | V31: 3
O32: =IF(O34>10000,HLOOKUP(O34,N30:$O33,4,FALSE),IF(OR(AND(22500<O30,O30<25001),AND(50000<O30,O30<53501),AND(70000<O30,O30<72501)),$F30,IF(OR(AND(25001<O30,O30<27501),AND(53500<O30,O30<57001),AND(72500<O30,O30<75001)),$G30,IF(OR(AND(27500<O30,O30<30001),AND(57000<O30,O30<60001),AND(75000<O30,O30<77500)),$H30,VLOOKUP(O30,BDins,6,FALSE))))) -> 12.64 | P32: =IF(P34>10000,HLOOKUP(P34,O30:$O33,4,FALSE),IF(OR(AND(22500<P30,P30<25001),AND(50000<P30,P30<53501),AND(70000<P30,P30<72501)),$F30,IF(OR(AND(25001<P30,P30<27501),AND(53500<P30,P30<57001),AND(72500<P30,P30<75001)),$G30,IF(OR(AND(27500<P30,P30<30001),AND(57000<P30,P30<60001),AND(75000<P30,P30<77500)),$H30,VLOOKUP(P30,BDins,6,FALSE))))) -> 14.12 | Q32: =IF(Q34>10000,HLOOKUP(Q34,$O30:P33,4,FALSE),IF(OR(AND(22500<Q30,Q30<25001),AND(50000<Q30,Q30<53501),AND(70000<Q30,Q30<72501)),$F30,IF(OR(AND(25001<Q30,Q30<27501),AND(53500<Q30,Q30<57001),AND(72500<Q30,Q30<75001)),$G30,IF(OR(AND(27500<Q30,Q30<30001),AND(57000<Q30,Q30<60001),AND(75000<Q30,Q30<77500)),$H30,VLOOKUP(Q30,BDins,6,FALSE))))) -> 17.59 | R32: =IF(R34>10000,HLOOKUP(R34,$O30:Q33,4,FALSE),IF(OR(AND(22500<R30,R30<25001),AND(50000<R30,R30<53501),AND(70000<R30,R30<72501)),$F30,IF(OR(AND(25001<R30,R30<27501),AND(53500<R30,R30<57001),AND(72500<R30,R30<75001)),$G30,IF(OR(AND(27500<R30,R30<30001),AND(57000<R30,R30<60001),AND(75000<R30,R30<77500)),$H30,VLOOKUP(R30,BDins,6,FALSE))))) -> 28 | S32: =IF(S34>10000,HLOOKUP(S34,$O30:R33,4,FALSE),IF(OR(AND(22500<S30,S30<25001),AND(50000<S30,S30<53501),AND(70000<S30,S30<72501)),$F30,IF(OR(AND(25001<S30,S30<27501),AND(53500<S30,S30<57001),AND(72500<S30,S30<75001)),$G30,IF(OR(AND(27500<S30,S30<30001),AND(57000<S30,S30<60001),AND(75000<S30,S30<77500)),$H30,VLOOKUP(S30,BDins,6,FALSE))))) -> 11.45 | T32: =IF(T34>10000,HLOOKUP(T34,$O30:S33,4,FALSE),IF(OR(AND(22500<T30,T30<25001),AND(50000<T30,T30<53501),AND(70000<T30,T30<72501)),$F30,IF(OR(AND(25001<T30,T30<27501),AND(53500<T30,T30<57001),AND(72500<T30,T30<75001)),$G30,IF(OR(AND(27500<T30,T30<30001),AND(57000<T30,T30<60001),AND(75000<T30,T30<77500)),$H30,VLOOKUP(T30,BDins,6,FALSE))))) -> 2.5 | U32: =IF(U34>10000,HLOOKUP(U34,$O30:T33,4,FALSE),IF(OR(AND(22500<U30,U30<25001),AND(50000<U30,U30<53501),AND(70000<U30,U30<72501)),$F30,IF(OR(AND(25001<U30,U30<27501),AND(53500<U30,U30<57001),AND(72500<U30,U30<75001)),$G30,IF(OR(AND(27500<U30,U30<30001),AND(57000<U30,U30<60001),AND(75000<U30,U30<77500)),$H30,VLOOKUP(U30,BDins,6,FALSE))))) -> 15.5 | V32: =IF(V34>10000,HLOOKUP(V34,$O30:U33,4,FALSE),IF(OR(AND(22500<V30,V30<25001),AND(50000<V30,V30<53501),AND(70000<V30,V30<72501)),$F30,IF(OR(AND(25001<V30,V30<27501),AND(53500<V30,V30<57001),AND(72500<V30,V30<75001)),$G30,IF(OR(AND(27500<V30,V30<30001),AND(57000<V30,V30<60001),AND(75000<V30,V30<77500)),$H30,VLOOKUP(V30,BDins,6,FALSE))))) -> 70.95
O33: =IF($K30>0,ROUND(O31*$E30/100,DpCU),IF(O34>10000,ROUND(HLOOKUP(O34,$O30:$V33,4,FALSE)/100*O31,DpCU),IF(OR(O30<20001,O30>95000,AND(60000<O30,O30<70001)),ROUND(ROUND(O31*JL/$C30,DcCU)*O32,DpCU),IF(OR(AND(20000<O30,O30<22501),AND(30000<O30,O30<50001),77500<O30),ROUND(O32*O31,DpCU),IF(OR(AND(22500<O30,O30<25001),AND(50000<O30,O30<53501),AND(70000<O30,O30<72501)),ROUND($F30/100*O31,DpCU),IF(OR(AND(25000<O30,O30<27501),AND(53500<O30,O30<57001),AND(72500<O30,O30<75001)),ROUND($G30/100*O31,DpCU),ROUND($H30/100*O31,DpCU))))))) -> 20.22 | P33: =IF($K30>0,ROUND(P31*$E30/100,DpCU),IF(P34>10000,ROUND(HLOOKUP(P34,$O30:$V33,4,FALSE)/100*P31,DpCU),IF(OR(P30<20001,P30>95000,AND(60000<P30,P30<70001)),ROUND(ROUND(P31*JL/$C30,DcCU)*P32,DpCU),IF(OR(AND(20000<P30,P30<22501),AND(30000<P30,P30<50001),77500<P30),ROUND(P32*P31,DpCU),IF(OR(AND(22500<P30,P30<25001),AND(50000<P30,P30<53501),AND(70000<P30,P30<72501)),ROUND($F30/100*P31,DpCU),IF(OR(AND(25000<P30,P30<27501),AND(53500<P30,P30<57001),AND(72500<P30,P30<75001)),ROUND($G30/100*P31,DpCU),ROUND($H30/100*P31,DpCU))))))) -> 22.59 | Q33: =IF($K30>0,ROUND(Q31*$E30/100,DpCU),IF(Q34>10000,ROUND(HLOOKUP(Q34,$O30:$V33,4,FALSE)/100*Q31,DpCU),IF(OR(Q30<20001,Q30>95000,AND(60000<Q30,Q30<70001)),ROUND(ROUND(Q31*JL/$C30,DcCU)*Q32,DpCU),IF(OR(AND(20000<Q30,Q30<22501),AND(30000<Q30,Q30<50001),77500<Q30),ROUND(Q32*Q31,DpCU),IF(OR(AND(22500<Q30,Q30<25001),AND(50000<Q30,Q30<53501),AND(70000<Q30,Q30<72501)),ROUND($F30/100*Q31,DpCU),IF(OR(AND(25000<Q30,Q30<27501),AND(53500<Q30,Q30<57001),AND(72500<Q30,Q30<75001)),ROUND($G30/100*Q31,DpCU),ROUND($H30/100*Q31,DpCU))))))) -> 28.14 | R33: =IF($K30>0,ROUND(R31*$E30/100,DpCU),IF(R34>10000,ROUND(HLOOKUP(R34,$O30:$V33,4,FALSE)/100*R31,DpCU),IF(OR(R30<20001,R30>95000,AND(60000<R30,R30<70001)),ROUND(ROUND(R31*JL/$C30,DcCU)*R32,DpCU),IF(OR(AND(20000<R30,R30<22501),AND(30000<R30,R30<50001),77500<R30),ROUND(R32*R31,DpCU),IF(OR(AND(22500<R30,R30<25001),AND(50000<R30,R30<53501),AND(70000<R30,R30<72501)),ROUND($F30/100*R31,DpCU),IF(OR(AND(25000<R30,R30<27501),AND(53500<R30,R30<57001),AND(72500<R30,R30<75001)),ROUND($G30/100*R31,DpCU),ROUND($H30/100*R31,DpCU))))))) -> 3.08 | S33: =IF($K30>0,ROUND(S31*$E30/100,DpCU),IF(S34>10000,ROUND(HLOOKUP(S34,$O30:$V33,4,FALSE)/100*S31,DpCU),IF(OR(S30<20001,S30>95000,AND(60000<S30,S30<70001)),ROUND(ROUND(S31*JL/$C30,DcCU)*S32,DpCU),IF(OR(AND(20000<S30,S30<22501),AND(30000<S30,S30<50001),77500<S30),ROUND(S32*S31,DpCU),IF(OR(AND(22500<S30,S30<25001),AND(50000<S30,S30<53501),AND(70000<S30,S30<72501)),ROUND($F30/100*S31,DpCU),IF(OR(AND(25000<S30,S30<27501),AND(53500<S30,S30<57001),AND(72500<S30,S30<75001)),ROUND($G30/100*S31,DpCU),ROUND($H30/100*S31,DpCU))))))) -> 11.45 | T33: =IF($K30>0,ROUND(T31*$E30/100,DpCU),IF(T34>10000,ROUND(HLOOKUP(T34,$O30:$V33,4,FALSE)/100*T31,DpCU),IF(OR(T30<20001,T30>95000,AND(60000<T30,T30<70001)),ROUND(ROUND(T31*JL/$C30,DcCU)*T32,DpCU),IF(OR(AND(20000<T30,T30<22501),AND(30000<T30,T30<50001),77500<T30),ROUND(T32*T31,DpCU),IF(OR(AND(22500<T30,T30<25001),AND(50000<T30,T30<53501),AND(70000<T30,T30<72501)),ROUND($F30/100*T31,DpCU),IF(OR(AND(25000<T30,T30<27501),AND(53500<T30,T30<57001),AND(72500<T30,T30<75001)),ROUND($G30/100*T31,DpCU),ROUND($H30/100*T31,DpCU))))))) -> 5 | U33: =IF($K30>0,ROUND(U31*$E30/100,DpCU),IF(U34>10000,ROUND(HLOOKUP(U34,$O30:$V33,4,FALSE)/100*U31,DpCU),IF(OR(U30<20001,U30>95000,AND(60000<U30,U30<70001)),ROUND(ROUND(U31*JL/$C30,DcCU)*U32,DpCU),IF(OR(AND(20000<U30,U30<22501),AND(30000<U30,U30<50001),77500<U30),ROUND(U32*U31,DpCU),IF(OR(AND(22500<U30,U30<25001),AND(50000<U30,U30<53501),AND(70000<U30,U30<72501)),ROUND($F30/100*U31,DpCU),IF(OR(AND(25000<U30,U30<27501),AND(53500<U30,U30<57001),AND(72500<U30,U30<75001)),ROUND($G30/100*U31,DpCU),ROUND($H30/100*U31,DpCU))))))) -> 15.5 | V33: =IF($K30>0,ROUND(V31*$E30/100,DpCU),IF(V34>10000,ROUND(HLOOKUP(V34,$O30:$V33,4,FALSE)/100*V31,DpCU),IF(OR(V30<20001,V30>95000,AND(60000<V30,V30<70001)),ROUND(ROUND(V31*JL/$C30,DcCU)*V32,DpCU),IF(OR(AND(20000<V30,V30<22501),AND(30000<V30,V30<50001),77500<V30),ROUND(V32*V31,DpCU),IF(OR(AND(22500<V30,V30<25001),AND(50000<V30,V30<53501),AND(70000<V30,V30<72501)),ROUND($F30/100*V31,DpCU),IF(OR(AND(25000<V30,V30<27501),AND(53500<V30,V30<57001),AND(72500<V30,V30<75001)),ROUND($G30/100*V31,DpCU),ROUND($H30/100*V31,DpCU))))))) -> 2.13
B34: =A30&"r" -> 10006r
A35: 10007 | B35: CHARLAS DE SEGURIDAD | C35: =ROUND(J35*JL*Frto/8,4) -> 1 | D35: sem | E35: =SUM($O38:$O38) -> 350 | F35: =SUMIF($O35:$O35,"<22501",$O38:$O38) -> 0 | G35: =SUMIFS($O38:$O38,$O35:$O35,">30000",$O35:$O35,"<50001") -> 350 | H35: =SUMIFS($O38:$O38,$O35:$O35,">60000",$O35:$O35,"<70001") -> 0 | I35: 1 | J35: 1 | O35: 30021
B36: =A35&"C" -> 10007C | O36: 1
