Workbook
Name APUb: #REF!
Name BDcodCU: ApuB!$A$5:$A$50005
Name BDcodINS: InsB!$A$16:$A$3015
Name BDcuA: ApuB!$A$5:$DJ$50005
Name BDcuB: ApuB!$B$5:$DJ$50005
Name BDins: InsB!$A$16:$M$3015
Name cellbimuser0EB30BF1602D56040B4019F3: 1714952548072
Name cellbimuser33120D4C9001780EE8508FEB: 1715181719314
Name CODc: #REF!&"C"
Name CODp: #REF!
Name CODr: #REF!&"P"
Name DcCU: Datos!$J$13
Name Dins: Datos!$J$15
Name DLS: Datos!$AJ$12:$AJ$18
Name DpCU: Datos!$J$12
Name DpP: Datos!$J$9
Name EQ: #REF!
Name Frto: Datos!$J$19
Name JL: Datos!$H$19
Name MA: #REF!
Name MO: #REF!
Name NO: Datos!$AJ$12:$AJ$18

Sheet Datos
AQ1: NO | AT1: Feriados
B2: PROYECTO | AQ2: SI | AT2: Comienzo | AU2: Fin | AV2: Descripcion
B3: UBICACIÓN | AQ3: SI
B4: CLIENTE | AQ4: SI
B5: FECHA | AI5: Soles | AJ5: S/ | AQ5: SI
F6: MONEDA | AI6: Dólares | AJ6: $
B7: LOGO | C7: RW7o | D7: =IF(J7=AI5,AJ5,AJ6) -> S/ | G7: Procesar el presupuesto utilizando la moneda en | J7: Soles
F8: NÚMERO DE DECIMALES PARA REDONDEO
B9: MODALIDAD DE E. | C9: CONTRATA | G9: Parciales de las partidas en la hoja de presupuesto | J9: 2 | AI9: CONTRATA | AQ9: NO
B10: IMPUESTO (IGV) | C10: 0.18 | G10: Total de los metrados en cada partida | J10: 2 | AI10: ADMINISTRACION DIRECTA | AO10: CALENDARIO | AR10: PIE DEL PRESUPUESTO
D11: =Pto!G474 -> 2400809 | AH11: 0 | AI11: 0 | AK11: 0 | AO11: Lunes | AP11: Laborable | AR11: VALOR FIJO
B12: COLOR DE TEXTOS: | G12: Parcial de los insumos en los APUs | J12: 2 | AI12: 1 | AJ12: 6 | AK12: 1 | AO12: Martes | AP12: Laborable | AR12: % COSTO DIRECTO
B13: Subpresupuesto | G13: Cantidad de MO y EQ en los APUs | J13: 4 | AI13: 2 | AJ13: 5 | AK13: 2 | AO13: Miercoles | AP13: Laborable | AR13: SUBTOTAL 1
B14: Título | D14: =VLOOKUP(C14,AL$10:AM$23,2,FALSE) -> #N/A | AI14: 3 | AK14: 3 | AO14: Jueves | AP14: Laborable | AR14: % SUBTOTAL 1
B15: Sub título de orden 1 | D15: =VLOOKUP(C15,AL$10:AM$23,2,FALSE) -> #N/A | G15: Precio de los insumos | J15: 2 | AI15: 4 | AK15: 4 | AO15: Viernes | AP15: Laborable | AR15: SUBTOTAL 2
B16: Sub título de orden 2 | D16: =VLOOKUP(C16,AL$10:AM$23,2,FALSE) -> #N/A | AI16: 5 | AK16: 5 | AO16: Sábado | AP16: Laborable | AR16: % SUBTOTAL 2
B17: Sub título de orden 3 | D17: =VLOOKUP(C17,AL$10:AM$23,2,FALSE) -> #N/A | F17: OTRAS OPCIONES | AI17: SI | AJ17: Parcial | AK17: 6 | AO17: Domingo | AP17: No laborable | AR17: SUBTOTAL 3
B18: Sub título de orden 4 | D18: =VLOOKUP(C18,AL$10:AM$23,2,FALSE) -> #N/A | I18: Factor costo mano de obra | J18: 1 | AI18: NO | AJ18: Cantidad | AK18: 7 | AR18: % SUBTOTAL 3
B19: Sub título de orden 5 | D19: =VLOOKUP(C19,AL$10:AM$23,2,FALSE) -> #N/A | G19: Jornada laboral | H19: 8 | I19: Factor para rendimiento | J19: 1 | AK19: 8 | AO19: TEXTO EN PANEL DE APUS | AR19: SUBTOTAL 4
B20: Sub título de orden 6 | D20: =VLOOKUP(C20,AL$10:AM$23,2,FALSE) -> #N/A | AI20: MO1 y EQ1 | AK20: 9 | AO20: Tamaño ET | AP20: 10 | AR20: % SUBTOTAL 4
B21: Sub título de orden 7 | D21: =VLOOKUP(C21,AL$10:AM$23,2,FALSE) -> #N/A | G21: Igualar el monto total de relación de insumos al CD | J21: SI | AI21: TODOS | AJ21: 1 | AO21: Fuente ET | AP21: Arial | AR21: % FILA ANTERIOR
B22: Sub título de orden 8 | D22: =VLOOKUP(C22,AL$10:AM$23,2,FALSE) -> #N/A | AO22: Tamaño DG | AP22: 9
B23: Sub título de orden 9 | D23: =VLOOKUP(C23,AL$10:AM$23,2,FALSE) -> #N/A | G23: Generar el gráfico de utilización de recursos para | J23: MO1 y EQ1 | AO23: Fuente DG | AP23: Arial
B25: Pie de presupuesto | G25: Al generar E.T. en Word usar IDEM en partidas repetidas | J25: SI
A26: CONTROL CONCURRENTE
A27: GESTION DEL PROYECTO | G27: Al generar E. T. en Word procesar UNIDAD | J27: SI
A28: GASTOS GENERALES
A29: UTILIDAD | G29: Al generar E.T. en Word procesar FORMA DE PAGO | J29: SI
A30: SUBTOTAL
A31: IMPUESTO (IGV) | G31: Calend. Adq. insumos de MO1 en DH y EQ1 en DM | J31: NO
A32: VALOR REFERENCIAL
A33: SUPERVISIÓN | G33: Al consolidar los insumos de las partidas calcular en base a | J33: Parcial
A34: EXPEDIENTE TÉCNICO
A35: LIQUIDACIÓN
A36: PIE DE PRESUPUESTO
A37: DESCRIPCIÓN | B37: SIM. | C37: VALOR | E37: TIPO
A38: GASTOS GENERALES | B38: GG | C38: 15 | E38: % COSTO DIRECTO
A39: UTILIDAD | B39: UT | C39: 10 | E39: % COSTO DIRECTO
A40: SUBTOTAL | B40: ST | E40: SUBTOTAL 1
A41: IMPUESTO (IGV) | B41: IM | C41: 18 | E41: % SUBTOTAL 1
...

Sheet InsB
A2: DATOS NECESARIOS PARA EL CALCULO DE FLETES
A3: INSUMOS | D3: FLETE CON VEHICULO | G3: FLETE CON ACEMILA Y PEON
D4: ORIGEN - DESTINO | F4: Prec. U. | G4: ORIGEN - DESTINO | K4: Prec. U. | L4: p.u.Cemento
A5: MATERIALES | D5: HUARAZ- HUARI | F5: 0.15 | G5: HUARI - OBRA(YUPAN) | K5: 0.06 | L5: 2.5
A6: AGREGADOS | F6: 0 | G6: HUARI - OBRA(YUPAN) | K6: 1.2 | L6: L | M6: A | N6: H
A7: TUBERIAS | F7: 0 | K7: 0 | L7: 6 | M7: 2.2 | N7: 1.5
A8: {=MAX(IF(BDcodINS<90001,BDcodINS,80000))} -> 80010 | B8: {=MAX(IF(BDcodINS<57001,BDcodINS,53500))} -> 53500 | C8: {=MAX(IF(BDcodINS<22501,BDcodINS,20000))} -> 20000
A9: {=MAX(IF(BDcodINS<80001,BDcodINS,77500))} -> 77513 | B9: {=MAX(IF(BDcodINS<53501,BDcodINS,50000))} -> 50000 | C9: {=MAX(IF(BDcodINS<77501,BDcodINS,75000))} -> 75000
A10: {=MAX(IF(BDcodINS<70001,BDcodINS,60000))} -> 60016 | B10: {=MAX(IF(BDcodINS<30001,BDcodINS,27500))} -> 27500 | C10: {=MAX(IF(BDcodINS<75001,BDcodINS,72500))} -> 72500
A11: {=MAX(IF(BDcodINS<50001,BDcodINS,30000))} -> 30429 | B11: {=MAX(IF(BDcodINS<27501,BDcodINS,25000))} -> 25000 | C11: {=MAX(IF(BDcodINS<72501,BDcodINS,70000))} -> 70001
A12: {=MAX(IF(BDcodINS<20001,BDcodINS,10000))} -> 10008 | B12: {=MAX(IF(BDcodINS<25001,BDcodINS,22500))} -> 22500 | C12: {=MAX(IF(BDcodINS<60001,BDcodINS,57000))} -> 57000 | N12: MONEDAS
A13: 70001 | B13: =MATCH($A$13,BDcodINS,0)+15 -> 24 | C13: {=MAX(IF(BDcodINS<95001,BDcodINS,90000))} -> 80010 | N13: =Datos!AI5 -> Soles | P13: =Datos!AI6 -> Dólares
A14: =COUNT(BDcodINS)+16 -> 493 | C14: {=MAX(IF(BDcodINS<100000,BDcodINS,95000))} -> 80010 | H14: SOLO TUBERIA | N14: Factor | O14: =1+Datos!$C$10 -> 1.18 | P14: 3.75 | Q14: =O14 -> 1.18
A15: Cod. | B15: IU | C15: Tipo | D15: Insumo | E15: Und | F15: =Datos!J7 -> Soles | G15: Peso unitario (kg) | H15: Long. (m) | I15: Ø ext. (mm) | J15: espesor (mm) | K15: Específica de Gastos | L15: Codigo de APU de SP | M15: Codigo insumo referido | N15: Adm. Directa | O15: Contrata | P15: Adm. Directa | Q15: Contrata
A16: 10001 | B16: 47 | C16: MO1 | D16: CAPATAZ | E16: hh | F16: =IF(AND($F$15=Datos!$AI$5,Datos!$C$9=Datos!$AI$10),IF(A16>30000,N16,ROUND(N16*Datos!$J$18,Dins)),IF(AND($F$15=Datos!$AI$5,Datos!$C$9=Datos!$AI$9),IF(A16>30000,O16,ROUND(O16*Datos!$J$18,Dins)),IF(AND($F$15=Datos!$AI$6,Datos!$C$9=Datos!$AI$10),IF(A16>30000,P16,ROUND(P16*Datos!$J$18,Dins)),IF(AND($F$15=Datos!$AI$6,Datos!$C$9=Datos!$AI$9),IF(A16>30000,Q16,ROUND(Q16*Datos!$J$18,Dins)))))) -> 24.97 | N16: 24.97 | O16: =IF(A16>30000,ROUND(N16/$O$14,Dins),ROUND(N16,Dins)) -> 24.97 | P16: =ROUND(N16/$P$14,Dins) -> 6.66 | Q16: =IF(A16>30000,ROUND(P16/$Q$14,Dins),ROUND(P16,Dins)) -> 6.66
A17: 10002 | B17: 47 | C17: MO1 | D17: OPERARIO | E17: hh | F17: =IF(AND($F$15=Datos!$AI$5,Datos!$C$9=Datos!$AI$10),IF(A17>30000,N17,ROUND(N17*Datos!$J$18,Dins)),IF(AND($F$15=Datos!$AI$5,Datos!$C$9=Datos!$AI$9),IF(A17>30000,O17,ROUND(O17*Datos!$J$18,Dins)),IF(AND($F$15=Datos!$AI$6,Datos!$C$9=Datos!$AI$10),IF(A17>30000,P17,ROUND(P17*Datos!$J$18,Dins)),IF(AND($F$15=Datos!$AI$6,Datos!$C$9=Datos!$AI$9),IF(A17>30000,Q17,ROUND(Q17*Datos!$J$18,Dins)))))) -> 20.81 | N17: 20.81 | O17: =IF(A17>30000,ROUND(N17/$O$14,Dins),ROUND(N17,Dins)) -> 20.81 | P17: =ROUND(N17/$P$14,Dins) -> 5.55 | Q17: =IF(A17>30000,ROUND(P17/$Q$14,Dins),ROUND(P17,Dins)) -> 5.55
A18: 10003 | B18: 47 | C18: MO1 | D18: PEON | E18: hh | F18: =IF(AND($F$15=Datos!$AI$5,Datos!$C$9=Datos!$AI$10),IF(A18>30000,N18,ROUND(N18*Datos!$J$18,Dins)),IF(AND($F$15=Datos!$AI$5,Datos!$C$9=Datos!$AI$9),IF(A18>30000,O18,ROUND(O18*Datos!$J$18,Dins)),IF(AND($F$15=Datos!$AI$6,Datos!$C$9=Datos!$AI$10),IF(A18>30000,P18,ROUND(P18*Datos!$J$18,Dins)),IF(AND($F$15=Datos!$AI$6,Datos!$C$9=Datos!$AI$9),IF(A18>30000,Q18,ROUND(Q18*Datos!$J$18,Dins)))))) -> 15.36 | N18: 15.36 | O18: =IF(A18>30000,ROUND(N18/$O$14,Dins),ROUND(N18,Dins)) -> 15.36 | P18: =ROUND(N18/$P$14,Dins) -> 4.1 | Q18: =IF(A18>30000,ROUND(P18/$Q$14,Dins),ROUND(P18,Dins)) -> 4.1
A19: 30001 | B19: 39 | C19: MA | D19: INSTALACIONES ELECTRICAS (ESTIMADO) | E19: est | F19: =IF(AND($F$15=Datos!$AI$5,Datos!$C$9=Datos!$AI$10),IF(A19>30000,N19,ROUND(N19*Datos!$J$18,Dins)),IF(AND($F$15=Datos!$AI$5,Datos!$C$9=Datos!$AI$9),IF(A19>30000,O19,ROUND(O19*Datos!$J$18,Dins)),IF(AND($F$15=Datos!$AI$6,Datos!$C$9=Datos!$AI$10),IF(A19>30000,P19,ROUND(P19*Datos!$J$18,Dins)),IF(AND($F$15=Datos!$AI$6,Datos!$C$9=Datos!$AI$9),IF(A19>30000,Q19,ROUND(Q19*Datos!$J$18,Dins)))))) -> 250 | G19: 0 | H19: 0 | I19: 0 | J19: 0 | N19: 295 | O19: =IF(A19>30000,ROUND(N19/$O$14,Dins),ROUND(N19,Dins)) -> 250 | P19: =ROUND(N19/$P$14,Dins) -> 78.67 | Q19: =IF(A19>30000,ROUND(P19/$Q$14,Dins),ROUND(P19,Dins)) -> 66.67
A20: 30002 | B20: 21 | C20: MA | D20: CEMENTO PORTLAND TIPO I (42.5KG) | E20: BOL | F20: =IF(AND($F$15=Datos!$AI$5,Datos!$C$9=Datos!$AI$10),IF(A20>30000,N20,ROUND(N20*Datos!$J$18,Dins)),IF(AND($F$15=Datos!$AI$5,Datos!$C$9=Datos!$AI$9),IF(A20>30000,O20,ROUND(O20*Datos!$J$18,Dins)),IF(AND($F$15=Datos!$AI$6,Datos!$C$9=Datos!$AI$10),IF(A20>30000,P20,ROUND(P20*Datos!$J$18,Dins)),IF(AND($F$15=Datos!$AI$6,Datos!$C$9=Datos!$AI$9),IF(A20>30000,Q20,ROUND(Q20*Datos!$J$18,Dins)))))) -> 18.5 | G20: 0 | H20: 0 | I20: 0 | J20: 0 | N20: 21.83 | O20: =IF(A20>30000,ROUND(N20/$O$14,Dins),ROUND(N20,Dins)) -> 18.5 | P20: =ROUND(N20/$P$14,Dins) -> 5.82 | Q20: =IF(A20>30000,ROUND(P20/$Q$14,Dins),ROUND(P20,Dins)) -> 4.93
A21: 30003 | B21: 26 | C21: MA | D21: CERRADURA DOS GOLPES FORTE -PARCHE MODELO 220 | E21: PZA | F21: =IF(AND($F$15=Datos!$AI$5,Datos!$C$9=Datos!$AI$10),IF(A21>30000,N21,ROUND(N21*Datos!$J$18,Dins)),IF(AND($F$15=Datos!$AI$5,Datos!$C$9=Datos!$AI$9),IF(A21>30000,O21,ROUND(O21*Datos!$J$18,Dins)),IF(AND($F$15=Datos!$AI$6,Datos!$C$9=Datos!$AI$10),IF(A21>30000,P21,ROUND(P21*Datos!$J$18,Dins)),IF(AND($F$15=Datos!$AI$6,Datos!$C$9=Datos!$AI$9),IF(A21>30000,Q21,ROUND(Q21*Datos!$J$18,Dins)))))) -> 45.8 | G21: 0 | H21: 0 | I21: 0 | J21: 0 | N21: 54.04 | O21: =IF(A21>30000,ROUND(N21/$O$14,Dins),ROUND(N21,Dins)) -> 45.8 | P21: =ROUND(N21/$P$14,Dins) -> 14.41 | Q21: =IF(A21>30000,ROUND(P21/$Q$14,Dins),ROUND(P21,Dins)) -> 12.21
A22: 30004 | B22: 38 | C22: MA | D22: HORMIGON | E22: M3 | F22: =IF(AND($F$15=Datos!$AI$5,Datos!$C$9=Datos!$AI$10),IF(A22>30000,N22,ROUND(N22*Datos!$J$18,Dins)),IF(AND($F$15=Datos!$AI$5,Datos!$C$9=Datos!$AI$9),IF(A22>30000,O22,ROUND(O22*Datos!$J$18,Dins)),IF(AND($F$15=Datos!$AI$6,Datos!$C$9=Datos!$AI$10),IF(A22>30000,P22,ROUND(P22*Datos!$J$18,Dins)),IF(AND($F$15=Datos!$AI$6,Datos!$C$9=Datos!$AI$9),IF(A22>30000,Q22,ROUND(Q22*Datos!$J$18,Dins)))))) -> 40 | G22: 0 | H22: 0 | I22: 0 | J22: 0 | N22: 47.2 | O22: =IF(A22>30000,ROUND(N22/$O$14,Dins),ROUND(N22,Dins)) -> 40 | P22: =ROUND(N22/$P$14,Dins) -> 12.59 | Q22: =IF(A22>30000,ROUND(P22/$Q$14,Dins),ROUND(P22,Dins)) -> 10.67
A23: 30005 | B23: 39 | C23: MA | D23: CASETA PREFABRICADA DE 3.0 X 3.0 M | E23: UND | F23: =IF(AND($F$15=Datos!$AI$5,Datos!$C$9=Datos!$AI$10),IF(A23>30000,N23,ROUND(N23*Datos!$J$18,Dins)),IF(AND($F$15=Datos!$AI$5,Datos!$C$9=Datos!$AI$9),IF(A23>30000,O23,ROUND(O23*Datos!$J$18,Dins)),IF(AND($F$15=Datos!$AI$6,Datos!$C$9=Datos!$AI$10),IF(A23>30000,P23,ROUND(P23*Datos!$J$18,Dins)),IF(AND($F$15=Datos!$AI$6,Datos!$C$9=Datos!$AI$9),IF(A23>30000,Q23,ROUND(Q23*Datos!$J$18,Dins)))))) -> 1500 | G23: 0 | H23: 0 | I23: 0 | J23: 0 | N23: 1770 | O23: =IF(A23>30000,ROUND(N23/$O$14,Dins),ROUND(N23,Dins)) -> 1500 | P23: =ROUND(N23/$P$14,Dins) -> 472 | Q23: =IF(A23>30000,ROUND(P23/$Q$14,Dins),ROUND(P23,Dins)) -> 400
A24: 70001 | B24: 37 | C24: EQ %MO | D24: HERRAMIENTAS MANUALES | E24: %MO | F24: =IF(AND($F$15=Datos!$AI$5,Datos!$C$9=Datos!$AI$10),IF(A24>30000,N24,ROUND(N24*Datos!$J$18,Dins)),IF(AND($F$15=Datos!$AI$5,Datos!$C$9=Datos!$AI$9),IF(A24>30000,O24,ROUND(O24*Datos!$J$18,Dins)),IF(AND($F$15=Datos!$AI$6,Datos!$C$9=Datos!$AI$10),IF(A24>30000,P24,ROUND(P24*Datos!$J$18,Dins)),IF(AND($F$15=Datos!$AI$6,Datos!$C$9=Datos!$AI$9),IF(A24>30000,Q24,ROUND(Q24*Datos!$J$18,Dins)))))) -> 34366.11 | N24: 40552.01 | O24: =IF(A24>30000,ROUND(N24/$O$14,Dins),ROUND(N24,Dins)) -> 34366.11 | P24: =ROUND(N24/$P$14,Dins) -> 10813.87 | Q24: =IF(A24>30000,ROUND(P24/$Q$14,Dins),ROUND(P24,Dins)) -> 9164.3
A25: 30006 | B25: 39 | C25: MA | D25: CASETA PREFABRICADA DE 3.0 X 4.5 M | E25: UND | F25: =IF(AND($F$15=Datos!$AI$5,Datos!$C$9=Datos!$AI$10),IF(A25>30000,N25,ROUND(N25*Datos!$J$18,Dins)),IF(AND($F$15=Datos!$AI$5,Datos!$C$9=Datos!$AI$9),IF(A25>30000,O25,ROUND(O25*Datos!$J$18,Dins)),IF(AND($F$15=Datos!$AI$6,Datos!$C$9=Datos!$AI$10),IF(A25>30000,P25,ROUND(P25*Datos!$J$18,Dins)),IF(AND($F$15=Datos!$AI$6,Datos!$C$9=Datos!$AI$9),IF(A25>30000,Q25,ROUND(Q25*Datos!$J$18,Dins)))))) -> 2025 | G25: 0 | H25: 0 | I25: 0 | J25: 0 | N25: 2389.5 | O25: =IF(A25>30000,ROUND(N25/$O$14,Dins),ROUND(N25,Dins)) -> 2025 | P25: =ROUND(N25/$P$14,Dins) -> 637.2 | Q25: =IF(A25>30000,ROUND(P25/$Q$14,Dins),ROUND(P25,Dins)) -> 540
A26: 30007 | B26: 2 | C26: MA | D26: CLAVOS DE ALAMBRE PARA MADERA C/C DE 3" | E26: KG | F26: =IF(AND($F$15=Datos!$AI$5,Datos!$C$9=Datos!$AI$10),IF(A26>30000,N26,ROUND(N26*Datos!$J$18,Dins)),IF(AND($F$15=Datos!$AI$5,Datos!$C$9=Datos!$AI$9),IF(A26>30000,O26,ROUND(O26*Datos!$J$18,Dins)),IF(AND($F$15=Datos!$AI$6,Datos!$C$9=Datos!$AI$10),IF(A26>30000,P26,ROUND(P26*Datos!$J$18,Dins)),IF(AND($F$15=Datos!$AI$6,Datos!$C$9=Datos!$AI$9),IF(A26>30000,Q26,ROUND(Q26*Datos!$J$18,Dins)))))) -> 3.65 | G26: 0 | H26: 0 | I26: 0 | J26: 0 | N26: 4.31 | O26: =IF(A26>30000,ROUND(N26/$O$14,Dins),ROUND(N26,Dins)) -> 3.65 | P26: =ROUND(N26/$P$14,Dins) -> 1.15 | Q26: =IF(A26>30000,ROUND(P26/$Q$14,Dins),ROUND(P26,Dins)) -> 0.97
A27: 30008 | B27: 10 | C27: MA | D27: APARATOS SANITARIOS Y ACCESORIOS | E27: GLB | F27: =IF(AND($F$15=Datos!$AI$5,Datos!$C$9=Datos!$AI$10),IF(A27>30000,N27,ROUND(N27*Datos!$J$18,Dins)),IF(AND($F$15=Datos!$AI$5,Datos!$C$9=Datos!$AI$9),IF(A27>30000,O27,ROUND(O27*Datos!$J$18,Dins)),IF(AND($F$15=Datos!$AI$6,Datos!$C$9=Datos!$AI$10),IF(A27>30000,P27,ROUND(P27*Datos!$J$18,Dins)),IF(AND($F$15=Datos!$AI$6,Datos!$C$9=Datos!$AI$9),IF(A27>30000,Q27,ROUND(Q27*Datos!$J$18,Dins)))))) -> 200 | G27: 0 | H27: 0 | I27: 0 | J27: 0 | N27: 236 | O27: =IF(A27>30000,ROUND(N27/$O$14,Dins),ROUND(N27,Dins)) -> 200 | P27: =ROUND(N27/$P$14,Dins) -> 62.93 | Q27: =IF(A27>30000,ROUND(P27/$Q$14,Dins),ROUND(P27,Dins)) -> 53.33
A28: 30009 | B28: 43 | C28: MA | D28: MADERA MOHENA EN BRUTO | E28: p2 | F28: =IF(AND($F$15=Datos!$AI$5,Datos!$C$9=Datos!$AI$10),IF(A28>30000,N28,ROUND(N28*Datos!$J$18,Dins)),IF(AND($F$15=Datos!$AI$5,Datos!$C$9=Datos!$AI$9),IF(A28>30000,O28,ROUND(O28*Datos!$J$18,Dins)),IF(AND($F$15=Datos!$AI$6,Datos!$C$9=Datos!$AI$10),IF(A28>30000,P28,ROUND(P28*Datos!$J$18,Dins)),IF(AND($F$15=Datos!$AI$6,Datos!$C$9=Datos!$AI$9),IF(A28>30000,Q28,ROUND(Q28*Datos!$J$18,Dins)))))) -> 3.7 | G28: 0 | H28: 0 | I28: 0 | J28: 0 | N28: 4.37 | O28: =IF(A28>30000,ROUND(N28/$O$14,Dins),ROUND(N28,Dins)) -> 3.7 | P28: =ROUND(N28/$P$14,Dins) -> 1.17 | Q28: =IF(A28>30000,ROUND(P28/$Q$14,Dins),ROUND(P28,Dins)) -> 0.99
A29: 30010 | B29: 45 | C29: MA | D29: TRIPLAY DE 4'x8'x 4 mm | E29: pln | F29: =IF(AND($F$15=Datos!$AI$5,Datos!$C$9=Datos!$AI$10),IF(A29>30000,N29,ROUND(N29*Datos!$J$18,Dins)),IF(AND($F$15=Datos!$AI$5,Datos!$C$9=Datos!$AI$9),IF(A29>30000,O29,ROUND(O29*Datos!$J$18,Dins)),IF(AND($F$15=Datos!$AI$6,Datos!$C$9=Datos!$AI$10),IF(A29>30000,P29,ROUND(P29*Datos!$J$18,Dins)),IF(AND($F$15=Datos!$AI$6,Datos!$C$9=Datos!$AI$9),IF(A29>30000,Q29,ROUND(Q29*Datos!$J$18,Dins)))))) -> 25 | G29: 0 | H29: 0 | I29: 0 | J29: 0 | N29: 29.5 | O29: =IF(A29>30000,ROUND(N29/$O$14,Dins),ROUND(N29,Dins)) -> 25 | P29: =ROUND(N29/$P$14,Dins) -> 7.87 | Q29: =IF(A29>30000,ROUND(P29/$Q$14,Dins),ROUND(P29,Dins)) -> 6.67
A30: 30011 | B30: 56 | C30: MA | D30: CALAMINA # 31 DE 1.83m x 0.83m x 2.7mm | E30: PZA | F30: =IF(AND($F$15=Datos!$AI$5,Datos!$C$9=Datos!$AI$10),IF(A30>30000,N30,ROUND(N30*Datos!$J$18,Dins)),IF(AND($F$15=Datos!$AI$5,Datos!$C$9=Datos!$AI$9),IF(A30>30000,O30,ROUND(O30*Datos!$J$18,Dins)),IF(AND($F$15=Datos!$AI$6,Datos!$C$9=Datos!$AI$10),IF(A30>30000,P30,ROUND(P30*Datos!$J$18,Dins)),IF(AND($F$15=Datos!$AI$6,Datos!$C$9=Datos!$AI$9),IF(A30>30000,Q30,ROUND(Q30*Datos!$J$18,Dins)))))) -> 15.5 | G30: 0 | H30: 0 | I30: 0 | J30: 0 | N30: 18.29 | O30: =IF(A30>30000,ROUND(N30/$O$14,Dins),ROUND(N30,Dins)) -> 15.5 | P30: =ROUND(N30/$P$14,Dins) -> 4.88 | Q30: =IF(A30>30000,ROUND(P30/$Q$14,Dins),ROUND(P30,Dins)) -> 4.14
A31: 30012 | B31: 72 | C31: MA | D31: TUBERIA Y ACCESORIOS PVC | E31: GLB | F31: =IF(AND($F$15=Datos!$AI$5,Datos!$C$9=Datos!$AI$10),IF(A31>30000,N31,ROUND(N31*Datos!$J$18,Dins)),IF(AND($F$15=Datos!$AI$5,Datos!$C$9=Datos!$AI$9),IF(A31>30000,O31,ROUND(O31*Datos!$J$18,Dins)),IF(AND($F$15=Datos!$AI$6,Datos!$C$9=Datos!$AI$10),IF(A31>30000,P31,ROUND(P31*Datos!$J$18,Dins)),IF(AND($F$15=Datos!$AI$6,Datos!$C$9=Datos!$AI$9),IF(A31>30000,Q31,ROUND(Q31*Datos!$J$18,Dins)))))) -> 500 | G31: 0 | H31: 0 | I31: 0 | J31: 0 | N31: 590 | O31: =IF(A31>30000,ROUND(N31/$O$14,Dins),ROUND(N31,Dins)) -> 500 | P31: =ROUND(N31/$P$14,Dins) -> 157.33 | Q31: =IF(A31>30000,ROUND(P31/$Q$14,Dins),ROUND(P31,Dins)) -> 133.33
A32: 10004 | B32: 47 | C32: MO1 | D32: OPERADOR DE EQUIPO LIVIANO | E32: hh | F32: =IF(AND($F$15=Datos!$AI$5,Datos!$C$9=Datos!$AI$10),IF(A32>30000,N32,ROUND(N32*Datos!$J$18,Dins)),IF(AND($F$15=Datos!$AI$5,Datos!$C$9=Datos!$AI$9),IF(A32>30000,O32,ROUND(O32*Datos!$J$18,Dins)),IF(AND($F$15=Datos!$AI$6,Datos!$C$9=Datos!$AI$10),IF(A32>30000,P32,ROUND(P32*Datos!$J$18,Dins)),IF(AND($F$15=Datos!$AI$6,Datos!$C$9=Datos!$AI$9),IF(A32>30000,Q32,ROUND(Q32*Datos!$J$18,Dins)))))) -> 20.81 | N32: 20.81 | O32: =IF(A32>30000,ROUND(N32/$O$14,Dins),ROUND(N32,Dins)) -> 20.81 | P32: =ROUND(N32/$P$14,Dins) -> 5.55 | Q32: =IF(A32>30000,ROUND(P32/$Q$14,Dins),ROUND(P32,Dins)) -> 5.55
A33: 10005 | B33: 47 | C33: MO1 | D33: OPERARIO ENCOFRADO | E33: hh | F33: =IF(AND($F$15=Datos!$AI$5,Datos!$C$9=Datos!$AI$10),IF(A33>30000,N33,ROUND(N33*Datos!$J$18,Dins)),IF(AND($F$15=Datos!$AI$5,Datos!$C$9=Datos!$AI$9),IF(A33>30000,O33,ROUND(O33*Datos!$J$18,Dins)),IF(AND($F$15=Datos!$AI$6,Datos!$C$9=Datos!$AI$10),IF(A33>30000,P33,ROUND(P33*Datos!$J$18,Dins)),IF(AND($F$15=Datos!$AI$6,Datos!$C$9=Datos!$AI$9),IF(A33>30000,Q33,ROUND(Q33*Datos!$J$18,Dins)))))) -> 20.81 | N33: 20.81 | O33: =IF(A33>30000,ROUND(N33/$O$14,Dins),ROUND(N33,Dins)) -> 20.81 | P33: =ROUND(N33/$P$14,Dins) -> 5.55 | Q33: =IF(A33>30000,ROUND(P33/$Q$14,Dins),ROUND(P33,Dins)) -> 5.55
A34: 30013 | B34: 43 | C34: MA | D34: MADERA TORNILLO DE 1 1/2" X 3" X 9' | E34: PZA | F34: =IF(AND($F$15=Datos!$AI$5,Datos!$C$9=Datos!$AI$10),IF(A34>30000,N34,ROUND(N34*Datos!$J$18,Dins)),IF(AND($F$15=Datos!$AI$5,Datos!$C$9=Datos!$AI$9),IF(A34>30000,O34,ROUND(O34*Datos!$J$18,Dins)),IF(AND($F$15=Datos!$AI$6,Datos!$C$9=Datos!$AI$10),IF(A34>30000,P34,ROUND(P34*Datos!$J$18,Dins)),IF(AND($F$15=Datos!$AI$6,Datos!$C$9=Datos!$AI$9),IF(A34>30000,Q34,ROUND(Q34*Datos!$J$18,Dins)))))) -> 11.7 | G34: 0 | H34: 0 | I34: 0 | J34: 0 | N34: 13.81 | O34: =IF(A34>30000,ROUND(N34/$O$14,Dins),ROUND(N34,Dins)) -> 11.7 | P34: =ROUND(N34/$P$14,Dins) -> 3.68 | Q34: =IF(A34>30000,ROUND(P34/$Q$14,Dins),ROUND(P34,Dins)) -> 3.12
A35: 30014 | B35: 39 | C35: MA | D35: WAYPE | E35: KG | F35: =IF(AND($F$15=Datos!$AI$5,Datos!$C$9=Datos!$AI$10),IF(A35>30000,N35,ROUND(N35*Datos!$J$18,Dins)),IF(AND($F$15=Datos!$AI$5,Datos!$C$9=Datos!$AI$9),IF(A35>30000,O35,ROUND(O35*Datos!$J$18,Dins)),IF(AND($F$15=Datos!$AI$6,Datos!$C$9=Datos!$AI$10),IF(A35>30000,P35,ROUND(P35*Datos!$J$18,Dins)),IF(AND($F$15=Datos!$AI$6,Datos!$C$9=Datos!$AI$9),IF(A35>30000,Q35,ROUND(Q35*Datos!$J$18,Dins)))))) -> 12 | G35: 0 | H35: 0 | I35: 0 | J35: 0 | N35: 14.16 | O35: =IF(A35>30000,ROUND(N35/$O$14,Dins),ROUND(N35,Dins)) -> 12 | P35: =ROUND(N35/$P$14,Dins) -> 3.78 | Q35: =IF(A35>30000,ROUND(P35/$Q$14,Dins),ROUND(P35,Dins)) -> 3.2
A36: 30015 | B36: 30 | C36: MA | D36: MASILLA GRIS VENCEACRIL 1/4 GLN | E36: UND | F36: =IF(AND($F$15=Datos!$AI$5,Datos!$C$9=Datos!$AI$10),IF(A36>30000,N36,ROUND(N36*Datos!$J$18,Dins)),IF(AND($F$15=Datos!$AI$5,Datos!$C$9=Datos!$AI$9),IF(A36>30000,O36,ROUND(O36*Datos!$J$18,Dins)),IF(AND($F$15=Datos!$AI$6,Datos!$C$9=Datos!$AI$10),IF(A36>30000,P36,ROUND(P36*Datos!$J$18,Dins)),IF(AND($F$15=Datos!$AI$6,Datos!$C$9=Datos!$AI$9),IF(A36>30000,Q36,ROUND(Q36*Datos!$J$18,Dins)))))) -> 7 | G36: 0 | H36: 0 | I36: 0 | J36: 0 | N36: 8.26 | O36: =IF(A36>30000,ROUND(N36/$O$14,Dins),ROUND(N36,Dins)) -> 7 | P36: =ROUND(N36/$P$14,Dins) -> 2.2 | Q36: =IF(A36>30000,ROUND(P36/$Q$14,Dins),ROUND(P36,Dins)) -> 1.86
A37: 30016 | B37: 30 | C37: MA | D37: SOLDADURA CELLOCORD P 3/16" | E37: KG | F37: =IF(AND($F$15=Datos!$AI$5,Datos!$C$9=Datos!$AI$10),IF(A37>30000,N37,ROUND(N37*Datos!$J$18,Dins)),IF(AND($F$15=Datos!$AI$5,Datos!$C$9=Datos!$AI$9),IF(A37>30000,O37,ROUND(O37*Datos!$J$18,Dins)),IF(AND($F$15=Datos!$AI$6,Datos!$C$9=Datos!$AI$10),IF(A37>30000,P37,ROUND(P37*Datos!$J$18,Dins)),IF(AND($F$15=Datos!$AI$6,Datos!$C$9=Datos!$AI$9),IF(A37>30000,Q37,ROUND(Q37*Datos!$J$18,Dins)))))) -> 8 | G37: 0 | H37: 0 | I37: 0 | J37: 0 | N37: 9.44 | O37: =IF(A37>30000,ROUND(N37/$O$14,Dins),ROUND(N37,Dins)) -> 8 | P37: =ROUND(N37/$P$14,Dins) -> 2.52 | Q37: =IF(A37>30000,ROUND(P37/$Q$14,Dins),ROUND(P37,Dins)) -> 2.14
A38: 30017 | B38: 26 | C38: MA | D38: ANGULO 1"x1"x3/16" x6m. AREQUIPA | E38: PZA | F38: =IF(AND($F$15=Datos!$AI$5,Datos!$C$9=Datos!$AI$10),IF(A38>30000,N38,ROUND(N38*Datos!$J$18,Dins)),IF(AND($F$15=Datos!$AI$5,Datos!$C$9=Datos!$AI$9),IF(A38>30000,O38,ROUND(O38*Datos!$J$18,Dins)),IF(AND($F$15=Datos!$AI$6,Datos!$C$9=Datos!$AI$10),IF(A38>30000,P38,ROUND(P38*Datos!$J$18,Dins)),IF(AND($F$15=Datos!$AI$6,Datos!$C$9=Datos!$AI$9),IF(A38>30000,Q38,ROUND(Q38*Datos!$J$18,Dins)))))) -> 15 | G38: 0 | H38: 0 | I38: 0 | J38: 0 | N38: 17.7 | O38: =IF(A38>30000,ROUND(N38/$O$14,Dins),ROUND(N38,Dins)) -> 15 | P38: =ROUND(N38/$P$14,Dins) -> 4.72 | Q38: =IF(A38>30000,ROUND(P38/$Q$14,Dins),ROUND(P38,Dins)) -> 4
A39: 30018 | B39: 48 | C39: MA | D39: THINER | E39: gln | F39: =IF(AND($F$15=Datos!$AI$5,Datos!$C$9=Datos!$AI$10),IF(A39>30000,N39,ROUND(N39*Datos!$J$18,Dins)),IF(AND($F$15=Datos!$AI$5,Datos!$C$9=Datos!$AI$9),IF(A39>30000,O39,ROUND(O39*Datos!$J$18,Dins)),IF(AND($F$15=Datos!$AI$6,Datos!$C$9=Datos!$AI$10),IF(A39>30000,P39,ROUND(P39*Datos!$J$18,Dins)),IF(AND($F$15=Datos!$AI$6,Datos!$C$9=Datos!$AI$9),IF(A39>30000,Q39,ROUND(Q39*Datos!$J$18,Dins)))))) -> 13.5 | G39: 0 | H39: 0 | I39: 0 | J39: 0 | N39: 15.93 | O39: =IF(A39>30000,ROUND(N39/$O$14,Dins),ROUND(N39,Dins)) -> 13.5 | P39: =ROUND(N39/$P$14,Dins) -> 4.25 | Q39: =IF(A39>30000,ROUND(P39/$Q$14,Dins),ROUND(P39,Dins)) -> 3.6
A40: 30019 | B40: 54 | C40: MA | D40: PINTURA ESMALTE | E40: gln | F40: =IF(AND($F$15=Datos!$AI$5,Datos!$C$9=Datos!$AI$10),IF(A40>30000,N40,ROUND(N40*Datos!$J$18,Dins)),IF(AND($F$15=Datos!$AI$5,Datos!$C$9=Datos!$AI$9),IF(A40>30000,O40,ROUND(O40*Datos!$J$18,Dins)),IF(AND($F$15=Datos!$AI$6,Datos!$C$9=Datos!$AI$10),IF(A40>30000,P40,ROUND(P40*Datos!$J$18,Dins)),IF(AND($F$15=Datos!$AI$6,Datos!$C$9=Datos!$AI$9),IF(A40>30000,Q40,ROUND(Q40*Datos!$J$18,Dins)))))) -> 40 | G40: 0 | H40: 0 | I40: 0 | J40: 0 | N40: 47.2 | O40: =IF(A40>30000,ROUND(N40/$O$14,Dins),ROUND(N40,Dins)) -> 40 | P40: =ROUND(N40/$P$14,Dins) -> 12.59 | Q40: =IF(A40>30000,ROUND(P40/$Q$14,Dins),ROUND(P40,Dins)) -> 10.67
A41: 30020 | B41: 54 | C41: MA | D41: PINTURA ZINCROMATO | E41: gln | F41: =IF(AND($F$15=Datos!$AI$5,Datos!$C$9=Datos!$AI$10),IF(A41>30000,N41,ROUND(N41*Datos!$J$18,Dins)),IF(AND($F$15=Datos!$AI$5,Datos!$C$9=Datos!$AI$9),IF(A41>30000,O41,ROUND(O41*Datos!$J$18,Dins)),IF(AND($F$15=Datos!$AI$6,Datos!$C$9=Datos!$AI$10),IF(A41>30000,P41,ROUND(P41*Datos!$J$18,Dins)),IF(AND($F$15=Datos!$AI$6,Datos!$C$9=Datos!$AI$9),IF(A41>30000,Q41,ROUND(Q41*Datos!$J$18,Dins)))))) -> 40 | G41: 0 | H41: 0 | I41: 0 | J41: 0 | N41: 47.2 | O41: =IF(A41>30000,ROUND(N41/$O$14,Dins),ROUND(N41,Dins)) -> 40 | P41: =ROUND(N41/$P$14,Dins) -> 12.59 | Q41: =IF(A41>30000,ROUND(P41/$Q$14,Dins),ROUND(P41,Dins)) -> 10.67
...

Sheet ApuB
A1: 0 | B1: =MATCH($A$1,$A$5:$A$50004,0)+4 -> #N/A | C1: =#REF! -> #REF!
A2: =COUNT(BDcodCU)*5+5 -> 1510 | C2: =COUNT(BDcodCU) -> 301
A3: =MAX($A$5:$A$50004)+1 -> 10302 | B3: Cifra de redondeo decimal del parcial | C3: =Datos!J12 -> 2
A4: Cod | B4: Denominación | C4: RTOf | D4: UND | E4: PU | F4: MO | G4: MA | H4: EQ | I4: nINS | J4: RTOi | K4: P.EST. | M4: SP | N4: ET | O4: 1 | P4: 2 | Q4: 3 | R4: 4 | S4: 5 | T4: 6 | U4: 7 | V4: 8 | W4: 9 | X4: 10 | Y4: 11 | Z4: 12 | AA4: 13 | AB4: 14 | AC4: 15 | AD4: 16 | AE4: 17 | AF4: 18 | AG4: 19 | AH4: 20 | AI4: 21 | AJ4: 22 | AK4: 23 | AL4: 24 | AM4: 25 | AN4: 26 | AO4: 27 | AP4: 28 | AQ4: 29 | AR4: 30 | AS4: 31 | AT4: 32 | AU4: 33 | AV4: 34 | AW4: 35 | AX4: 36 | AY4: 37 | AZ4: 38 | BA4: 39 | BB4: 40 | BC4: 41 | BD4: 42 | BE4: 43 | BF4: 44 | BG4: 45 | BH4: 46 | BI4: 47 | BJ4: 48 | BK4: 49 | BL4: 50 | BM4: 51 | BN4: 52 | BO4: 53 | BP4: 54 | BQ4: 55 | BR4: 56 | BS4: 57 | BT4: 58 | BU4: 59 | BV4: 60 | BW4: 61 | BX4: 62 | BY4: 63 | BZ4: 64 | CA4: 65 | CB4: 66 | CC4: 67 | CD4: 68 | CE4: 69 | CF4: 70 | CG4: 71 | CH4: 72 | CI4: 73 | CJ4: 74 | CK4: 75 | CL4: 76 | CM4: 77 | CN4: 78 | CO4: 79 | CP4: 80 | CQ4: 81 | CR4: 82 | CS4: 83 | CT4: 84 | CU4: 85 | CV4: 86 | CW4: 87 | CX4: 88 | CY4: 89 | CZ4: 90 | DA4: 91 | DB4: 92 | DC4: 93 | DD4: 94 | DE4: 95 | DF4: 96 | DG4: 97 | DH4: 98 | DI4: 99 | DJ4: 100
A5: 10001 | B5: OFICINA | C5: =ROUND(J5*JL*Frto/8,4) -> 0.6 | D5: GLB | E5: =SUM($O8:$W8) -> 1232.64 | F5: =SUMIF($O5:$W5,"<22501",$O8:$W8) -> 515.56 | G5: =SUMIFS($O8:$W8,$O5:$W5,">30000",$O5:$W5,"<50001") -> 691.3 | H5: =SUMIFS($O8:$W8,$O5:$W5,">60000",$O5:$W5,"<70001") -> 0 | I5: 9 | J5: 0.6 | O5: 10001 | P5: 10002 | Q5: 10003 | R5: 30001 | S5: 30002 | T5: 30003 | U5: 30004 | V5: 30005 | W5: 70001
B6: =A5&"C" -> 10001C | O6: 0.1 | P6: 1 | Q6: 1 | R6: 1 | S6: 3 | T6: 1 | U6: 1 | V6: 0.2 | W6: 5
O7: =IF(O9>10000,HLOOKUP(O9,N5:$O8,4,FALSE),IF(OR(AND(22500<O5,O5<25001),AND(50000<O5,O5<53501),AND(70000<O5,O5<72501)),$F5,IF(OR(AND(25001<O5,O5<27501),AND(53500<O5,O5<57001),AND(72500<O5,O5<75001)),$G5,IF(OR(AND(27500<O5,O5<30001),AND(57000<O5,O5<60001),AND(75000<O5,O5<77500)),$H5,VLOOKUP(O5,BDins,6,FALSE))))) -> 24.97 | P7: =IF(P9>10000,HLOOKUP(P9,O5:$O8,4,FALSE),IF(OR(AND(22500<P5,P5<25001),AND(50000<P5,P5<53501),AND(70000<P5,P5<72501)),$F5,IF(OR(AND(25001<P5,P5<27501),AND(53500<P5,P5<57001),AND(72500<P5,P5<75001)),$G5,IF(OR(AND(27500<P5,P5<30001),AND(57000<P5,P5<60001),AND(75000<P5,P5<77500)),$H5,VLOOKUP(P5,BDins,6,FALSE))))) -> 20.81 | Q7: =IF(Q9>10000,HLOOKUP(Q9,$O5:P8,4,FALSE),IF(OR(AND(22500<Q5,Q5<25001),AND(50000<Q5,Q5<53501),AND(70000<Q5,Q5<72501)),$F5,IF(OR(AND(25001<Q5,Q5<27501),AND(53500<Q5,Q5<57001),AND(72500<Q5,Q5<75001)),$G5,IF(OR(AND(27500<Q5,Q5<30001),AND(57000<Q5,Q5<60001),AND(75000<Q5,Q5<77500)),$H5,VLOOKUP(Q5,BDins,6,FALSE))))) -> 15.36 | R7: =IF(R9>10000,HLOOKUP(R9,$O5:Q8,4,FALSE),IF(OR(AND(22500<R5,R5<25001),AND(50000<R5,R5<53501),AND(70000<R5,R5<72501)),$F5,IF(OR(AND(25001<R5,R5<27501),AND(53500<R5,R5<57001),AND(72500<R5,R5<75001)),$G5,IF(OR(AND(27500<R5,R5<30001),AND(57000<R5,R5<60001),AND(75000<R5,R5<77500)),$H5,VLOOKUP(R5,BDins,6,FALSE))))) -> 250 | S7: =IF(S9>10000,HLOOKUP(S9,$O5:R8,4,FALSE),IF(OR(AND(22500<S5,S5<25001),AND(50000<S5,S5<53501),AND(70000<S5,S5<72501)),$F5,IF(OR(AND(25001<S5,S5<27501),AND(53500<S5,S5<57001),AND(72500<S5,S5<75001)),$G5,IF(OR(AND(27500<S5,S5<30001),AND(57000<S5,S5<60001),AND(75000<S5,S5<77500)),$H5,VLOOKUP(S5,BDins,6,FALSE))))) -> 18.5 | T7: =IF(T9>10000,HLOOKUP(T9,$O5:S8,4,FALSE),IF(OR(AND(22500<T5,T5<25001),AND(50000<T5,T5<53501),AND(70000<T5,T5<72501)),$F5,IF(OR(AND(25001<T5,T5<27501),AND(53500<T5,T5<57001),AND(72500<T5,T5<75001)),$G5,IF(OR(AND(27500<T5,T5<30001),AND(57000<T5,T5<60001),AND(75000<T5,T5<77500)),$H5,VLOOKUP(T5,BDins,6,FALSE))))) -> 45.8 | U7: =IF(U9>10000,HLOOKUP(U9,$O5:T8,4,FALSE),IF(OR(AND(22500<U5,U5<25001),AND(50000<U5,U5<53501),AND(70000<U5,U5<72501)),$F5,IF(OR(AND(25001<U5,U5<27501),AND(53500<U5,U5<57001),AND(72500<U5,U5<75001)),$G5,IF(OR(AND(27500<U5,U5<30001),AND(57000<U5,U5<60001),AND(75000<U5,U5<77500)),$H5,VLOOKUP(U5,BDins,6,FALSE))))) -> 40 | V7: =IF(V9>10000,HLOOKUP(V9,$O5:U8,4,FALSE),IF(OR(AND(22500<V5,V5<25001),AND(50000<V5,V5<53501),AND(70000<V5,V5<72501)),$F5,IF(OR(AND(25001<V5,V5<27501),AND(53500<V5,V5<57001),AND(72500<V5,V5<75001)),$G5,IF(OR(AND(27500<V5,V5<30001),AND(57000<V5,V5<60001),AND(75000<V5,V5<77500)),$H5,VLOOKUP(V5,BDins,6,FALSE))))) -> 1500 | W7: =IF(W9>10000,HLOOKUP(W9,$O5:V8,4,FALSE),IF(OR(AND(22500<W5,W5<25001),AND(50000<W5,W5<53501),AND(70000<W5,W5<72501)),$F5,IF(OR(AND(25001<W5,W5<27501),AND(53500<W5,W5<57001),AND(72500<W5,W5<75001)),$G5,IF(OR(AND(27500<W5,W5<30001),AND(57000<W5,W5<60001),AND(75000<W5,W5<77500)),$H5,VLOOKUP(W5,BDins,6,FALSE))))) -> 515.56
O8: =IF($K5>0,ROUND(O6*$E5/100,DpCU),IF(O9>10000,ROUND(HLOOKUP(O9,$O5:$W8,4,FALSE)/100*O6,DpCU),IF(OR(O5<20001,O5>95000,AND(60000<O5,O5<70001)),ROUND(ROUND(O6*JL/$C5,DcCU)*O7,DpCU),IF(OR(AND(20000<O5,O5<22501),AND(30000<O5,O5<50001),77500<O5),ROUND(O7*O6,DpCU),IF(OR(AND(22500<O5,O5<25001),AND(50000<O5,O5<53501),AND(70000<O5,O5<72501)),ROUND($F5/100*O6,DpCU),IF(OR(AND(25000<O5,O5<27501),AND(53500<O5,O5<57001),AND(72500<O5,O5<75001)),ROUND($G5/100*O6,DpCU),ROUND($H5/100*O6,DpCU))))))) -> 33.29 | P8: =IF($K5>0,ROUND(P6*$E5/100,DpCU),IF(P9>10000,ROUND(HLOOKUP(P9,$O5:$W8,4,FALSE)/100*P6,DpCU),IF(OR(P5<20001,P5>95000,AND(60000<P5,P5<70001)),ROUND(ROUND(P6*JL/$C5,DcCU)*P7,DpCU),IF(OR(AND(20000<P5,P5<22501),AND(30000<P5,P5<50001),77500<P5),ROUND(P7*P6,DpCU),IF(OR(AND(22500<P5,P5<25001),AND(50000<P5,P5<53501),AND(70000<P5,P5<72501)),ROUND($F5/100*P6,DpCU),IF(OR(AND(25000<P5,P5<27501),AND(53500<P5,P5<57001),AND(72500<P5,P5<75001)),ROUND($G5/100*P6,DpCU),ROUND($H5/100*P6,DpCU))))))) -> 277.47 | Q8: =IF($K5>0,ROUND(Q6*$E5/100,DpCU),IF(Q9>10000,ROUND(HLOOKUP(Q9,$O5:$W8,4,FALSE)/100*Q6,DpCU),IF(OR(Q5<20001,Q5>95000,AND(60000<Q5,Q5<70001)),ROUND(ROUND(Q6*JL/$C5,DcCU)*Q7,DpCU),IF(OR(AND(20000<Q5,Q5<22501),AND(30000<Q5,Q5<50001),77500<Q5),ROUND(Q7*Q6,DpCU),IF(OR(AND(22500<Q5,Q5<25001),AND(50000<Q5,Q5<53501),AND(70000<Q5,Q5<72501)),ROUND($F5/100*Q6,DpCU),IF(OR(AND(25000<Q5,Q5<27501),AND(53500<Q5,Q5<57001),AND(72500<Q5,Q5<75001)),ROUND($G5/100*Q6,DpCU),ROUND($H5/100*Q6,DpCU))))))) -> 204.8 | R8: =IF($K5>0,ROUND(R6*$E5/100,DpCU),IF(R9>10000,ROUND(HLOOKUP(R9,$O5:$W8,4,FALSE)/100*R6,DpCU),IF(OR(R5<20001,R5>95000,AND(60000<R5,R5<70001)),ROUND(ROUND(R6*JL/$C5,DcCU)*R7,DpCU),IF(OR(AND(20000<R5,R5<22501),AND(30000<R5,R5<50001),77500<R5),ROUND(R7*R6,DpCU),IF(OR(AND(22500<R5,R5<25001),AND(50000<R5,R5<53501),AND(70000<R5,R5<72501)),ROUND($F5/100*R6,DpCU),IF(OR(AND(25000<R5,R5<27501),AND(53500<R5,R5<57001),AND(72500<R5,R5<75001)),ROUND($G5/100*R6,DpCU),ROUND($H5/100*R6,DpCU))))))) -> 250 | S8: =IF($K5>0,ROUND(S6*$E5/100,DpCU),IF(S9>10000,ROUND(HLOOKUP(S9,$O5:$W8,4,FALSE)/100*S6,DpCU),IF(OR(S5<20001,S5>95000,AND(60000<S5,S5<70001)),ROUND(ROUND(S6*JL/$C5,DcCU)*S7,DpCU),IF(OR(AND(20000<S5,S5<22501),AND(30000<S5,S5<50001),77500<S5),ROUND(S7*S6,DpCU),IF(OR(AND(22500<S5,S5<25001),AND(50000<S5,S5<53501),AND(70000<S5,S5<72501)),ROUND($F5/100*S6,DpCU),IF(OR(AND(25000<S5,S5<27501),AND(53500<S5,S5<57001),AND(72500<S5,S5<75001)),ROUND($G5/100*S6,DpCU),ROUND($H5/100*S6,DpCU))))))) -> 55.5 | T8: =IF($K5>0,ROUND(T6*$E5/100,DpCU),IF(T9>10000,ROUND(HLOOKUP(T9,$O5:$W8,4,FALSE)/100*T6,DpCU),IF(OR(T5<20001,T5>95000,AND(60000<T5,T5<70001)),ROUND(ROUND(T6*JL/$C5,DcCU)*T7,DpCU),IF(OR(AND(20000<T5,T5<22501),AND(30000<T5,T5<50001),77500<T5),ROUND(T7*T6,DpCU),IF(OR(AND(22500<T5,T5<25001),AND(50000<T5,T5<53501),AND(70000<T5,T5<72501)),ROUND($F5/100*T6,DpCU),IF(OR(AND(25000<T5,T5<27501),AND(53500<T5,T5<57001),AND(72500<T5,T5<75001)),ROUND($G5/100*T6,DpCU),ROUND($H5/100*T6,DpCU))))))) -> 45.8 | U8: =IF($K5>0,ROUND(U6*$E5/100,DpCU),IF(U9>10000,ROUND(HLOOKUP(U9,$O5:$W8,4,FALSE)/100*U6,DpCU),IF(OR(U5<20001,U5>95000,AND(60000<U5,U5<70001)),ROUND(ROUND(U6*JL/$C5,DcCU)*U7,DpCU),IF(OR(AND(20000<U5,U5<22501),AND(30000<U5,U5<50001),77500<U5),ROUND(U7*U6,DpCU),IF(OR(AND(22500<U5,U5<25001),AND(50000<U5,U5<53501),AND(70000<U5,U5<72501)),ROUND($F5/100*U6,DpCU),IF(OR(AND(25000<U5,U5<27501),AND(53500<U5,U5<57001),AND(72500<U5,U5<75001)),ROUND($G5/100*U6,DpCU),ROUND($H5/100*U6,DpCU))))))) -> 40 | V8: =IF($K5>0,ROUND(V6*$E5/100,DpCU),IF(V9>10000,ROUND(HLOOKUP(V9,$O5:$W8,4,FALSE)/100*V6,DpCU),IF(OR(V5<20001,V5>95000,AND(60000<V5,V5<70001)),ROUND(ROUND(V6*JL/$C5,DcCU)*V7,DpCU),IF(OR(AND(20000<V5,V5<22501),AND(30000<V5,V5<50001),77500<V5),ROUND(V7*V6,DpCU),IF(OR(AND(22500<V5,V5<25001),AND(50000<V5,V5<53501),AND(70000<V5,V5<72501)),ROUND($F5/100*V6,DpCU),IF(OR(AND(25000<V5,V5<27501),AND(53500<V5,V5<57001),AND(72500<V5,V5<75001)),ROUND($G5/100*V6,DpCU),ROUND($H5/100*V6,DpCU))))))) -> 300 | W8: =IF($K5>0,ROUND(W6*$E5/100,DpCU),IF(W9>10000,ROUND(HLOOKUP(W9,$O5:$W8,4,FALSE)/100*W6,DpCU),IF(OR(W5<20001,W5>95000,AND(60000<W5,W5<70001)),ROUND(ROUND(W6*JL/$C5,DcCU)*W7,DpCU),IF(OR(AND(20000<W5,W5<22501),AND(30000<W5,W5<50001),77500<W5),ROUND(W7*W6,DpCU),IF(OR(AND(22500<W5,W5<25001),AND(50000<W5,W5<53501),AND(70000<W5,W5<72501)),ROUND($F5/100*W6,DpCU),IF(OR(AND(25000<W5,W5<27501),AND(53500<W5,W5<57001),AND(72500<W5,W5<75001)),ROUND($G5/100*W6,DpCU),ROUND($H5/100*W6,DpCU))))))) -> 25.78
B9: =A5&"r" -> 10001r
A10: 10002 | B10: ALMACEN Y GUARDIANIA | C10: =ROUND(J10*JL*Frto/8,4) -> 0.6 | D10: GLB | E10: =SUM($O13:$W13) -> 1976.58 | F10: =SUMIF($O10:$W10,"<22501",$O13:$W13) -> 515.56 | G10: =SUMIFS($O13:$W13,$O10:$W10,">30000",$O10:$W10,"<50001") -> 1445.55 | H10: =SUMIFS($O13:$W13,$O10:$W10,">60000",$O10:$W10,"<70001") -> 0 | I10: 9 | J10: 0.6 | O10: 10001 | P10: 10002 | Q10: 10003 | R10: 30001 | S10: 30002 | T10: 30003 | U10: 30004 | V10: 30006 | W10: 70001
B11: =A10&"C" -> 10002C | O11: 0.1 | P11: 1 | Q11: 1 | R11: 1 | S11: 4.5 | T11: 1 | U11: 1.35 | V11: 0.5 | W11: 3
O12: =IF(O14>10000,HLOOKUP(O14,N10:$O13,4,FALSE),IF(OR(AND(22500<O10,O10<25001),AND(50000<O10,O10<53501),AND(70000<O10,O10<72501)),$F10,IF(OR(AND(25001<O10,O10<27501),AND(53500<O10,O10<57001),AND(72500<O10,O10<75001)),$G10,IF(OR(AND(27500<O10,O10<30001),AND(57000<O10,O10<60001),AND(75000<O10,O10<77500)),$H10,VLOOKUP(O10,BDins,6,FALSE))))) -> 24.97 | P12: =IF(P14>10000,HLOOKUP(P14,O10:$O13,4,FALSE),IF(OR(AND(22500<P10,P10<25001),AND(50000<P10,P10<53501),AND(70000<P10,P10<72501)),$F10,IF(OR(AND(25001<P10,P10<27501),AND(53500<P10,P10<57001),AND(72500<P10,P10<75001)),$G10,IF(OR(AND(27500<P10,P10<30001),AND(57000<P10,P10<60001),AND(75000<P10,P10<77500)),$H10,VLOOKUP(P10,BDins,6,FALSE))))) -> 20.81 | Q12: =IF(Q14>10000,HLOOKUP(Q14,$O10:P13,4,FALSE),IF(OR(AND(22500<Q10,Q10<25001),AND(50000<Q10,Q10<53501),AND(70000<Q10,Q10<72501)),$F10,IF(OR(AND(25001<Q10,Q10<27501),AND(53500<Q10,Q10<57001),AND(72500<Q10,Q10<75001)),$G10,IF(OR(AND(27500<Q10,Q10<30001),AND(57000<Q10,Q10<60001),AND(75000<Q10,Q10<77500)),$H10,VLOOKUP(Q10,BDins,6,FALSE))))) -> 15.36 | R12: =IF(R14>10000,HLOOKUP(R14,$O10:Q13,4,FALSE),IF(OR(AND(22500<R10,R10<25001),AND(50000<R10,R10<53501),AND(70000<R10,R10<72501)),$F10,IF(OR(AND(25001<R10,R10<27501),AND(53500<R10,R10<57001),AND(72500<R10,R10<75001)),$G10,IF(OR(AND(27500<R10,R10<30001),AND(57000<R10,R10<60001),AND(75000<R10,R10<77500)),$H10,VLOOKUP(R10,BDins,6,FALSE))))) -> 250 | S12: =IF(S14>10000,HLOOKUP(S14,$O10:R13,4,FALSE),IF(OR(AND(22500<S10,S10<25001),AND(50000<S10,S10<53501),AND(70000<S10,S10<72501)),$F10,IF(OR(AND(25001<S10,S10<27501),AND(53500<S10,S10<57001),AND(72500<S10,S10<75001)),$G10,IF(OR(AND(27500<S10,S10<30001),AND(57000<S10,S10<60001),AND(75000<S10,S10<77500)),$H10,VLOOKUP(S10,BDins,6,FALSE))))) -> 18.5 | T12: =IF(T14>10000,HLOOKUP(T14,$O10:S13,4,FALSE),IF(OR(AND(22500<T10,T10<25001),AND(50000<T10,T10<53501),AND(70000<T10,T10<72501)),$F10,IF(OR(AND(25001<T10,T10<27501),AND(53500<T10,T10<57001),AND(72500<T10,T10<75001)),$G10,IF(OR(AND(27500<T10,T10<30001),AND(57000<T10,T10<60001),AND(75000<T10,T10<77500)),$H10,VLOOKUP(T10,BDins,6,FALSE))))) -> 45.8 | U12: =IF(U14>10000,HLOOKUP(U14,$O10:T13,4,FALSE),IF(OR(AND(22500<U10,U10<25001),AND(50000<U10,U10<53501),AND(70000<U10,U10<72501)),$F10,IF(OR(AND(25001<U10,U10<27501),AND(53500<U10,U10<57001),AND(72500<U10,U10<75001)),$G10,IF(OR(AND(27500<U10,U10<30001),AND(57000<U10,U10<60001),AND(75000<U10,U10<77500)),$H10,VLOOKUP(U10,BDins,6,FALSE))))) -> 40 | V12: =IF(V14>10000,HLOOKUP(V14,$O10:U13,4,FALSE),IF(OR(AND(22500<V10,V10<25001),AND(50000<V10,V10<53501),AND(70000<V10,V10<72501)),$F10,IF(OR(AND(25001<V10,V10<27501),AND(53500<V10,V10<57001),AND(72500<V10,V10<75001)),$G10,IF(OR(AND(27500<V10,V10<30001),AND(57000<V10,V10<60001),AND(75000<V10,V10<77500)),$H10,VLOOKUP(V10,BDins,6,FALSE))))) -> 2025 | W12: =IF(W14>10000,HLOOKUP(W14,$O10:V13,4,FALSE),IF(OR(AND(22500<W10,W10<25001),AND(50000<W10,W10<53501),AND(70000<W10,W10<72501)),$F10,IF(OR(AND(25001<W10,W10<27501),AND(53500<W10,W10<57001),AND(72500<W10,W10<75001)),$G10,IF(OR(AND(27500<W10,W10<30001),AND(57000<W10,W10<60001),AND(75000<W10,W10<77500)),$H10,VLOOKUP(W10,BDins,6,FALSE))))) -> 515.56
O13: =IF($K10>0,ROUND(O11*$E10/100,DpCU),IF(O14>10000,ROUND(HLOOKUP(O14,$O10:$W13,4,FALSE)/100*O11,DpCU),IF(OR(O10<20001,O10>95000,AND(60000<O10,O10<70001)),ROUND(ROUND(O11*JL/$C10,DcCU)*O12,DpCU),IF(OR(AND(20000<O10,O10<22501),AND(30000<O10,O10<50001),77500<O10),ROUND(O12*O11,DpCU),IF(OR(AND(22500<O10,O10<25001),AND(50000<O10,O10<53501),AND(70000<O10,O10<72501)),ROUND($F10/100*O11,DpCU),IF(OR(AND(25000<O10,O10<27501),AND(53500<O10,O10<57001),AND(72500<O10,O10<75001)),ROUND($G10/100*O11,DpCU),ROUND($H10/100*O11,DpCU))))))) -> 33.29 | P13: =IF($K10>0,ROUND(P11*$E10/100,DpCU),IF(P14>10000,ROUND(HLOOKUP(P14,$O10:$W13,4,FALSE)/100*P11,DpCU),IF(OR(P10<20001,P10>95000,AND(60000<P10,P10<70001)),ROUND(ROUND(P11*JL/$C10,DcCU)*P12,DpCU),IF(OR(AND(20000<P10,P10<22501),AND(30000<P10,P10<50001),77500<P10),ROUND(P12*P11,DpCU),IF(OR(AND(22500<P10,P10<25001),AND(50000<P10,P10<53501),AND(70000<P10,P10<72501)),ROUND($F10/100*P11,DpCU),IF(OR(AND(25000<P10,P10<27501),AND(53500<P10,P10<57001),AND(72500<P10,P10<75001)),ROUND($G10/100*P11,DpCU),ROUND($H10/100*P11,DpCU))))))) -> 277.47 | Q13: =IF($K10>0,ROUND(Q11*$E10/100,DpCU),IF(Q14>10000,ROUND(HLOOKUP(Q14,$O10:$W13,4,FALSE)/100*Q11,DpCU),IF(OR(Q10<20001,Q10>95000,AND(60000<Q10,Q10<70001)),ROUND(ROUND(Q11*JL/$C10,DcCU)*Q12,DpCU),IF(OR(AND(20000<Q10,Q10<22501),AND(30000<Q10,Q10<50001),77500<Q10),ROUND(Q12*Q11,DpCU),IF(OR(AND(22500<Q10,Q10<25001),AND(50000<Q10,Q10<53501),AND(70000<Q10,Q10<72501)),ROUND($F10/100*Q11,DpCU),IF(OR(AND(25000<Q10,Q10<27501),AND(53500<Q10,Q10<57001),AND(72500<Q10,Q10<75001)),ROUND($G10/100*Q11,DpCU),ROUND($H10/100*Q11,DpCU))))))) -> 204.8 | R13: =IF($K10>0,ROUND(R11*$E10/100,DpCU),IF(R14>10000,ROUND(HLOOKUP(R14,$O10:$W13,4,FALSE)/100*R11,DpCU),IF(OR(R10<20001,R10>95000,AND(60000<R10,R10<70001)),ROUND(ROUND(R11*JL/$C10,DcCU)*R12,DpCU),IF(OR(AND(20000<R10,R10<22501),AND(30000<R10,R10<50001),77500<R10),ROUND(R12*R11,DpCU),IF(OR(AND(22500<R10,R10<25001),AND(50000<R10,R10<53501),AND(70000<R10,R10<72501)),ROUND($F10/100*R11,DpCU),IF(OR(AND(25000<R10,R10<27501),AND(53500<R10,R10<57001),AND(72500<R10,R10<75001)),ROUND($G10/100*R11,DpCU),ROUND($H10/100*R11,DpCU))))))) -> 250 | S13: =IF($K10>0,ROUND(S11*$E10/100,DpCU),IF(S14>10000,ROUND(HLOOKUP(S14,$O10:$W13,4,FALSE)/100*S11,DpCU),IF(OR(S10<20001,S10>95000,AND(60000<S10,S10<70001)),ROUND(ROUND(S11*JL/$C10,DcCU)*S12,DpCU),IF(OR(AND(20000<S10,S10<22501),AND(30000<S10,S10<50001),77500<S10),ROUND(S12*S11,DpCU),IF(OR(AND(22500<S10,S10<25001),AND(50000<S10,S10<53501),AND(70000<S10,S10<72501)),ROUND($F10/100*S11,DpCU),IF(OR(AND(25000<S10,S10<27501),AND(53500<S10,S10<57001),AND(72500<S10,S10<75001)),ROUND($G10/100*S11,DpCU),ROUND($H10/100*S11,DpCU))))))) -> 83.25 | T13: =IF($K10>0,ROUND(T11*$E10/100,DpCU),IF(T14>10000,ROUND(HLOOKUP(T14,$O10:$W13,4,FALSE)/100*T11,DpCU),IF(OR(T10<20001,T10>95000,AND(60000<T10,T10<70001)),ROUND(ROUND(T11*JL/$C10,DcCU)*T12,DpCU),IF(OR(AND(20000<T10,T10<22501),AND(30000<T10,T10<50001),77500<T10),ROUND(T12*T11,DpCU),IF(OR(AND(22500<T10,T10<25001),AND(50000<T10,T10<53501),AND(70000<T10,T10<72501)),ROUND($F10/100*T11,DpCU),IF(OR(AND(25000<T10,T10<27501),AND(53500<T10,T10<57001),AND(72500<T10,T10<75001)),ROUND($G10/100*T11,DpCU),ROUND($H10/100*T11,DpCU))))))) -> 45.8 | U13: =IF($K10>0,ROUND(U11*$E10/100,DpCU),IF(U14>10000,ROUND(HLOOKUP(U14,$O10:$W13,4,FALSE)/100*U11,DpCU),IF(OR(U10<20001,U10>95000,AND(60000<U10,U10<70001)),ROUND(ROUND(U11*JL/$C10,DcCU)*U12,DpCU),IF(OR(AND(20000<U10,U10<22501),AND(30000<U10,U10<50001),77500<U10),ROUND(U12*U11,DpCU),IF(OR(AND(22500<U10,U10<25001),AND(50000<U10,U10<53501),AND(70000<U10,U10<72501)),ROUND($F10/100*U11,DpCU),IF(OR(AND(25000<U10,U10<27501),AND(53500<U10,U10<57001),AND(72500<U10,U10<75001)),ROUND($G10/100*U11,DpCU),ROUND($H10/100*U11,DpCU))))))) -> 54 | V13: =IF($K10>0,ROUND(V11*$E10/100,DpCU),IF(V14>10000,ROUND(HLOOKUP(V14,$O10:$W13,4,FALSE)/100*V11,DpCU),IF(OR(V10<20001,V10>95000,AND(60000<V10,V10<70001)),ROUND(ROUND(V11*JL/$C10,DcCU)*V12,DpCU),IF(OR(AND(20000<V10,V10<22501),AND(30000<V10,V10<50001),77500<V10),ROUND(V12*V11,DpCU),IF(OR(AND(22500<V10,V10<25001),AND(50000<V10,V10<53501),AND(70000<V10,V10<72501)),ROUND($F10/100*V11,DpCU),IF(OR(AND(25000<V10,V10<27501),AND(53500<V10,V10<57001),AND(72500<V10,V10<75001)),ROUND($G10/100*V11,DpCU),ROUND($H10/100*V11,DpCU))))))) -> 1012.5 | W13: =IF($K10>0,ROUND(W11*$E10/100,DpCU),IF(W14>10000,ROUND(HLOOKUP(W14,$O10:$W13,4,FALSE)/100*W11,DpCU),IF(OR(W10<20001,W10>95000,AND(60000<W10,W10<70001)),ROUND(ROUND(W11*JL/$C10,DcCU)*W12,DpCU),IF(OR(AND(20000<W10,W10<22501),AND(30000<W10,W10<50001),77500<W10),ROUND(W12*W11,DpCU),IF(OR(AND(22500<W10,W10<25001),AND(50000<W10,W10<53501),AND(70000<W10,W10<72501)),ROUND($F10/100*W11,DpCU),IF(OR(AND(25000<W10,W10<27501),AND(53500<W10,W10<57001),AND(72500<W10,W10<75001)),ROUND($G10/100*W11,DpCU),ROUND($H10/100*W11,DpCU))))))) -> 15.47
B14: =A10&"r" -> 10002r
A15: 10003 | B15: SS. HH. PARA LA OBRA | C15: =ROUND(J15*JL*Frto/8,4) -> 2 | D15: GLB | E15: =SUM($O18:$AA18) -> 2001.68 | F15: =SUMIF($O15:$AA15,"<22501",$O18:$AA18) -> 444.03 | G15: =SUMIFS($O18:$AA18,$O15:$AA15,">30000",$O15:$AA15,"<50001") -> 1535.45 | H15: =SUMIFS($O18:$AA18,$O15:$AA15,">60000",$O15:$AA15,"<70001") -> 0 | I15: 13 | J15: 2 | O15: 10001 | P15: 10002 | Q15: 10003 | R15: 30001 | S15: 30002 | T15: 30004 | U15: 30007 | V15: 30008 | W15: 30009 | X15: 30010 | Y15: 30011 | Z15: 30012 | AA15: 70001
B16: =A15&"C" -> 10003C | O16: 0.1 | P16: 3 | Q16: 3 | R16: 0.5 | S16: 3 | T16: 0.9 | U16: 3 | V16: 1 | W16: 60 | X16: 8 | Y16: 12 | Z16: 1 | AA16: 5
O17: =IF(O19>10000,HLOOKUP(O19,N15:$O18,4,FALSE),IF(OR(AND(22500<O15,O15<25001),AND(50000<O15,O15<53501),AND(70000<O15,O15<72501)),$F15,IF(OR(AND(25001<O15,O15<27501),AND(53500<O15,O15<57001),AND(72500<O15,O15<75001)),$G15,IF(OR(AND(27500<O15,O15<30001),AND(57000<O15,O15<60001),AND(75000<O15,O15<77500)),$H15,VLOOKUP(O15,BDins,6,FALSE))))) -> 24.97 | P17: =IF(P19>10000,HLOOKUP(P19,O15:$O18,4,FALSE),IF(OR(AND(22500<P15,P15<25001),AND(50000<P15,P15<53501),AND(70000<P15,P15<72501)),$F15,IF(OR(AND(25001<P15,P15<27501),AND(53500<P15,P15<57001),AND(72500<P15,P15<75001)),$G15,IF(OR(AND(27500<P15,P15<30001),AND(57000<P15,P15<60001),AND(75000<P15,P15<77500)),$H15,VLOOKUP(P15,BDins,6,FALSE))))) -> 20.81 | Q17: =IF(Q19>10000,HLOOKUP(Q19,$O15:P18,4,FALSE),IF(OR(AND(22500<Q15,Q15<25001),AND(50000<Q15,Q15<53501),AND(70000<Q15,Q15<72501)),$F15,IF(OR(AND(25001<Q15,Q15<27501),AND(53500<Q15,Q15<57001),AND(72500<Q15,Q15<75001)),$G15,IF(OR(AND(27500<Q15,Q15<30001),AND(57000<Q15,Q15<60001),AND(75000<Q15,Q15<77500)),$H15,VLOOKUP(Q15,BDins,6,FALSE))))) -> 15.36 | R17: =IF(R19>10000,HLOOKUP(R19,$O15:Q18,4,FALSE),IF(OR(AND(22500<R15,R15<25001),AND(50000<R15,R15<53501),AND(70000<R15,R15<72501)),$F15,IF(OR(AND(25001<R15,R15<27501),AND(53500<R15,R15<57001),AND(72500<R15,R15<75001)),$G15,IF(OR(AND(27500<R15,R15<30001),AND(57000<R15,R15<60001),AND(75000<R15,R15<77500)),$H15,VLOOKUP(R15,BDins,6,FALSE))))) -> 250 | S17: =IF(S19>10000,HLOOKUP(S19,$O15:R18,4,FALSE),IF(OR(AND(22500<S15,S15<25001),AND(50000<S15,S15<53501),AND(70000<S15,S15<72501)),$F15,IF(OR(AND(25001<S15,S15<27501),AND(53500<S15,S15<57001),AND(72500<S15,S15<75001)),$G15,IF(OR(AND(27500<S15,S15<30001),AND(57000<S15,S15<60001),AND(75000<S15,S15<77500)),$H15,VLOOKUP(S15,BDins,6,FALSE))))) -> 18.5 | T17: =IF(T19>10000,HLOOKUP(T19,$O15:S18,4,FALSE),IF(OR(AND(22500<T15,T15<25001),AND(50000<T15,T15<53501),AND(70000<T15,T15<72501)),$F15,IF(OR(AND(25001<T15,T15<27501),AND(53500<T15,T15<57001),AND(72500<T15,T15<75001)),$G15,IF(OR(AND(27500<T15,T15<30001),AND(57000<T15,T15<60001),AND(75000<T15,T15<77500)),$H15,VLOOKUP(T15,BDins,6,FALSE))))) -> 40 | U17: =IF(U19>10000,HLOOKUP(U19,$O15:T18,4,FALSE),IF(OR(AND(22500<U15,U15<25001),AND(50000<U15,U15<53501),AND(70000<U15,U15<72501)),$F15,IF(OR(AND(25001<U15,U15<27501),AND(53500<U15,U15<57001),AND(72500<U15,U15<75001)),$G15,IF(OR(AND(27500<U15,U15<30001),AND(57000<U15,U15<60001),AND(75000<U15,U15<77500)),$H15,VLOOKUP(U15,BDins,6,FALSE))))) -> 3.65 | V17: =IF(V19>10000,HLOOKUP(V19,$O15:U18,4,FALSE),IF(OR(AND(22500<V15,V15<25001),AND(50000<V15,V15<53501),AND(70000<V15,V15<72501)),$F15,IF(OR(AND(25001<V15,V15<27501),AND(53500<V15,V15<57001),AND(72500<V15,V15<75001)),$G15,IF(OR(AND(27500<V15,V15<30001),AND(57000<V15,V15<60001),AND(75000<V15,V15<77500)),$H15,VLOOKUP(V15,BDins,6,FALSE))))) -> 200 | W17: =IF(W19>10000,HLOOKUP(W19,$O15:V18,4,FALSE),IF(OR(AND(22500<W15,W15<25001),AND(50000<W15,W15<53501),AND(70000<W15,W15<72501)),$F15,IF(OR(AND(25001<W15,W15<27501),AND(53500<W15,W15<57001),AND(72500<W15,W15<75001)),$G15,IF(OR(AND(27500<W15,W15<30001),AND(57000<W15,W15<60001),AND(75000<W15,W15<77500)),$H15,VLOOKUP(W15,BDins,6,FALSE))))) -> 3.7 | X17: =IF(X19>10000,HLOOKUP(X19,$O15:W18,4,FALSE),IF(OR(AND(22500<X15,X15<25001),AND(50000<X15,X15<53501),AND(70000<X15,X15<72501)),$F15,IF(OR(AND(25001<X15,X15<27501),AND(53500<X15,X15<57001),AND(72500<X15,X15<75001)),$G15,IF(OR(AND(27500<X15,X15<30001),AND(57000<X15,X15<60001),AND(75000<X15,X15<77500)),$H15,VLOOKUP(X15,BDins,6,FALSE))))) -> 25 | ... AA17: =IF(AA19>10000,HLOOKUP(AA19,$O15:Z18,4,FALSE),IF(OR(AND(22500<AA15,AA15<25001),AND(50000<AA15,AA15<53501),AND(70000<AA15,AA15<72501)),$F15,IF(OR(AND(25001<AA15,AA15<27501),AND(53500<AA15,AA15<57001),AND(72500<AA15,AA15<75001)),$G15,IF(OR(AND(27500<AA15,AA15<30001),AND(57000<AA15,AA15<60001),AND(75000<AA15,AA15<77500)),$H15,VLOOKUP(AA15,BDins,6,FALSE))))) -> 444.03
O18: =IF($K15>0,ROUND(O16*$E15/100,DpCU),IF(O19>10000,ROUND(HLOOKUP(O19,$O15:$AA18,4,FALSE)/100*O16,DpCU),IF(OR(O15<20001,O15>95000,AND(60000<O15,O15<70001)),ROUND(ROUND(O16*JL/$C15,DcCU)*O17,DpCU),IF(OR(AND(20000<O15,O15<22501),AND(30000<O15,O15<50001),77500<O15),ROUND(O17*O16,DpCU),IF(OR(AND(22500<O15,O15<25001),AND(50000<O15,O15<53501),AND(70000<O15,O15<72501)),ROUND($F15/100*O16,DpCU),IF(OR(AND(25000<O15,O15<27501),AND(53500<O15,O15<57001),AND(72500<O15,O15<75001)),ROUND($G15/100*O16,DpCU),ROUND($H15/100*O16,DpCU))))))) -> 9.99 | P18: =IF($K15>0,ROUND(P16*$E15/100,DpCU),IF(P19>10000,ROUND(HLOOKUP(P19,$O15:$AA18,4,FALSE)/100*P16,DpCU),IF(OR(P15<20001,P15>95000,AND(60000<P15,P15<70001)),ROUND(ROUND(P16*JL/$C15,DcCU)*P17,DpCU),IF(OR(AND(20000<P15,P15<22501),AND(30000<P15,P15<50001),77500<P15),ROUND(P17*P16,DpCU),IF(OR(AND(22500<P15,P15<25001),AND(50000<P15,P15<53501),AND(70000<P15,P15<72501)),ROUND($F15/100*P16,DpCU),IF(OR(AND(25000<P15,P15<27501),AND(53500<P15,P15<57001),AND(72500<P15,P15<75001)),ROUND($G15/100*P16,DpCU),ROUND($H15/100*P16,DpCU))))))) -> 249.72 | Q18: =IF($K15>0,ROUND(Q16*$E15/100,DpCU),IF(Q19>10000,ROUND(HLOOKUP(Q19,$O15:$AA18,4,FALSE)/100*Q16,DpCU),IF(OR(Q15<20001,Q15>95000,AND(60000<Q15,Q15<70001)),ROUND(ROUND(Q16*JL/$C15,DcCU)*Q17,DpCU),IF(OR(AND(20000<Q15,Q15<22501),AND(30000<Q15,Q15<50001),77500<Q15),ROUND(Q17*Q16,DpCU),IF(OR(AND(22500<Q15,Q15<25001),AND(50000<Q15,Q15<53501),AND(70000<Q15,Q15<72501)),ROUND($F15/100*Q16,DpCU),IF(OR(AND(25000<Q15,Q15<27501),AND(53500<Q15,Q15<57001),AND(72500<Q15,Q15<75001)),ROUND($G15/100*Q16,DpCU),ROUND($H15/100*Q16,DpCU))))))) -> 184.32 | R18: =IF($K15>0,ROUND(R16*$E15/100,DpCU),IF(R19>10000,ROUND(HLOOKUP(R19,$O15:$AA18,4,FALSE)/100*R16,DpCU),IF(OR(R15<20001,R15>95000,AND(60000<R15,R15<70001)),ROUND(ROUND(R16*JL/$C15,DcCU)*R17,DpCU),IF(OR(AND(20000<R15,R15<22501),AND(30000<R15,R15<50001),77500<R15),ROUND(R17*R16,DpCU),IF(OR(AND(22500<R15,R15<25001),AND(50000<R15,R15<53501),AND(70000<R15,R15<72501)),ROUND($F15/100*R16,DpCU),IF(OR(AND(25000<R15,R15<27501),AND(53500<R15,R15<57001),AND(72500<R15,R15<75001)),ROUND($G15/100*R16,DpCU),ROUND($H15/100*R16,DpCU))))))) -> 125 | S18: =IF($K15>0,ROUND(S16*$E15/100,DpCU),IF(S19>10000,ROUND(HLOOKUP(S19,$O15:$AA18,4,FALSE)/100*S16,DpCU),IF(OR(S15<20001,S15>95000,AND(60000<S15,S15<70001)),ROUND(ROUND(S16*JL/$C15,DcCU)*S17,DpCU),IF(OR(AND(20000<S15,S15<22501),AND(30000<S15,S15<50001),77500<S15),ROUND(S17*S16,DpCU),IF(OR(AND(22500<S15,S15<25001),AND(50000<S15,S15<53501),AND(70000<S15,S15<72501)),ROUND($F15/100*S16,DpCU),IF(OR(AND(25000<S15,S15<27501),AND(53500<S15,S15<57001),AND(72500<S15,S15<75001)),ROUND($G15/100*S16,DpCU),ROUND($H15/100*S16,DpCU))))))) -> 55.5 | T18: =IF($K15>0,ROUND(T16*$E15/100,DpCU),IF(T19>10000,ROUND(HLOOKUP(T19,$O15:$AA18,4,FALSE)/100*T16,DpCU),IF(OR(T15<20001,T15>95000,AND(60000<T15,T15<70001)),ROUND(ROUND(T16*JL/$C15,DcCU)*T17,DpCU),IF(OR(AND(20000<T15,T15<22501),AND(30000<T15,T15<50001),77500<T15),ROUND(T17*T16,DpCU),IF(OR(AND(22500<T15,T15<25001),AND(50000<T15,T15<53501),AND(70000<T15,T15<72501)),ROUND($F15/100*T16,DpCU),IF(OR(AND(25000<T15,T15<27501),AND(53500<T15,T15<57001),AND(72500<T15,T15<75001)),ROUND($G15/100*T16,DpCU),ROUND($H15/100*T16,DpCU))))))) -> 36 | U18: =IF($K15>0,ROUND(U16*$E15/100,DpCU),IF(U19>10000,ROUND(HLOOKUP(U19,$O15:$AA18,4,FALSE)/100*U16,DpCU),IF(OR(U15<20001,U15>95000,AND(60000<U15,U15<70001)),ROUND(ROUND(U16*JL/$C15,DcCU)*U17,DpCU),IF(OR(AND(20000<U15,U15<22501),AND(30000<U15,U15<50001),77500<U15),ROUND(U17*U16,DpCU),IF(OR(AND(22500<U15,U15<25001),AND(50000<U15,U15<53501),AND(70000<U15,U15<72501)),ROUND($F15/100*U16,DpCU),IF(OR(AND(25000<U15,U15<27501),AND(53500<U15,U15<57001),AND(72500<U15,U15<75001)),ROUND($G15/100*U16,DpCU),ROUND($H15/100*U16,DpCU))))))) -> 10.95 | V18: =IF($K15>0,ROUND(V16*$E15/100,DpCU),IF(V19>10000,ROUND(HLOOKUP(V19,$O15:$AA18,4,FALSE)/100*V16,DpCU),IF(OR(V15<20001,V15>95000,AND(60000<V15,V15<70001)),ROUND(ROUND(V16*JL/$C15,DcCU)*V17,DpCU),IF(OR(AND(20000<V15,V15<22501),AND(30000<V15,V15<50001),77500<V15),ROUND(V17*V16,DpCU),IF(OR(AND(22500<V15,V15<25001),AND(50000<V15,V15<53501),AND(70000<V15,V15<72501)),ROUND($F15/100*V16,DpCU),IF(OR(AND(25000<V15,V15<27501),AND(53500<V15,V15<57001),AND(72500<V15,V15<75001)),ROUND($G15/100*V16,DpCU),ROUND($H15/100*V16,DpCU))))))) -> 200 | ... AA18: =IF($K15>0,ROUND(AA16*$E15/100,DpCU),IF(AA19>10000,ROUND(HLOOKUP(AA19,$O15:$AA18,4,FALSE)/100*AA16,DpCU),IF(OR(AA15<20001,AA15>95000,AND(60000<AA15,AA15<70001)),ROUND(ROUND(AA16*JL/$C15,DcCU)*AA17,DpCU),IF(OR(AND(20000<AA15,AA15<22501),AND(30000<AA15,AA15<50001),77500<AA15),ROUND(AA17*AA16,DpCU),IF(OR(AND(22500<AA15,AA15<25001),AND(50000<AA15,AA15<53501),AND(70000<AA15,AA15<72501)),ROUND($F15/100*AA16,DpCU),IF(OR(AND(25000<AA15,AA15<27501),AND(53500<AA15,AA15<57001),AND(72500<AA15,AA15<75001)),ROUND($G15/100*AA16,DpCU),ROUND($H15/100*AA16,DpCU))))))) -> 22.2
B19: =A15&"r" -> 10003r
A20: 10004 | B20: TRANSPORTE VERTICAL DE MATERIALES | C20: =ROUND(J20*JL*Frto/8,4) -> 1 | D20: GLB | E20: =SUM($O23:$O23) -> 1664.8 | F20: =SUMIF($O20:$O20,"<22501",$O23:$O23) -> 1664.8 | G20: =SUMIFS($O23:$O23,$O20:$O20,">30000",$O20:$O20,"<50001") -> 0 | H20: =SUMIFS($O23:$O23,$O20:$O20,">60000",$O20:$O20,"<70001") -> 0 | I20: 1 | J20: 1 | O20: 10004
B21: =A20&"C" -> 10004C | O21: 10
O22: =IF(O24>10000,HLOOKUP(O24,N20:$O23,4,FALSE),IF(OR(AND(22500<O20,O20<25001),AND(50000<O20,O20<53501),AND(70000<O20,O20<72501)),$F20,IF(OR(AND(25001<O20,O20<27501),AND(53500<O20,O20<57001),AND(72500<O20,O20<75001)),$G20,IF(OR(AND(27500<O20,O20<30001),AND(57000<O20,O20<60001),AND(75000<O20,O20<77500)),$H20,VLOOKUP(O20,BDins,6,FALSE))))) -> 20.81
O23: =IF($K20>0,ROUND(O21*$E20/100,DpCU),IF(O24>10000,ROUND(HLOOKUP(O24,$O20:$O23,4,FALSE)/100*O21,DpCU),IF(OR(O20<20001,O20>95000,AND(60000<O20,O20<70001)),ROUND(ROUND(O21*JL/$C20,DcCU)*O22,DpCU),IF(OR(AND(20000<O20,O20<22501),AND(30000<O20,O20<50001),77500<O20),ROUND(O22*O21,DpCU),IF(OR(AND(22500<O20,O20<25001),AND(50000<O20,O20<53501),AND(70000<O20,O20<72501)),ROUND($F20/100*O21,DpCU),IF(OR(AND(25000<O20,O20<27501),AND(53500<O20,O20<57001),AND(72500<O20,O20<75001)),ROUND($G20/100*O21,DpCU),ROUND($H20/100*O21,DpCU))))))) -> 1664.8
B24: =A20&"r" -> 10004r
A25: 10005 | B25: PROTECCION DE LINDEROS DE PANELES DE TRIPLAY DE 1.20 X 2.40 M X 4 MM | C25: =ROUND(J25*JL*Frto/8,4) -> 10 | D25: M | E25: =SUM($O28:$T28) -> 76.53 | F25: =SUMIF($O25:$T25,"<22501",$O28:$T28) -> 43.23 | G25: =SUMIFS($O28:$T28,$O25:$T25,">30000",$O25:$T25,"<50001") -> 31.14 | H25: =SUMIFS($O28:$T28,$O25:$T25,">60000",$O25:$T25,"<70001") -> 0 | I25: 6 | J25: 10 | O25: 10001 | P25: 10003 | Q25: 10005 | R25: 30010 | S25: 30013 | T25: 70001
B26: =A25&"C" -> 10005C | O26: 0.1 | P26: 2 | Q26: 1 | R26: 0.45 | S26: 1.7 | T26: 5
O27: =IF(O29>10000,HLOOKUP(O29,N25:$O28,4,FALSE),IF(OR(AND(22500<O25,O25<25001),AND(50000<O25,O25<53501),AND(70000<O25,O25<72501)),$F25,IF(OR(AND(25001<O25,O25<27501),AND(53500<O25,O25<57001),AND(72500<O25,O25<75001)),$G25,IF(OR(AND(27500<O25,O25<30001),AND(57000<O25,O25<60001),AND(75000<O25,O25<77500)),$H25,VLOOKUP(O25,BDins,6,FALSE))))) -> 24.97 | P27: =IF(P29>10000,HLOOKUP(P29,O25:$O28,4,FALSE),IF(OR(AND(22500<P25,P25<25001),AND(50000<P25,P25<53501),AND(70000<P25,P25<72501)),$F25,IF(OR(AND(25001<P25,P25<27501),AND(53500<P25,P25<57001),AND(72500<P25,P25<75001)),$G25,IF(OR(AND(27500<P25,P25<30001),AND(57000<P25,P25<60001),AND(75000<P25,P25<77500)),$H25,VLOOKUP(P25,BDins,6,FALSE))))) -> 15.36 | Q27: =IF(Q29>10000,HLOOKUP(Q29,$O25:P28,4,FALSE),IF(OR(AND(22500<Q25,Q25<25001),AND(50000<Q25,Q25<53501),AND(70000<Q25,Q25<72501)),$F25,IF(OR(AND(25001<Q25,Q25<27501),AND(53500<Q25,Q25<57001),AND(72500<Q25,Q25<75001)),$G25,IF(OR(AND(27500<Q25,Q25<30001),AND(57000<Q25,Q25<60001),AND(75000<Q25,Q25<77500)),$H25,VLOOKUP(Q25,BDins,6,FALSE))))) -> 20.81 | R27: =IF(R29>10000,HLOOKUP(R29,$O25:Q28,4,FALSE),IF(OR(AND(22500<R25,R25<25001),AND(50000<R25,R25<53501),AND(70000<R25,R25<72501)),$F25,IF(OR(AND(25001<R25,R25<27501),AND(53500<R25,R25<57001),AND(72500<R25,R25<75001)),$G25,IF(OR(AND(27500<R25,R25<30001),AND(57000<R25,R25<60001),AND(75000<R25,R25<77500)),$H25,VLOOKUP(R25,BDins,6,FALSE))))) -> 25 | S27: =IF(S29>10000,HLOOKUP(S29,$O25:R28,4,FALSE),IF(OR(AND(22500<S25,S25<25001),AND(50000<S25,S25<53501),AND(70000<S25,S25<72501)),$F25,IF(OR(AND(25001<S25,S25<27501),AND(53500<S25,S25<57001),AND(72500<S25,S25<75001)),$G25,IF(OR(AND(27500<S25,S25<30001),AND(57000<S25,S25<60001),AND(75000<S25,S25<77500)),$H25,VLOOKUP(S25,BDins,6,FALSE))))) -> 11.7 | T27: =IF(T29>10000,HLOOKUP(T29,$O25:S28,4,FALSE),IF(OR(AND(22500<T25,T25<25001),AND(50000<T25,T25<53501),AND(70000<T25,T25<72501)),$F25,IF(OR(AND(25001<T25,T25<27501),AND(53500<T25,T25<57001),AND(72500<T25,T25<75001)),$G25,IF(OR(AND(27500<T25,T25<30001),AND(57000<T25,T25<60001),AND(75000<T25,T25<77500)),$H25,VLOOKUP(T25,BDins,6,FALSE))))) -> 43.23
O28: =IF($K25>0,ROUND(O26*$E25/100,DpCU),IF(O29>10000,ROUND(HLOOKUP(O29,$O25:$T28,4,FALSE)/100*O26,DpCU),IF(OR(O25<20001,O25>95000,AND(60000<O25,O25<70001)),ROUND(ROUND(O26*JL/$C25,DcCU)*O27,DpCU),IF(OR(AND(20000<O25,O25<22501),AND(30000<O25,O25<50001),77500<O25),ROUND(O27*O26,DpCU),IF(OR(AND(22500<O25,O25<25001),AND(50000<O25,O25<53501),AND(70000<O25,O25<72501)),ROUND($F25/100*O26,DpCU),IF(OR(AND(25000<O25,O25<27501),AND(53500<O25,O25<57001),AND(72500<O25,O25<75001)),ROUND($G25/100*O26,DpCU),ROUND($H25/100*O26,DpCU))))))) -> 2 | P28: =IF($K25>0,ROUND(P26*$E25/100,DpCU),IF(P29>10000,ROUND(HLOOKUP(P29,$O25:$T28,4,FALSE)/100*P26,DpCU),IF(OR(P25<20001,P25>95000,AND(60000<P25,P25<70001)),ROUND(ROUND(P26*JL/$C25,DcCU)*P27,DpCU),IF(OR(AND(20000<P25,P25<22501),AND(30000<P25,P25<50001),77500<P25),ROUND(P27*P26,DpCU),IF(OR(AND(22500<P25,P25<25001),AND(50000<P25,P25<53501),AND(70000<P25,P25<72501)),ROUND($F25/100*P26,DpCU),IF(OR(AND(25000<P25,P25<27501),AND(53500<P25,P25<57001),AND(72500<P25,P25<75001)),ROUND($G25/100*P26,DpCU),ROUND($H25/100*P26,DpCU))))))) -> 24.58 | Q28: =IF($K25>0,ROUND(Q26*$E25/100,DpCU),IF(Q29>10000,ROUND(HLOOKUP(Q29,$O25:$T28,4,FALSE)/100*Q26,DpCU),IF(OR(Q25<20001,Q25>95000,AND(60000<Q25,Q25<70001)),ROUND(ROUND(Q26*JL/$C25,DcCU)*Q27,DpCU),IF(OR(AND(20000<Q25,Q25<22501),AND(30000<Q25,Q25<50001),77500<Q25),ROUND(Q27*Q26,DpCU),IF(OR(AND(22500<Q25,Q25<25001),AND(50000<Q25,Q25<53501),AND(70000<Q25,Q25<72501)),ROUND($F25/100*Q26,DpCU),IF(OR(AND(25000<Q25,Q25<27501),AND(53500<Q25,Q25<57001),AND(72500<Q25,Q25<75001)),ROUND($G25/100*Q26,DpCU),ROUND($H25/100*Q26,DpCU))))))) -> 16.65 | R28: =IF($K25>0,ROUND(R26*$E25/100,DpCU),IF(R29>10000,ROUND(HLOOKUP(R29,$O25:$T28,4,FALSE)/100*R26,DpCU),IF(OR(R25<20001,R25>95000,AND(60000<R25,R25<70001)),ROUND(ROUND(R26*JL/$C25,DcCU)*R27,DpCU),IF(OR(AND(20000<R25,R25<22501),AND(30000<R25,R25<50001),77500<R25),ROUND(R27*R26,DpCU),IF(OR(AND(22500<R25,R25<25001),AND(50000<R25,R25<53501),AND(70000<R25,R25<72501)),ROUND($F25/100*R26,DpCU),IF(OR(AND(25000<R25,R25<27501),AND(53500<R25,R25<57001),AND(72500<R25,R25<75001)),ROUND($G25/100*R26,DpCU),ROUND($H25/100*R26,DpCU))))))) -> 11.25 | S28: =IF($K25>0,ROUND(S26*$E25/100,DpCU),IF(S29>10000,ROUND(HLOOKUP(S29,$O25:$T28,4,FALSE)/100*S26,DpCU),IF(OR(S25<20001,S25>95000,AND(60000<S25,S25<70001)),ROUND(ROUND(S26*JL/$C25,DcCU)*S27,DpCU),IF(OR(AND(20000<S25,S25<22501),AND(30000<S25,S25<50001),77500<S25),ROUND(S27*S26,DpCU),IF(OR(AND(22500<S25,S25<25001),AND(50000<S25,S25<53501),AND(70000<S25,S25<72501)),ROUND($F25/100*S26,DpCU),IF(OR(AND(25000<S25,S25<27501),AND(53500<S25,S25<57001),AND(72500<S25,S25<75001)),ROUND($G25/100*S26,DpCU),ROUND($H25/100*S26,DpCU))))))) -> 19.89 | T28: =IF($K25>0,ROUND(T26*$E25/100,DpCU),IF(T29>10000,ROUND(HLOOKUP(T29,$O25:$T28,4,FALSE)/100*T26,DpCU),IF(OR(T25<20001,T25>95000,AND(60000<T25,T25<70001)),ROUND(ROUND(T26*JL/$C25,DcCU)*T27,DpCU),IF(OR(AND(20000<T25,T25<22501),AND(30000<T25,T25<50001),77500<T25),ROUND(T27*T26,DpCU),IF(OR(AND(22500<T25,T25<25001),AND(50000<T25,T25<53501),AND(70000<T25,T25<72501)),ROUND($F25/100*T26,DpCU),IF(OR(AND(25000<T25,T25<27501),AND(53500<T25,T25<57001),AND(72500<T25,T25<75001)),ROUND($G25/100*T26,DpCU),ROUND($H25/100*T26,DpCU))))))) -> 2.16
B29: =A25&"r" -> 10005r
A30: 10006 | B30: LIMPIEZA PERMANENTE DE LA OBRA | C30: =ROUND(J30*JL*Frto/8,4) -> 6 | D30: GLB | E30: =SUM($O33:$Q33) -> 2153.9 | F30: =SUMIF($O30:$Q30,"<22501",$O33:$Q33) -> 2051.33 | G30: =SUMIFS($O33:$Q33,$O30:$Q30,">30000",$O30:$Q30,"<50001") -> 0 | H30: =SUMIFS($O33:$Q33,$O30:$Q30,">60000",$O30:$Q30,"<70001") -> 0 | I30: 3 | J30: 6 | O30: 10001 | P30: 10003 | Q30: 70001
B31: =A30&"C" -> 10006C | O31: 0.1 | P31: 100 | Q31: 5
